<?xml version="1.0"?>
<!-- created with Phobos 1.0.1 "Capricious Choutengan" -->
  <robot name="move_twice">

    <link name="base_link">
      <inertial>
        <origin xyz="0 0 0" rpy="0 0 0"/>
        <mass value="0.001"/>
        <inertia ixx="0.001" ixy="0" ixz="0" iyy="0.001" iyz="0" izz="0.001"/>
      </inertial>
      <visual name="visual_box_base">
        <origin xyz="0 0 0" rpy="0 0 0"/>
        <geometry>
          <box size="31.999 31.999 0.199"/>
        </geometry>
        <material name="lavender"/>
      </visual>
      <collision name="collision_box_base">
        <origin xyz="0 0 0" rpy="0 0 0"/>
        <geometry>
          <box size="31.999 31.999 0.199"/>
        </geometry>
      </collision>
    </link>

    <link name="goal">
      <inertial>
        <origin xyz="0 0 0" rpy="0 0 0"/>
        <mass value="0.001"/>
        <inertia ixx="0.001" ixy="0" ixz="0" iyy="0.001" iyz="0" izz="0.001"/>
      </inertial>
    </link>

    <link name="link_0_joint_0">
      <inertial>
        <origin xyz="0 0 0" rpy="0 0 0"/>
        <mass value="0.001"/>
        <inertia ixx="0.001" ixy="0" ixz="0" iyy="0.001" iyz="0" izz="0.001"/>
      </inertial>
      <visual name="visual_mesh_95_link_0">
        <origin xyz="0 0 0" rpy="0 0 0"/>
        <geometry>
          <mesh filename="file:///home/userone/ba/puzzle-generator/puzzles/move_twice/meshes/stl/robot.stl" scale="1.0 1.0 1.0"/>
        </geometry>
        <material name="green"/>
      </visual>
      <collision concave="yes" name="collision_mesh_95_link_0">
        <origin xyz="0 0 0" rpy="0 0 0"/>
        <geometry>
          <mesh filename="file:///home/userone/ba/puzzle-generator/puzzles/move_twice/meshes/stl/robot.001.stl" scale="1.0 1.0 1.0"/>
        </geometry>
      </collision>
    </link>

    <link name="link_0_joint_0.001">
      <inertial>
        <origin xyz="0 0 0" rpy="0 0 0"/>
        <mass value="0.001"/>
        <inertia ixx="0.001" ixy="0" ixz="0" iyy="0.001" iyz="0" izz="0.001"/>
      </inertial>
      <visual name="visual_mesh_95_link_0.001">
        <origin xyz="0 0 0" rpy="0 0 0"/>
        <geometry>
          <mesh filename="file:///home/userone/ba/puzzle-generator/puzzles/move_twice/meshes/stl/robot.002.stl" scale="1.0 1.0 1.0"/>
        </geometry>
        <material name="green_translucent"/>
      </visual>
    </link>

    <link name="link_0_joint_1">
      <inertial>
        <origin xyz="0 0 0" rpy="0 0 0"/>
        <mass value="0.001"/>
        <inertia ixx="0.001" ixy="0" ixz="0" iyy="0.001" iyz="0" izz="0.001"/>
      </inertial>
    </link>

    <link name="link_0_joint_1.001">
      <inertial>
        <origin xyz="0 0 0" rpy="0 0 0"/>
        <mass value="0.001"/>
        <inertia ixx="0.001" ixy="0" ixz="0" iyy="0.001" iyz="0" izz="0.001"/>
      </inertial>
    </link>

    <link name="link_0_joint_2">
      <inertial>
        <origin xyz="0 0 0" rpy="0 0 0"/>
        <mass value="0.001"/>
        <inertia ixx="0.001" ixy="0" ixz="0" iyy="0.001" iyz="0" izz="0.001"/>
      </inertial>
    </link>

    <link name="link_100_fixed_wall_back">
      <inertial>
        <origin xyz="0 0 0" rpy="0 0 0"/>
        <mass value="0.001"/>
        <inertia ixx="0.001" ixy="0" ixz="0" iyy="0.001" iyz="0" izz="0.001"/>
      </inertial>
      <visual name="visual_box_100_fixed_wall_back">
        <origin xyz="0 0 0" rpy="0 0 0"/>
        <geometry>
          <box size="0.199 5.999 0.999"/>
        </geometry>
        <material name="gray"/>
      </visual>
      <collision name="collision_box_100_fixed_wall_back">
        <origin xyz="0 0 0" rpy="0 0 0"/>
        <geometry>
          <box size="0.199 5.999 0.999"/>
        </geometry>
      </collision>
    </link>

    <link name="link_1_joint_0">
      <inertial>
        <origin xyz="0 0 0" rpy="0 0 0"/>
        <mass value="0.001"/>
        <inertia ixx="0.001" ixy="0" ixz="0" iyy="0.001" iyz="0" izz="0.001"/>
      </inertial>
      <visual name="visual_box_101_link_1">
        <origin xyz="0 0 0" rpy="0 0 0"/>
        <geometry>
          <box size="0.199 5.999 0.999"/>
        </geometry>
        <material name="red"/>
      </visual>
      <collision name="collision_box_101_link_1">
        <origin xyz="0 0 0" rpy="0 0 0"/>
        <geometry>
          <box size="0.199 5.999 0.999"/>
        </geometry>
      </collision>
    </link>

    <link name="link_96_fixed_hinge">
      <inertial>
        <origin xyz="0 0 0" rpy="0 0 0"/>
        <mass value="0.001"/>
        <inertia ixx="0.001" ixy="0" ixz="0" iyy="0.001" iyz="0" izz="0.001"/>
      </inertial>
      <visual name="visual_cylinder_96_fixed_hinge">
        <origin xyz="0 0 0" rpy="0 0 0"/>
        <geometry>
          <cylinder radius="0.0495" length="1.099"/>
        </geometry>
        <material name="gray"/>
      </visual>
    </link>

    <link name="link_96_fixed_hinge.001">
      <inertial>
        <origin xyz="0 0 0" rpy="0 0 0"/>
        <mass value="0.001"/>
        <inertia ixx="0.001" ixy="0" ixz="0" iyy="0.001" iyz="0" izz="0.001"/>
      </inertial>
      <visual name="visual_cylinder_96_fixed_hinge.001">
        <origin xyz="0 0 0" rpy="0 0 0"/>
        <geometry>
          <cylinder radius="0.0495" length="1.099"/>
        </geometry>
        <material name="green_translucent"/>
      </visual>
    </link>

    <link name="link_97_fixed_wall_left">
      <inertial>
        <origin xyz="0 0 0" rpy="0 0 0"/>
        <mass value="0.001"/>
        <inertia ixx="0.001" ixy="0" ixz="0" iyy="0.001" iyz="0" izz="0.001"/>
      </inertial>
      <visual name="visual_box_97_fixed_wall_left">
        <origin xyz="0 0 0" rpy="0 0 0"/>
        <geometry>
          <box size="3.999 0.199 0.999"/>
        </geometry>
        <material name="gray"/>
      </visual>
      <collision name="collision_box_97_fixed_wall_left">
        <origin xyz="0 0 0" rpy="0 0 0"/>
        <geometry>
          <box size="3.999 0.199 0.999"/>
        </geometry>
      </collision>
    </link>

    <link name="link_98_fixed_wall_right">
      <inertial>
        <origin xyz="0 0 0" rpy="0 0 0"/>
        <mass value="0.001"/>
        <inertia ixx="0.001" ixy="0" ixz="0" iyy="0.001" iyz="0" izz="0.001"/>
      </inertial>
      <visual name="visual_box_98_fixed_wall_right">
        <origin xyz="0 0 0" rpy="0 0 0"/>
        <geometry>
          <box size="3.999 0.199 0.999"/>
        </geometry>
        <material name="gray"/>
      </visual>
      <collision name="collision_box_98_fixed_wall_right">
        <origin xyz="0 0 0" rpy="0 0 0"/>
        <geometry>
          <box size="3.999 0.199 0.999"/>
        </geometry>
      </collision>
    </link>

    <link name="link_99_fixed_wall_mid">
      <inertial>
        <origin xyz="0 0 0" rpy="0 0 0"/>
        <mass value="0.001"/>
        <inertia ixx="0.001" ixy="0" ixz="0" iyy="0.001" iyz="0" izz="0.001"/>
      </inertial>
      <visual name="visual_box_99_fixed_wall_mid">
        <origin xyz="0 0 0" rpy="0 0 0"/>
        <geometry>
          <box size="3.999 0.199 0.999"/>
        </geometry>
        <material name="gray"/>
      </visual>
      <collision name="collision_box_99_fixed_wall_mid">
        <origin xyz="0 0 0" rpy="0 0 0"/>
        <geometry>
          <box size="3.999 0.199 0.999"/>
        </geometry>
      </collision>
    </link>

    <joint name="goal" type="fixed">
      <origin xyz="1.03327 3.36114 0.6" rpy="0 0 -0.49906"/>
      <parent link="base_link"/>
      <child link="goal"/>
      <limit effort="0" velocity="0"/>
    </joint>

    <joint name="link_0_joint_0" type="revolute">
      <origin xyz="0 0 0" rpy="0 0 0"/>
      <parent link="link_0_joint_1"/>
      <child link="link_0_joint_0"/>
      <axis xyz="0 0 1.0"/>
      <limit lower="-3.14159" upper="3.14159" effort="0" velocity="0"/>
    </joint>

    <joint name="link_0_joint_0.001" type="fixed">
      <origin xyz="0 0 0" rpy="0 0 0"/>
      <parent link="link_0_joint_1.001"/>
      <child link="link_0_joint_0.001"/>
      <limit effort="0" velocity="0"/>
    </joint>

    <joint name="link_0_joint_1" type="prismatic">
      <origin xyz="0 0 0" rpy="0 0 0"/>
      <parent link="link_0_joint_2"/>
      <child link="link_0_joint_1"/>
      <axis xyz="0 1.0 0"/>
      <limit lower="-16.0" upper="16.0" effort="0" velocity="0"/>
    </joint>

    <joint name="link_0_joint_1.001" type="fixed">
      <origin xyz="0 0 0" rpy="0 0 0"/>
      <parent link="goal"/>
      <child link="link_0_joint_1.001"/>
      <limit effort="0" velocity="0"/>
    </joint>

    <joint name="link_0_joint_2" type="prismatic">
      <origin xyz="0 0 0.6" rpy="0 0 0"/>
      <parent link="base_link"/>
      <child link="link_0_joint_2"/>
      <axis xyz="1.0 0 0"/>
      <limit lower="-16.0" upper="16.0" effort="0" velocity="0"/>
    </joint>

    <joint name="link_100_fixed_wall_back" type="fixed">
      <origin xyz="-2.1 1.5 0.6" rpy="0 0 0"/>
      <parent link="base_link"/>
      <child link="link_100_fixed_wall_back"/>
    </joint>

    <joint name="link_1_joint_0" type="prismatic">
      <origin xyz="2.1 1.5 0.6" rpy="0 0 0"/>
      <parent link="base_link"/>
      <child link="link_1_joint_0"/>
      <axis xyz="0 1.0 0"/>
      <limit lower="-3.0" upper="3.0" effort="0" velocity="0"/>
    </joint>

    <joint name="link_96_fixed_hinge" type="fixed">
      <origin xyz="0 0 0" rpy="0 0 0"/>
      <parent link="link_0_joint_0"/>
      <child link="link_96_fixed_hinge"/>
    </joint>

    <joint name="link_96_fixed_hinge.001" type="fixed">
      <origin xyz="0 0 0" rpy="0 0 0"/>
      <parent link="link_0_joint_0.001"/>
      <child link="link_96_fixed_hinge.001"/>
    </joint>

    <joint name="link_97_fixed_wall_left" type="fixed">
      <origin xyz="0 -1.4 0.6" rpy="0 0 0"/>
      <parent link="base_link"/>
      <child link="link_97_fixed_wall_left"/>
    </joint>

    <joint name="link_98_fixed_wall_right" type="fixed">
      <origin xyz="0 4.4 0.6" rpy="0 0 0"/>
      <parent link="base_link"/>
      <child link="link_98_fixed_wall_right"/>
    </joint>

    <joint name="link_99_fixed_wall_mid" type="fixed">
      <origin xyz="0 1.5 0.6" rpy="0 0 0"/>
      <parent link="base_link"/>
      <child link="link_99_fixed_wall_mid"/>
    </joint>

    <material name="gray">
      <color rgba="0.5 0.5 0.5 1.0"/>
    </material>

    <material name="green">
      <color rgba="0 1.0 0 1.0"/>
    </material>

    <material name="green_translucent">
      <color rgba="0 1.0 0 0.25"/>
    </material>

    <material name="lavender">
      <color rgba="0.8 0.8 1.0 1.0"/>
    </material>

    <material name="red">
      <color rgba="1.0 0 0 1.0"/>
    </material>

  </robot>
