<?xml version="1.0"?>
<!-- created with Phobos 1.0.1 "Capricious Choutengan" -->
  <robot name="grid_world">

    <link name="base_link">
      <inertial>
        <origin xyz="0 0 0" rpy="0 0 0"/>
        <mass value="0.001"/>
        <inertia ixx="0.001" ixy="0" ixz="0" iyy="0.001" iyz="0" izz="0.001"/>
      </inertial>
    </link>

    <link name="goal">
      <inertial>
        <origin xyz="0 0 0" rpy="0 0 0"/>
        <mass value="0.001"/>
        <inertia ixx="0.001" ixy="0" ixz="0" iyy="0.001" iyz="0" izz="0.001"/>
      </inertial>
      <visual name="visual_box_1_link_0.001">
        <origin xyz="0 0 0" rpy="0 0 0"/>
        <geometry>
          <box size="2.8961 0.8981 0.8981"/>
        </geometry>
        <material name="green_translucent"/>
      </visual>
    </link>

    <link name="link_0_joint_0">
      <inertial>
        <origin xyz="0 0 0" rpy="0 0 0"/>
        <mass value="0.001"/>
        <inertia ixx="0.001" ixy="0" ixz="0" iyy="0.001" iyz="0" izz="0.001"/>
      </inertial>
      <visual name="visual_box_1_link_0">
        <origin xyz="0 0 0" rpy="0 0 0"/>
        <geometry>
          <box size="2.899 0.899 0.899"/>
        </geometry>
        <material name="green"/>
      </visual>
      <collision name="collision_box_1_link_0">
        <origin xyz="0 0 0" rpy="0 0 0"/>
        <geometry>
          <box size="2.899 0.899 0.899"/>
        </geometry>
      </collision>
    </link>

    <link name="link_1_joint_0">
      <inertial>
        <origin xyz="0 0 0" rpy="0 0 0"/>
        <mass value="0.001"/>
        <inertia ixx="0.001" ixy="0" ixz="0" iyy="0.001" iyz="0" izz="0.001"/>
      </inertial>
      <visual name="visual_box_5_link_1">
        <origin xyz="0 0 0" rpy="0 0 0"/>
        <geometry>
          <box size="1.899 0.899 0.899"/>
        </geometry>
        <material name="red"/>
      </visual>
      <collision name="collision_box_5_link_1">
        <origin xyz="0 0 0" rpy="0 0 0"/>
        <geometry>
          <box size="1.899 0.899 0.899"/>
        </geometry>
      </collision>
    </link>

    <link name="link_2_joint_0">
      <inertial>
        <origin xyz="0 0 0" rpy="0 0 0"/>
        <mass value="0.001"/>
        <inertia ixx="0.001" ixy="0" ixz="0" iyy="0.001" iyz="0" izz="0.001"/>
      </inertial>
      <visual name="visual_box_8_link_2">
        <origin xyz="0 0 0" rpy="0 0 0"/>
        <geometry>
          <box size="2.899 0.899 0.899"/>
        </geometry>
        <material name="red"/>
      </visual>
      <collision name="collision_box_8_link_2">
        <origin xyz="0 0 0" rpy="0 0 0"/>
        <geometry>
          <box size="2.899 0.899 0.899"/>
        </geometry>
      </collision>
    </link>

    <link name="link_3_joint_0">
      <inertial>
        <origin xyz="0 0 0" rpy="0 0 0"/>
        <mass value="0.001"/>
        <inertia ixx="0.001" ixy="0" ixz="0" iyy="0.001" iyz="0" izz="0.001"/>
      </inertial>
      <visual name="visual_box_12_link_3">
        <origin xyz="0 0 0" rpy="0 0 0"/>
        <geometry>
          <box size="1.899 0.899 0.899"/>
        </geometry>
        <material name="red"/>
      </visual>
      <collision name="collision_box_12_link_3">
        <origin xyz="0 0 0" rpy="0 0 0"/>
        <geometry>
          <box size="1.899 0.899 0.899"/>
        </geometry>
      </collision>
    </link>

    <link name="link_4_joint_0">
      <inertial>
        <origin xyz="0 0 0" rpy="0 0 0"/>
        <mass value="0.001"/>
        <inertia ixx="0.001" ixy="0" ixz="0" iyy="0.001" iyz="0" izz="0.001"/>
      </inertial>
      <visual name="visual_box_15_link_4">
        <origin xyz="0 0 0" rpy="0 0 0"/>
        <geometry>
          <box size="1.899 0.899 0.899"/>
        </geometry>
        <material name="red"/>
      </visual>
      <collision name="collision_box_15_link_4">
        <origin xyz="0 0 0" rpy="0 0 0"/>
        <geometry>
          <box size="1.899 0.899 0.899"/>
        </geometry>
      </collision>
    </link>

    <link name="link_5_joint_0">
      <inertial>
        <origin xyz="0 0 0" rpy="0 0 0"/>
        <mass value="0.001"/>
        <inertia ixx="0.001" ixy="0" ixz="0" iyy="0.001" iyz="0" izz="0.001"/>
      </inertial>
      <visual name="visual_box_18_link_5">
        <origin xyz="0 0 0" rpy="0 0 0"/>
        <geometry>
          <box size="1.899 0.899 0.899"/>
        </geometry>
        <material name="red"/>
      </visual>
      <collision name="collision_box_18_link_5">
        <origin xyz="0 0 0" rpy="0 0 0"/>
        <geometry>
          <box size="1.899 0.899 0.899"/>
        </geometry>
      </collision>
    </link>

    <link name="link_fixed_0_floor">
      <inertial>
        <origin xyz="0 0 0" rpy="0 0 0"/>
        <mass value="0.001"/>
        <inertia ixx="0.001" ixy="0" ixz="0" iyy="0.001" iyz="0" izz="0.001"/>
      </inertial>
      <visual name="visual_box_fixed_0_floor">
        <origin xyz="0 0 0" rpy="0 0 0"/>
        <geometry>
          <box size="31.999 31.999 0.199"/>
        </geometry>
        <material name="lavender"/>
      </visual>
      <collision name="collision_box_fixed_0_floor">
        <origin xyz="0 0 0" rpy="0 0 0"/>
        <geometry>
          <box size="31.999 31.999 0.199"/>
        </geometry>
      </collision>
    </link>

    <link name="link_fixed_10_handle_shaft">
      <inertial>
        <origin xyz="0 0 0" rpy="0 0 0"/>
        <mass value="0.001"/>
        <inertia ixx="0.001" ixy="0" ixz="0" iyy="0.001" iyz="0" izz="0.001"/>
      </inertial>
      <visual name="visual_cylinder_fixed_10_handle_shaft">
        <origin xyz="0 0 0" rpy="0 0 0"/>
        <geometry>
          <cylinder radius="0.0995" length="0.999"/>
        </geometry>
        <material name="red"/>
      </visual>
      <collision name="collision_cylinder_fixed_10_handle_shaft">
        <origin xyz="0 0 0" rpy="0 0 0"/>
        <geometry>
          <cylinder radius="0.0995" length="0.999"/>
        </geometry>
      </collision>
    </link>

    <link name="link_fixed_11_handle_knob">
      <inertial>
        <origin xyz="0 0 0" rpy="0 0 0"/>
        <mass value="0.001"/>
        <inertia ixx="0.001" ixy="0" ixz="0" iyy="0.001" iyz="0" izz="0.001"/>
      </inertial>
      <visual name="visual_box_fixed_11_handle_knob">
        <origin xyz="0 0 0" rpy="0 0 0"/>
        <geometry>
          <box size="0.049 0.049 0.199"/>
        </geometry>
        <material name="yellow"/>
      </visual>
      <collision name="collision_box_fixed_11_handle_knob">
        <origin xyz="0 0 0" rpy="0 0 0"/>
        <geometry>
          <box size="0.049 0.049 0.199"/>
        </geometry>
      </collision>
    </link>

    <link name="link_fixed_13_handle_shaft">
      <inertial>
        <origin xyz="0 0 0" rpy="0 0 0"/>
        <mass value="0.001"/>
        <inertia ixx="0.001" ixy="0" ixz="0" iyy="0.001" iyz="0" izz="0.001"/>
      </inertial>
      <visual name="visual_box_fixed_13_handle_shaft">
        <origin xyz="0 0 0" rpy="0 0 0"/>
        <geometry>
          <box size="0.199 0.199 0.999"/>
        </geometry>
        <material name="red"/>
      </visual>
      <collision name="collision_box_fixed_13_handle_shaft">
        <origin xyz="0 0 0" rpy="0 0 0"/>
        <geometry>
          <box size="0.199 0.199 0.999"/>
        </geometry>
      </collision>
    </link>

    <link name="link_fixed_14_handle_knob">
      <inertial>
        <origin xyz="0 0 0" rpy="0 0 0"/>
        <mass value="0.001"/>
        <inertia ixx="0.001" ixy="0" ixz="0" iyy="0.001" iyz="0" izz="0.001"/>
      </inertial>
      <visual name="visual_box_fixed_14_handle_knob">
        <origin xyz="0 0 0" rpy="0 0 0"/>
        <geometry>
          <box size="0.049 0.049 0.199"/>
        </geometry>
        <material name="yellow"/>
      </visual>
      <collision name="collision_box_fixed_14_handle_knob">
        <origin xyz="0 0 0" rpy="0 0 0"/>
        <geometry>
          <box size="0.049 0.049 0.199"/>
        </geometry>
      </collision>
    </link>

    <link name="link_fixed_16_handle_shaft">
      <inertial>
        <origin xyz="0 0 0" rpy="0 0 0"/>
        <mass value="0.001"/>
        <inertia ixx="0.001" ixy="0" ixz="0" iyy="0.001" iyz="0" izz="0.001"/>
      </inertial>
      <visual name="visual_box_fixed_16_handle_shaft">
        <origin xyz="0 0 0" rpy="0 0 0"/>
        <geometry>
          <box size="0.199 0.199 0.999"/>
        </geometry>
        <material name="red"/>
      </visual>
      <collision name="collision_box_fixed_16_handle_shaft">
        <origin xyz="0 0 0" rpy="0 0 0"/>
        <geometry>
          <box size="0.199 0.199 0.999"/>
        </geometry>
      </collision>
    </link>

    <link name="link_fixed_17_handle_knob">
      <inertial>
        <origin xyz="0 0 0" rpy="0 0 0"/>
        <mass value="0.001"/>
        <inertia ixx="0.001" ixy="0" ixz="0" iyy="0.001" iyz="0" izz="0.001"/>
      </inertial>
      <visual name="visual_box_fixed_17_handle_knob">
        <origin xyz="0 0 0" rpy="0 0 0"/>
        <geometry>
          <box size="0.049 0.049 0.199"/>
        </geometry>
        <material name="yellow"/>
      </visual>
      <collision name="collision_box_fixed_17_handle_knob">
        <origin xyz="0 0 0" rpy="0 0 0"/>
        <geometry>
          <box size="0.049 0.049 0.199"/>
        </geometry>
      </collision>
    </link>

    <link name="link_fixed_19_handle_shaft">
      <inertial>
        <origin xyz="0 0 0" rpy="0 0 0"/>
        <mass value="0.001"/>
        <inertia ixx="0.001" ixy="0" ixz="0" iyy="0.001" iyz="0" izz="0.001"/>
      </inertial>
      <visual name="visual_box_fixed_19_handle_shaft">
        <origin xyz="0 0 0" rpy="0 0 0"/>
        <geometry>
          <box size="0.199 0.199 0.999"/>
        </geometry>
        <material name="red"/>
      </visual>
      <collision name="collision_box_fixed_19_handle_shaft">
        <origin xyz="0 0 0" rpy="0 0 0"/>
        <geometry>
          <box size="0.199 0.199 0.999"/>
        </geometry>
      </collision>
    </link>

    <link name="link_fixed_20_handle_knob">
      <inertial>
        <origin xyz="0 0 0" rpy="0 0 0"/>
        <mass value="0.001"/>
        <inertia ixx="0.001" ixy="0" ixz="0" iyy="0.001" iyz="0" izz="0.001"/>
      </inertial>
      <visual name="visual_box_fixed_20_handle_knob">
        <origin xyz="0 0 0" rpy="0 0 0"/>
        <geometry>
          <box size="0.049 0.049 0.199"/>
        </geometry>
        <material name="yellow"/>
      </visual>
      <collision name="collision_box_fixed_20_handle_knob">
        <origin xyz="0 0 0" rpy="0 0 0"/>
        <geometry>
          <box size="0.049 0.049 0.199"/>
        </geometry>
      </collision>
    </link>

    <link name="link_fixed_2_hinge">
      <inertial>
        <origin xyz="0 0 0" rpy="0 0 0"/>
        <mass value="0.001"/>
        <inertia ixx="0.001" ixy="0" ixz="0" iyy="0.001" iyz="0" izz="0.001"/>
      </inertial>
      <visual name="visual_cylinder_fixed_2_hinge">
        <origin xyz="0 0 0" rpy="0 0 0"/>
        <geometry>
          <cylinder radius="0.112" length="0.989"/>
        </geometry>
        <material name="gray"/>
      </visual>
    </link>

    <link name="link_fixed_2_hinge.001">
      <inertial>
        <origin xyz="0 0 0" rpy="0 0 0"/>
        <mass value="0.001"/>
        <inertia ixx="0.001" ixy="0" ixz="0" iyy="0.001" iyz="0" izz="0.001"/>
      </inertial>
      <visual name="visual_cylinder_fixed_2_hinge.001">
        <origin xyz="0 0 0" rpy="0 0 0"/>
        <geometry>
          <cylinder radius="0.11189" length="0.98801"/>
        </geometry>
        <material name="green_translucent"/>
      </visual>
    </link>

    <link name="link_fixed_3_handle_shaft">
      <inertial>
        <origin xyz="0 0 0" rpy="0 0 0"/>
        <mass value="0.001"/>
        <inertia ixx="0.001" ixy="0" ixz="0" iyy="0.001" iyz="0" izz="0.001"/>
      </inertial>
      <visual name="visual_cylinder_fixed_3_handle_shaft">
        <origin xyz="0 0 0" rpy="0 0 0"/>
        <geometry>
          <cylinder radius="0.0995" length="0.999"/>
        </geometry>
        <material name="green"/>
      </visual>
      <collision name="collision_cylinder_fixed_3_handle_shaft">
        <origin xyz="0 0 0" rpy="0 0 0"/>
        <geometry>
          <cylinder radius="0.0995" length="0.999"/>
        </geometry>
      </collision>
    </link>

    <link name="link_fixed_3_handle_shaft.001">
      <inertial>
        <origin xyz="0 0 0" rpy="0 0 0"/>
        <mass value="0.001"/>
        <inertia ixx="0.001" ixy="0" ixz="0" iyy="0.001" iyz="0" izz="0.001"/>
      </inertial>
      <visual name="visual_cylinder_fixed_3_handle_shaft.001">
        <origin xyz="0 0 0" rpy="0 0 0"/>
        <geometry>
          <cylinder radius="0.0994" length="0.998"/>
        </geometry>
        <material name="green_translucent"/>
      </visual>
    </link>

    <link name="link_fixed_4_handle_knob">
      <inertial>
        <origin xyz="0 0 0" rpy="0 0 0"/>
        <mass value="0.001"/>
        <inertia ixx="0.001" ixy="0" ixz="0" iyy="0.001" iyz="0" izz="0.001"/>
      </inertial>
      <visual name="visual_box_fixed_4_handle_knob">
        <origin xyz="0 0 0" rpy="0 0 0"/>
        <geometry>
          <box size="0.049 0.049 0.199"/>
        </geometry>
        <material name="yellow"/>
      </visual>
      <collision name="collision_box_fixed_4_handle_knob">
        <origin xyz="0 0 0" rpy="0 0 0"/>
        <geometry>
          <box size="0.049 0.049 0.199"/>
        </geometry>
      </collision>
    </link>

    <link name="link_fixed_4_handle_knob.001">
      <inertial>
        <origin xyz="0 0 0" rpy="0 0 0"/>
        <mass value="0.001"/>
        <inertia ixx="0.001" ixy="0" ixz="0" iyy="0.001" iyz="0" izz="0.001"/>
      </inertial>
      <visual name="visual_box_fixed_4_handle_knob.001">
        <origin xyz="0 0 0" rpy="0 0 0"/>
        <geometry>
          <box size="0.04895 0.04895 0.1988"/>
        </geometry>
        <material name="green_translucent"/>
      </visual>
    </link>

    <link name="link_fixed_6_handle_shaft">
      <inertial>
        <origin xyz="0 0 0" rpy="0 0 0"/>
        <mass value="0.001"/>
        <inertia ixx="0.001" ixy="0" ixz="0" iyy="0.001" iyz="0" izz="0.001"/>
      </inertial>
      <visual name="visual_box_fixed_6_handle_shaft">
        <origin xyz="0 0 0" rpy="0 0 0"/>
        <geometry>
          <box size="0.199 0.199 0.999"/>
        </geometry>
        <material name="red"/>
      </visual>
      <collision name="collision_box_fixed_6_handle_shaft">
        <origin xyz="0 0 0" rpy="0 0 0"/>
        <geometry>
          <box size="0.199 0.199 0.999"/>
        </geometry>
      </collision>
    </link>

    <link name="link_fixed_7_handle_knob">
      <inertial>
        <origin xyz="0 0 0" rpy="0 0 0"/>
        <mass value="0.001"/>
        <inertia ixx="0.001" ixy="0" ixz="0" iyy="0.001" iyz="0" izz="0.001"/>
      </inertial>
      <visual name="visual_box_fixed_7_handle_knob">
        <origin xyz="0 0 0" rpy="0 0 0"/>
        <geometry>
          <box size="0.049 0.049 0.199"/>
        </geometry>
        <material name="yellow"/>
      </visual>
      <collision name="collision_box_fixed_7_handle_knob">
        <origin xyz="0 0 0" rpy="0 0 0"/>
        <geometry>
          <box size="0.049 0.049 0.199"/>
        </geometry>
      </collision>
    </link>

    <link name="link_fixed_9_hinge">
      <inertial>
        <origin xyz="0 0 0" rpy="0 0 0"/>
        <mass value="0.001"/>
        <inertia ixx="0.001" ixy="0" ixz="0" iyy="0.001" iyz="0" izz="0.001"/>
      </inertial>
      <visual name="visual_cylinder_fixed_9_hinge">
        <origin xyz="0 0 0" rpy="0 0 0"/>
        <geometry>
          <cylinder radius="0.112" length="0.989"/>
        </geometry>
        <material name="gray"/>
      </visual>
    </link>

    <joint name="goal" type="fixed">
      <origin xyz="-0.5 0.5 0.45" rpy="0 0 1.5708"/>
      <parent link="base_link"/>
      <child link="goal"/>
      <limit effort="0" velocity="0"/>
    </joint>

    <joint name="link_0_joint_0" type="revolute">
      <origin xyz="-0.5 0.5 0.45" rpy="0 0 0"/>
      <parent link="base_link"/>
      <child link="link_0_joint_0"/>
      <axis xyz="0 0 1.0"/>
      <limit lower="0" upper="1.5708" effort="0" velocity="0"/>
    </joint>

    <joint name="link_1_joint_0" type="prismatic">
      <origin xyz="-1.0 1.5 0.45" rpy="0 0 3.14159"/>
      <parent link="base_link"/>
      <child link="link_1_joint_0"/>
      <axis xyz="1.0 0 0"/>
      <limit lower="0" upper="1.0" effort="0" velocity="0"/>
    </joint>

    <joint name="link_2_joint_0" type="revolute">
      <origin xyz="-2.5 -0.5 0.45" rpy="0 0 0"/>
      <parent link="base_link"/>
      <child link="link_2_joint_0"/>
      <axis xyz="0 0 1.0"/>
      <limit lower="-1.5708" upper="0" effort="0" velocity="0"/>
    </joint>

    <joint name="link_3_joint_0" type="prismatic">
      <origin xyz="1.0 1.5 0.45" rpy="0 0 0"/>
      <parent link="base_link"/>
      <child link="link_3_joint_0"/>
      <axis xyz="1.0 0 0"/>
      <limit lower="0" upper="1.0" effort="0" velocity="0"/>
    </joint>

    <joint name="link_4_joint_0" type="prismatic">
      <origin xyz="0 -0.5 0.45" rpy="0 0 0"/>
      <parent link="base_link"/>
      <child link="link_4_joint_0"/>
      <axis xyz="1.0 0 0"/>
      <limit lower="0" upper="1.0" effort="0" velocity="0"/>
    </joint>

    <joint name="link_5_joint_0" type="prismatic">
      <origin xyz="-2.5 2.0 0.45" rpy="0 0 1.5708"/>
      <parent link="base_link"/>
      <child link="link_5_joint_0"/>
      <axis xyz="1.0 0 0"/>
      <limit lower="0" upper="1.0" effort="0" velocity="0"/>
    </joint>

    <joint name="link_fixed_0_floor" type="fixed">
      <origin xyz="0 0 -0.1" rpy="0 0 0"/>
      <parent link="base_link"/>
      <child link="link_fixed_0_floor"/>
    </joint>

    <joint name="link_fixed_10_handle_shaft" type="fixed">
      <origin xyz="1.0875 0 0.95" rpy="0 0 0"/>
      <parent link="link_2_joint_0"/>
      <child link="link_fixed_10_handle_shaft"/>
    </joint>

    <joint name="link_fixed_11_handle_knob" type="fixed">
      <origin xyz="0 0 0.6" rpy="0 0 0"/>
      <parent link="link_fixed_10_handle_shaft"/>
      <child link="link_fixed_11_handle_knob"/>
    </joint>

    <joint name="link_fixed_13_handle_shaft" type="fixed">
      <origin xyz="0 0 0.95" rpy="0 0 0"/>
      <parent link="link_3_joint_0"/>
      <child link="link_fixed_13_handle_shaft"/>
    </joint>

    <joint name="link_fixed_14_handle_knob" type="fixed">
      <origin xyz="0 0 0.6" rpy="0 0 0"/>
      <parent link="link_fixed_13_handle_shaft"/>
      <child link="link_fixed_14_handle_knob"/>
    </joint>

    <joint name="link_fixed_16_handle_shaft" type="fixed">
      <origin xyz="0 0 0.95" rpy="0 0 0"/>
      <parent link="link_4_joint_0"/>
      <child link="link_fixed_16_handle_shaft"/>
    </joint>

    <joint name="link_fixed_17_handle_knob" type="fixed">
      <origin xyz="0 0 0.6" rpy="0 0 0"/>
      <parent link="link_fixed_16_handle_shaft"/>
      <child link="link_fixed_17_handle_knob"/>
    </joint>

    <joint name="link_fixed_19_handle_shaft" type="fixed">
      <origin xyz="0 0 0.95" rpy="0 0 0"/>
      <parent link="link_5_joint_0"/>
      <child link="link_fixed_19_handle_shaft"/>
    </joint>

    <joint name="link_fixed_20_handle_knob" type="fixed">
      <origin xyz="0 0 0.6" rpy="0 0 0"/>
      <parent link="link_fixed_19_handle_shaft"/>
      <child link="link_fixed_20_handle_knob"/>
    </joint>

    <joint name="link_fixed_2_hinge" type="fixed">
      <origin xyz="0 0 0" rpy="0 0 0"/>
      <parent link="link_0_joint_0"/>
      <child link="link_fixed_2_hinge"/>
    </joint>

    <joint name="link_fixed_2_hinge.001" type="fixed">
      <origin xyz="0 0 0" rpy="0 0 0"/>
      <parent link="goal"/>
      <child link="link_fixed_2_hinge.001"/>
    </joint>

    <joint name="link_fixed_3_handle_shaft" type="fixed">
      <origin xyz="1.0875 0 0.95" rpy="0 0 0"/>
      <parent link="link_0_joint_0"/>
      <child link="link_fixed_3_handle_shaft"/>
    </joint>

    <joint name="link_fixed_3_handle_shaft.001" type="fixed">
      <origin xyz="1.08641 0 0.94905" rpy="0 0 0"/>
      <parent link="goal"/>
      <child link="link_fixed_3_handle_shaft.001"/>
    </joint>

    <joint name="link_fixed_4_handle_knob" type="fixed">
      <origin xyz="0 0 0.6" rpy="0 0 0"/>
      <parent link="link_fixed_3_handle_shaft"/>
      <child link="link_fixed_4_handle_knob"/>
    </joint>

    <joint name="link_fixed_4_handle_knob.001" type="fixed">
      <origin xyz="0 0 0.5994" rpy="0 0 0"/>
      <parent link="link_fixed_3_handle_shaft.001"/>
      <child link="link_fixed_4_handle_knob.001"/>
    </joint>

    <joint name="link_fixed_6_handle_shaft" type="fixed">
      <origin xyz="0 0 0.95" rpy="0 0 0"/>
      <parent link="link_1_joint_0"/>
      <child link="link_fixed_6_handle_shaft"/>
    </joint>

    <joint name="link_fixed_7_handle_knob" type="fixed">
      <origin xyz="0 0 0.6" rpy="0 0 0"/>
      <parent link="link_fixed_6_handle_shaft"/>
      <child link="link_fixed_7_handle_knob"/>
    </joint>

    <joint name="link_fixed_9_hinge" type="fixed">
      <origin xyz="0 0 0" rpy="0 0 0"/>
      <parent link="link_2_joint_0"/>
      <child link="link_fixed_9_hinge"/>
    </joint>

    <material name="gray">
      <color rgba="0.5 0.5 0.5 1.0"/>
    </material>

    <material name="green">
      <color rgba="0 1.0 0 1.0"/>
    </material>

    <material name="green_translucent">
      <color rgba="0 1.0 0 0.25"/>
    </material>

    <material name="lavender">
      <color rgba="0.8 0.8 1.0 1.0"/>
    </material>

    <material name="red">
      <color rgba="1.0 0 0 1.0"/>
    </material>

    <material name="yellow">
      <color rgba="1.0 1.0 0 1.0"/>
    </material>

  </robot>
