<?xml version="1.0"?>
<!-- created with Phobos 1.0.1 "Capricious Choutengan" -->
  <robot name="rooms0">

    <link name="base_link">
    </link>

    <link name="goal">
    </link>

    <link name="link_0_joint_0">
      <visual name="visual_mesh_2_link_0">
        <origin xyz="0 0 0" rpy="0 0 0"/>
        <geometry>
          <mesh filename="file:///home/ubuntu22/ba/puzzle-generator/puzzles/rooms0/meshes/stl/robot.stl" scale="1.0 1.0 1.0"/>
        </geometry>
        <material name="green"/>
      </visual>
      <collision name="collision_mesh_2_link_0">
        <origin xyz="0 0 0" rpy="0 0 0"/>
        <geometry>
          <mesh filename="file:///home/ubuntu22/ba/puzzle-generator/puzzles/rooms0/meshes/stl/robot.001.stl" scale="1.0 1.0 1.0"/>
        </geometry>
      </collision>
    </link>

    <link name="link_0_joint_0.001">
      <visual name="visual_mesh_2_link_0.001">
        <origin xyz="0 0 0" rpy="0 0 0"/>
        <geometry>
          <mesh filename="file:///home/ubuntu22/ba/puzzle-generator/puzzles/rooms0/meshes/stl/robot.002.stl" scale="0.999 0.999 0.999"/>
        </geometry>
        <material name="green_translucent"/>
      </visual>
    </link>

    <link name="link_0_joint_1">
    </link>

    <link name="link_0_joint_1.001">
    </link>

    <link name="link_0_joint_2">
    </link>

    <link name="link_1_joint_0">
      <visual name="visual_cylinder_17_link_1">
        <origin xyz="0 0 0" rpy="0 0 0"/>
        <geometry>
          <cylinder radius="0.1645" length="0.799"/>
        </geometry>
        <material name="gray"/>
      </visual>
      <collision name="collision_cylinder_17_link_1">
        <origin xyz="0 0 0" rpy="0 0 0"/>
        <geometry>
          <cylinder radius="0.1645" length="0.799"/>
        </geometry>
      </collision>
    </link>

    <link name="link_2_joint_0">
      <visual name="visual_cylinder_38_link_2">
        <origin xyz="0 0 0" rpy="0 0 0"/>
        <geometry>
          <cylinder radius="0.1645" length="0.799"/>
        </geometry>
        <material name="gray"/>
      </visual>
      <collision name="collision_cylinder_38_link_2">
        <origin xyz="0 0 0" rpy="0 0 0"/>
        <geometry>
          <cylinder radius="0.1645" length="0.799"/>
        </geometry>
      </collision>
    </link>

    <link name="link_fixed_10_pillar_(-0.4625, 0.4625)">
      <visual name="visual_box_fixed_10_pillar_(-0.4625, 0.4625)">
        <origin xyz="0 0 0" rpy="0 0 0"/>
        <geometry>
          <box size="0.299 0.299 0.799"/>
        </geometry>
        <material name="black"/>
      </visual>
      <collision name="collision_box_fixed_10_pillar_(-0.4625, 0.4625)">
        <origin xyz="0 0 0" rpy="0 0 0"/>
        <geometry>
          <box size="0.299 0.299 0.799"/>
        </geometry>
      </collision>
    </link>

    <link name="link_fixed_11_wall_(0.0, 0.4625)">
      <visual name="visual_box_fixed_11_wall_(0.0, 0.4625)">
        <origin xyz="0 0 0" rpy="0 0 0"/>
        <geometry>
          <box size="3.399 0.299 0.799"/>
        </geometry>
        <material name="gray"/>
      </visual>
      <collision name="collision_box_fixed_11_wall_(0.0, 0.4625)">
        <origin xyz="0 0 0" rpy="0 0 0"/>
        <geometry>
          <box size="3.399 0.299 0.799"/>
        </geometry>
      </collision>
    </link>

    <link name="link_fixed_12_pillar_(-0.4625, -1.4625)">
      <visual name="visual_box_fixed_12_pillar_(-0.4625, -1.4625)">
        <origin xyz="0 0 0" rpy="0 0 0"/>
        <geometry>
          <box size="0.299 0.299 0.799"/>
        </geometry>
        <material name="black"/>
      </visual>
      <collision name="collision_box_fixed_12_pillar_(-0.4625, -1.4625)">
        <origin xyz="0 0 0" rpy="0 0 0"/>
        <geometry>
          <box size="0.299 0.299 0.799"/>
        </geometry>
      </collision>
    </link>

    <link name="link_fixed_13_wall_(-0.4625, -1.0)">
      <visual name="visual_box_fixed_13_wall_(-0.4625, -1.0)">
        <origin xyz="0 0 0" rpy="0 0 0"/>
        <geometry>
          <box size="0.299 3.399 0.799"/>
        </geometry>
        <material name="gray"/>
      </visual>
      <collision name="collision_box_fixed_13_wall_(-0.4625, -1.0)">
        <origin xyz="0 0 0" rpy="0 0 0"/>
        <geometry>
          <box size="0.299 3.399 0.799"/>
        </geometry>
      </collision>
    </link>

    <link name="link_fixed_14_pillar_(0.4625, -1.4625)">
      <visual name="visual_box_fixed_14_pillar_(0.4625, -1.4625)">
        <origin xyz="0 0 0" rpy="0 0 0"/>
        <geometry>
          <box size="0.299 0.299 0.799"/>
        </geometry>
        <material name="black"/>
      </visual>
      <collision name="collision_box_fixed_14_pillar_(0.4625, -1.4625)">
        <origin xyz="0 0 0" rpy="0 0 0"/>
        <geometry>
          <box size="0.299 0.299 0.799"/>
        </geometry>
      </collision>
    </link>

    <link name="link_fixed_15_wall_(-0.3375, -1.4625)">
      <visual name="visual_box_fixed_15_wall_(-0.3375, -1.4625)">
        <origin xyz="0 0 0" rpy="0 0 0"/>
        <geometry>
          <box size="0.699 0.299 0.799"/>
        </geometry>
        <material name="gray"/>
      </visual>
      <collision name="collision_box_fixed_15_wall_(-0.3375, -1.4625)">
        <origin xyz="0 0 0" rpy="0 0 0"/>
        <geometry>
          <box size="0.699 0.299 0.799"/>
        </geometry>
      </collision>
    </link>

    <link name="link_fixed_16_wall_(0.3375, -1.4625)">
      <visual name="visual_box_fixed_16_wall_(0.3375, -1.4625)">
        <origin xyz="0 0 0" rpy="0 0 0"/>
        <geometry>
          <box size="0.699 0.299 0.799"/>
        </geometry>
        <material name="gray"/>
      </visual>
      <collision name="collision_box_fixed_16_wall_(0.3375, -1.4625)">
        <origin xyz="0 0 0" rpy="0 0 0"/>
        <geometry>
          <box size="0.699 0.299 0.799"/>
        </geometry>
      </collision>
    </link>

    <link name="link_fixed_18_hinge">
      <visual name="visual_cylinder_fixed_18_hinge">
        <origin xyz="0 0 0" rpy="0 0 0"/>
        <geometry>
          <cylinder radius="0.04075" length="0.879"/>
        </geometry>
        <material name="gray"/>
      </visual>
    </link>

    <link name="link_fixed_19_door_panel">
      <visual name="visual_box_fixed_19_door_panel">
        <origin xyz="0 0 0" rpy="0 0 0"/>
        <geometry>
          <box size="1.599 0.299 0.795"/>
        </geometry>
        <material name="red"/>
      </visual>
      <collision name="collision_box_fixed_19_door_panel">
        <origin xyz="0 0 0" rpy="0 0 0"/>
        <geometry>
          <box size="1.599 0.299 0.795"/>
        </geometry>
      </collision>
    </link>

    <link name="link_fixed_20_door_handle1">
      <visual name="visual_box_fixed_20_door_handle1">
        <origin xyz="0 0 0" rpy="0 0 0"/>
        <geometry>
          <box size="0.039 0.039 0.199"/>
        </geometry>
        <material name="yellow"/>
      </visual>
      <collision name="collision_box_fixed_20_door_handle1">
        <origin xyz="0 0 0" rpy="0 0 0"/>
        <geometry>
          <box size="0.039 0.039 0.199"/>
        </geometry>
      </collision>
    </link>

    <link name="link_fixed_21_door_handle1_connector">
      <visual name="visual_box_fixed_21_door_handle1_connector">
        <origin xyz="0 0 0" rpy="0 0 0"/>
        <geometry>
          <box size="0.039 0.199 0.039"/>
        </geometry>
        <material name="yellow"/>
      </visual>
      <collision name="collision_box_fixed_21_door_handle1_connector">
        <origin xyz="0 0 0" rpy="0 0 0"/>
        <geometry>
          <box size="0.039 0.199 0.039"/>
        </geometry>
      </collision>
    </link>

    <link name="link_fixed_22_door_handle2">
      <visual name="visual_box_fixed_22_door_handle2">
        <origin xyz="0 0 0" rpy="0 0 0"/>
        <geometry>
          <box size="0.039 0.039 0.199"/>
        </geometry>
        <material name="yellow"/>
      </visual>
      <collision name="collision_box_fixed_22_door_handle2">
        <origin xyz="0 0 0" rpy="0 0 0"/>
        <geometry>
          <box size="0.039 0.039 0.199"/>
        </geometry>
      </collision>
    </link>

    <link name="link_fixed_23_door_handle2_connector">
      <visual name="visual_box_fixed_23_door_handle2_connector">
        <origin xyz="0 0 0" rpy="0 0 0"/>
        <geometry>
          <box size="0.039 0.199 0.039"/>
        </geometry>
        <material name="yellow"/>
      </visual>
      <collision name="collision_box_fixed_23_door_handle2_connector">
        <origin xyz="0 0 0" rpy="0 0 0"/>
        <geometry>
          <box size="0.039 0.199 0.039"/>
        </geometry>
      </collision>
    </link>

    <link name="link_fixed_24_pillar_(0.4625, -0.5375)">
      <visual name="visual_box_fixed_24_pillar_(0.4625, -0.5375)">
        <origin xyz="0 0 0" rpy="0 0 0"/>
        <geometry>
          <box size="0.299 0.299 0.799"/>
        </geometry>
        <material name="black"/>
      </visual>
      <collision name="collision_box_fixed_24_pillar_(0.4625, -0.5375)">
        <origin xyz="0 0 0" rpy="0 0 0"/>
        <geometry>
          <box size="0.299 0.299 0.799"/>
        </geometry>
      </collision>
    </link>

    <link name="link_fixed_25_wall_(0.4625, -1.0)">
      <visual name="visual_box_fixed_25_wall_(0.4625, -1.0)">
        <origin xyz="0 0 0" rpy="0 0 0"/>
        <geometry>
          <box size="0.299 3.399 0.799"/>
        </geometry>
        <material name="gray"/>
      </visual>
      <collision name="collision_box_fixed_25_wall_(0.4625, -1.0)">
        <origin xyz="0 0 0" rpy="0 0 0"/>
        <geometry>
          <box size="0.299 3.399 0.799"/>
        </geometry>
      </collision>
    </link>

    <link name="link_fixed_26_pillar_(-0.4625, -0.5375)">
      <visual name="visual_box_fixed_26_pillar_(-0.4625, -0.5375)">
        <origin xyz="0 0 0" rpy="0 0 0"/>
        <geometry>
          <box size="0.299 0.299 0.799"/>
        </geometry>
        <material name="black"/>
      </visual>
      <collision name="collision_box_fixed_26_pillar_(-0.4625, -0.5375)">
        <origin xyz="0 0 0" rpy="0 0 0"/>
        <geometry>
          <box size="0.299 0.299 0.799"/>
        </geometry>
      </collision>
    </link>

    <link name="link_fixed_27_pillar_(-0.4625, -2.4625)">
      <visual name="visual_box_fixed_27_pillar_(-0.4625, -2.4625)">
        <origin xyz="0 0 0" rpy="0 0 0"/>
        <geometry>
          <box size="0.299 0.299 0.799"/>
        </geometry>
        <material name="black"/>
      </visual>
      <collision name="collision_box_fixed_27_pillar_(-0.4625, -2.4625)">
        <origin xyz="0 0 0" rpy="0 0 0"/>
        <geometry>
          <box size="0.299 0.299 0.799"/>
        </geometry>
      </collision>
    </link>

    <link name="link_fixed_28_wall_(-0.4625, -2.0)">
      <visual name="visual_box_fixed_28_wall_(-0.4625, -2.0)">
        <origin xyz="0 0 0" rpy="0 0 0"/>
        <geometry>
          <box size="0.299 3.399 0.799"/>
        </geometry>
        <material name="gray"/>
      </visual>
      <collision name="collision_box_fixed_28_wall_(-0.4625, -2.0)">
        <origin xyz="0 0 0" rpy="0 0 0"/>
        <geometry>
          <box size="0.299 3.399 0.799"/>
        </geometry>
      </collision>
    </link>

    <link name="link_fixed_29_pillar_(0.4625, -2.4625)">
      <visual name="visual_box_fixed_29_pillar_(0.4625, -2.4625)">
        <origin xyz="0 0 0" rpy="0 0 0"/>
        <geometry>
          <box size="0.299 0.299 0.799"/>
        </geometry>
        <material name="black"/>
      </visual>
      <collision name="collision_box_fixed_29_pillar_(0.4625, -2.4625)">
        <origin xyz="0 0 0" rpy="0 0 0"/>
        <geometry>
          <box size="0.299 0.299 0.799"/>
        </geometry>
      </collision>
    </link>

    <link name="link_fixed_30_wall_(-0.3375, -2.4625)">
      <visual name="visual_box_fixed_30_wall_(-0.3375, -2.4625)">
        <origin xyz="0 0 0" rpy="0 0 0"/>
        <geometry>
          <box size="0.699 0.299 0.799"/>
        </geometry>
        <material name="gray"/>
      </visual>
      <collision name="collision_box_fixed_30_wall_(-0.3375, -2.4625)">
        <origin xyz="0 0 0" rpy="0 0 0"/>
        <geometry>
          <box size="0.699 0.299 0.799"/>
        </geometry>
      </collision>
    </link>

    <link name="link_fixed_31_wall_(0.3375, -2.4625)">
      <visual name="visual_box_fixed_31_wall_(0.3375, -2.4625)">
        <origin xyz="0 0 0" rpy="0 0 0"/>
        <geometry>
          <box size="0.699 0.299 0.799"/>
        </geometry>
        <material name="gray"/>
      </visual>
      <collision name="collision_box_fixed_31_wall_(0.3375, -2.4625)">
        <origin xyz="0 0 0" rpy="0 0 0"/>
        <geometry>
          <box size="0.699 0.299 0.799"/>
        </geometry>
      </collision>
    </link>

    <link name="link_fixed_32_pillar_(0.4625, -1.5375)">
      <visual name="visual_box_fixed_32_pillar_(0.4625, -1.5375)">
        <origin xyz="0 0 0" rpy="0 0 0"/>
        <geometry>
          <box size="0.299 0.299 0.799"/>
        </geometry>
        <material name="black"/>
      </visual>
      <collision name="collision_box_fixed_32_pillar_(0.4625, -1.5375)">
        <origin xyz="0 0 0" rpy="0 0 0"/>
        <geometry>
          <box size="0.299 0.299 0.799"/>
        </geometry>
      </collision>
    </link>

    <link name="link_fixed_33_wall_(0.4625, -2.0)">
      <visual name="visual_box_fixed_33_wall_(0.4625, -2.0)">
        <origin xyz="0 0 0" rpy="0 0 0"/>
        <geometry>
          <box size="0.299 3.399 0.799"/>
        </geometry>
        <material name="gray"/>
      </visual>
      <collision name="collision_box_fixed_33_wall_(0.4625, -2.0)">
        <origin xyz="0 0 0" rpy="0 0 0"/>
        <geometry>
          <box size="0.299 3.399 0.799"/>
        </geometry>
      </collision>
    </link>

    <link name="link_fixed_34_pillar_(-0.4625, -1.5375)">
      <visual name="visual_box_fixed_34_pillar_(-0.4625, -1.5375)">
        <origin xyz="0 0 0" rpy="0 0 0"/>
        <geometry>
          <box size="0.299 0.299 0.799"/>
        </geometry>
        <material name="black"/>
      </visual>
      <collision name="collision_box_fixed_34_pillar_(-0.4625, -1.5375)">
        <origin xyz="0 0 0" rpy="0 0 0"/>
        <geometry>
          <box size="0.299 0.299 0.799"/>
        </geometry>
      </collision>
    </link>

    <link name="link_fixed_35_pillar_(-0.4625, -3.4625)">
      <visual name="visual_box_fixed_35_pillar_(-0.4625, -3.4625)">
        <origin xyz="0 0 0" rpy="0 0 0"/>
        <geometry>
          <box size="0.299 0.299 0.799"/>
        </geometry>
        <material name="black"/>
      </visual>
      <collision name="collision_box_fixed_35_pillar_(-0.4625, -3.4625)">
        <origin xyz="0 0 0" rpy="0 0 0"/>
        <geometry>
          <box size="0.299 0.299 0.799"/>
        </geometry>
      </collision>
    </link>

    <link name="link_fixed_36_wall_(-0.4625, -3.3375)">
      <visual name="visual_box_fixed_36_wall_(-0.4625, -3.3375)">
        <origin xyz="0 0 0" rpy="0 0 0"/>
        <geometry>
          <box size="0.299 0.699 0.799"/>
        </geometry>
        <material name="gray"/>
      </visual>
      <collision name="collision_box_fixed_36_wall_(-0.4625, -3.3375)">
        <origin xyz="0 0 0" rpy="0 0 0"/>
        <geometry>
          <box size="0.299 0.699 0.799"/>
        </geometry>
      </collision>
    </link>

    <link name="link_fixed_37_wall_(-0.4625, -2.6625)">
      <visual name="visual_box_fixed_37_wall_(-0.4625, -2.6625)">
        <origin xyz="0 0 0" rpy="0 0 0"/>
        <geometry>
          <box size="0.299 0.699 0.799"/>
        </geometry>
        <material name="gray"/>
      </visual>
      <collision name="collision_box_fixed_37_wall_(-0.4625, -2.6625)">
        <origin xyz="0 0 0" rpy="0 0 0"/>
        <geometry>
          <box size="0.299 0.699 0.799"/>
        </geometry>
      </collision>
    </link>

    <link name="link_fixed_39_hinge">
      <visual name="visual_cylinder_fixed_39_hinge">
        <origin xyz="0 0 0" rpy="0 0 0"/>
        <geometry>
          <cylinder radius="0.04075" length="0.879"/>
        </geometry>
        <material name="gray"/>
      </visual>
    </link>

    <link name="link_fixed_3_pillar_(-0.4625, -0.4625)">
      <visual name="visual_box_fixed_3_pillar_(-0.4625, -0.4625)">
        <origin xyz="0 0 0" rpy="0 0 0"/>
        <geometry>
          <box size="0.299 0.299 0.799"/>
        </geometry>
        <material name="black"/>
      </visual>
      <collision name="collision_box_fixed_3_pillar_(-0.4625, -0.4625)">
        <origin xyz="0 0 0" rpy="0 0 0"/>
        <geometry>
          <box size="0.299 0.299 0.799"/>
        </geometry>
      </collision>
    </link>

    <link name="link_fixed_40_door_panel">
      <visual name="visual_box_fixed_40_door_panel">
        <origin xyz="0 0 0" rpy="0 0 0"/>
        <geometry>
          <box size="1.599 0.299 0.795"/>
        </geometry>
        <material name="red"/>
      </visual>
      <collision name="collision_box_fixed_40_door_panel">
        <origin xyz="0 0 0" rpy="0 0 0"/>
        <geometry>
          <box size="1.599 0.299 0.795"/>
        </geometry>
      </collision>
    </link>

    <link name="link_fixed_41_door_handle1">
      <visual name="visual_box_fixed_41_door_handle1">
        <origin xyz="0 0 0" rpy="0 0 0"/>
        <geometry>
          <box size="0.039 0.039 0.199"/>
        </geometry>
        <material name="yellow"/>
      </visual>
      <collision name="collision_box_fixed_41_door_handle1">
        <origin xyz="0 0 0" rpy="0 0 0"/>
        <geometry>
          <box size="0.039 0.039 0.199"/>
        </geometry>
      </collision>
    </link>

    <link name="link_fixed_42_door_handle1_connector">
      <visual name="visual_box_fixed_42_door_handle1_connector">
        <origin xyz="0 0 0" rpy="0 0 0"/>
        <geometry>
          <box size="0.039 0.199 0.039"/>
        </geometry>
        <material name="yellow"/>
      </visual>
      <collision name="collision_box_fixed_42_door_handle1_connector">
        <origin xyz="0 0 0" rpy="0 0 0"/>
        <geometry>
          <box size="0.039 0.199 0.039"/>
        </geometry>
      </collision>
    </link>

    <link name="link_fixed_43_door_handle2">
      <visual name="visual_box_fixed_43_door_handle2">
        <origin xyz="0 0 0" rpy="0 0 0"/>
        <geometry>
          <box size="0.039 0.039 0.199"/>
        </geometry>
        <material name="yellow"/>
      </visual>
      <collision name="collision_box_fixed_43_door_handle2">
        <origin xyz="0 0 0" rpy="0 0 0"/>
        <geometry>
          <box size="0.039 0.039 0.199"/>
        </geometry>
      </collision>
    </link>

    <link name="link_fixed_44_door_handle2_connector">
      <visual name="visual_box_fixed_44_door_handle2_connector">
        <origin xyz="0 0 0" rpy="0 0 0"/>
        <geometry>
          <box size="0.039 0.199 0.039"/>
        </geometry>
        <material name="yellow"/>
      </visual>
      <collision name="collision_box_fixed_44_door_handle2_connector">
        <origin xyz="0 0 0" rpy="0 0 0"/>
        <geometry>
          <box size="0.039 0.199 0.039"/>
        </geometry>
      </collision>
    </link>

    <link name="link_fixed_45_pillar_(0.4625, -3.4625)">
      <visual name="visual_box_fixed_45_pillar_(0.4625, -3.4625)">
        <origin xyz="0 0 0" rpy="0 0 0"/>
        <geometry>
          <box size="0.299 0.299 0.799"/>
        </geometry>
        <material name="black"/>
      </visual>
      <collision name="collision_box_fixed_45_pillar_(0.4625, -3.4625)">
        <origin xyz="0 0 0" rpy="0 0 0"/>
        <geometry>
          <box size="0.299 0.299 0.799"/>
        </geometry>
      </collision>
    </link>

    <link name="link_fixed_46_wall_(0.0, -3.4625)">
      <visual name="visual_box_fixed_46_wall_(0.0, -3.4625)">
        <origin xyz="0 0 0" rpy="0 0 0"/>
        <geometry>
          <box size="3.399 0.299 0.799"/>
        </geometry>
        <material name="gray"/>
      </visual>
      <collision name="collision_box_fixed_46_wall_(0.0, -3.4625)">
        <origin xyz="0 0 0" rpy="0 0 0"/>
        <geometry>
          <box size="3.399 0.299 0.799"/>
        </geometry>
      </collision>
    </link>

    <link name="link_fixed_47_pillar_(0.4625, -2.5375)">
      <visual name="visual_box_fixed_47_pillar_(0.4625, -2.5375)">
        <origin xyz="0 0 0" rpy="0 0 0"/>
        <geometry>
          <box size="0.299 0.299 0.799"/>
        </geometry>
        <material name="black"/>
      </visual>
      <collision name="collision_box_fixed_47_pillar_(0.4625, -2.5375)">
        <origin xyz="0 0 0" rpy="0 0 0"/>
        <geometry>
          <box size="0.299 0.299 0.799"/>
        </geometry>
      </collision>
    </link>

    <link name="link_fixed_48_wall_(0.4625, -3.0)">
      <visual name="visual_box_fixed_48_wall_(0.4625, -3.0)">
        <origin xyz="0 0 0" rpy="0 0 0"/>
        <geometry>
          <box size="0.299 3.399 0.799"/>
        </geometry>
        <material name="gray"/>
      </visual>
      <collision name="collision_box_fixed_48_wall_(0.4625, -3.0)">
        <origin xyz="0 0 0" rpy="0 0 0"/>
        <geometry>
          <box size="0.299 3.399 0.799"/>
        </geometry>
      </collision>
    </link>

    <link name="link_fixed_49_pillar_(-0.4625, -2.5375)">
      <visual name="visual_box_fixed_49_pillar_(-0.4625, -2.5375)">
        <origin xyz="0 0 0" rpy="0 0 0"/>
        <geometry>
          <box size="0.299 0.299 0.799"/>
        </geometry>
        <material name="black"/>
      </visual>
      <collision name="collision_box_fixed_49_pillar_(-0.4625, -2.5375)">
        <origin xyz="0 0 0" rpy="0 0 0"/>
        <geometry>
          <box size="0.299 0.299 0.799"/>
        </geometry>
      </collision>
    </link>

    <link name="link_fixed_4_wall_(-0.4625, 0.0)">
      <visual name="visual_box_fixed_4_wall_(-0.4625, 0.0)">
        <origin xyz="0 0 0" rpy="0 0 0"/>
        <geometry>
          <box size="0.299 3.399 0.799"/>
        </geometry>
        <material name="gray"/>
      </visual>
      <collision name="collision_box_fixed_4_wall_(-0.4625, 0.0)">
        <origin xyz="0 0 0" rpy="0 0 0"/>
        <geometry>
          <box size="0.299 3.399 0.799"/>
        </geometry>
      </collision>
    </link>

    <link name="link_fixed_5_pillar_(0.4625, -0.4625)">
      <visual name="visual_box_fixed_5_pillar_(0.4625, -0.4625)">
        <origin xyz="0 0 0" rpy="0 0 0"/>
        <geometry>
          <box size="0.299 0.299 0.799"/>
        </geometry>
        <material name="black"/>
      </visual>
      <collision name="collision_box_fixed_5_pillar_(0.4625, -0.4625)">
        <origin xyz="0 0 0" rpy="0 0 0"/>
        <geometry>
          <box size="0.299 0.299 0.799"/>
        </geometry>
      </collision>
    </link>

    <link name="link_fixed_6_wall_(-0.3375, -0.4625)">
      <visual name="visual_box_fixed_6_wall_(-0.3375, -0.4625)">
        <origin xyz="0 0 0" rpy="0 0 0"/>
        <geometry>
          <box size="0.699 0.299 0.799"/>
        </geometry>
        <material name="gray"/>
      </visual>
      <collision name="collision_box_fixed_6_wall_(-0.3375, -0.4625)">
        <origin xyz="0 0 0" rpy="0 0 0"/>
        <geometry>
          <box size="0.699 0.299 0.799"/>
        </geometry>
      </collision>
    </link>

    <link name="link_fixed_7_wall_(0.3375, -0.4625)">
      <visual name="visual_box_fixed_7_wall_(0.3375, -0.4625)">
        <origin xyz="0 0 0" rpy="0 0 0"/>
        <geometry>
          <box size="0.699 0.299 0.799"/>
        </geometry>
        <material name="gray"/>
      </visual>
      <collision name="collision_box_fixed_7_wall_(0.3375, -0.4625)">
        <origin xyz="0 0 0" rpy="0 0 0"/>
        <geometry>
          <box size="0.699 0.299 0.799"/>
        </geometry>
      </collision>
    </link>

    <link name="link_fixed_8_pillar_(0.4625, 0.4625)">
      <visual name="visual_box_fixed_8_pillar_(0.4625, 0.4625)">
        <origin xyz="0 0 0" rpy="0 0 0"/>
        <geometry>
          <box size="0.299 0.299 0.799"/>
        </geometry>
        <material name="black"/>
      </visual>
      <collision name="collision_box_fixed_8_pillar_(0.4625, 0.4625)">
        <origin xyz="0 0 0" rpy="0 0 0"/>
        <geometry>
          <box size="0.299 0.299 0.799"/>
        </geometry>
      </collision>
    </link>

    <link name="link_fixed_9_wall_(0.4625, 0.0)">
      <visual name="visual_box_fixed_9_wall_(0.4625, 0.0)">
        <origin xyz="0 0 0" rpy="0 0 0"/>
        <geometry>
          <box size="0.299 3.399 0.799"/>
        </geometry>
        <material name="gray"/>
      </visual>
      <collision name="collision_box_fixed_9_wall_(0.4625, 0.0)">
        <origin xyz="0 0 0" rpy="0 0 0"/>
        <geometry>
          <box size="0.299 3.399 0.799"/>
        </geometry>
      </collision>
    </link>

    <joint name="goal" type="fixed">
      <origin xyz="-4.0 -12.0 0.25" rpy="0 0 0"/>
      <parent link="base_link"/>
      <child link="goal"/>
      <limit effort="0" velocity="0"/>
    </joint>

    <joint name="link_0_joint_0" type="fixed">
      <origin xyz="0 0 0" rpy="0 0 0"/>
      <parent link="link_0_joint_1"/>
      <child link="link_0_joint_0"/>
      <limit effort="0" velocity="0"/>
    </joint>

    <joint name="link_0_joint_0.001" type="fixed">
      <origin xyz="0 0 0" rpy="0 0 0"/>
      <parent link="link_0_joint_1.001"/>
      <child link="link_0_joint_0.001"/>
      <limit effort="0" velocity="0"/>
    </joint>

    <joint name="link_0_joint_1" type="prismatic">
      <origin xyz="0 0 0" rpy="0 0 0"/>
      <parent link="link_0_joint_2"/>
      <child link="link_0_joint_1"/>
      <axis xyz="0 1.0 0"/>
      <limit lower="-14.0" upper="2.0" effort="0" velocity="0"/>
    </joint>

    <joint name="link_0_joint_1.001" type="fixed">
      <origin xyz="0 0 0" rpy="0 0 0"/>
      <parent link="goal"/>
      <child link="link_0_joint_1.001"/>
      <limit effort="0" velocity="0"/>
    </joint>

    <joint name="link_0_joint_2" type="prismatic">
      <origin xyz="0 0 0.25" rpy="0 0 0"/>
      <parent link="base_link"/>
      <child link="link_0_joint_2"/>
      <axis xyz="1.0 0 0"/>
      <limit lower="-6.0" upper="2.0" effort="0" velocity="0"/>
    </joint>

    <joint name="link_1_joint_0" type="revolute">
      <origin xyz="-0.8 -5.85 0.4" rpy="0 0 0"/>
      <parent link="base_link"/>
      <child link="link_1_joint_0"/>
      <axis xyz="0 0 1.0"/>
      <limit lower="0" upper="1.5708" effort="0" velocity="0"/>
    </joint>

    <joint name="link_2_joint_0" type="revolute">
      <origin xyz="-1.85 -11.2 0.4" rpy="0 0 -1.5708"/>
      <parent link="base_link"/>
      <child link="link_2_joint_0"/>
      <axis xyz="0 0 1.0"/>
      <limit lower="0" upper="1.5708" effort="0" velocity="0"/>
    </joint>

    <joint name="link_fixed_10_pillar_(-0.4625, 0.4625)" type="fixed">
      <origin xyz="-1.85 1.85 0.4" rpy="0 0 0"/>
      <parent link="base_link"/>
      <child link="link_fixed_10_pillar_(-0.4625, 0.4625)"/>
    </joint>

    <joint name="link_fixed_11_wall_(0.0, 0.4625)" type="fixed">
      <origin xyz="0 1.85 0.4" rpy="0 0 0"/>
      <parent link="base_link"/>
      <child link="link_fixed_11_wall_(0.0, 0.4625)"/>
    </joint>

    <joint name="link_fixed_12_pillar_(-0.4625, -1.4625)" type="fixed">
      <origin xyz="-1.85 -5.85 0.4" rpy="0 0 0"/>
      <parent link="base_link"/>
      <child link="link_fixed_12_pillar_(-0.4625, -1.4625)"/>
    </joint>

    <joint name="link_fixed_13_wall_(-0.4625, -1.0)" type="fixed">
      <origin xyz="-1.85 -4.0 0.4" rpy="0 0 0"/>
      <parent link="base_link"/>
      <child link="link_fixed_13_wall_(-0.4625, -1.0)"/>
    </joint>

    <joint name="link_fixed_14_pillar_(0.4625, -1.4625)" type="fixed">
      <origin xyz="1.85 -5.85 0.4" rpy="0 0 0"/>
      <parent link="base_link"/>
      <child link="link_fixed_14_pillar_(0.4625, -1.4625)"/>
    </joint>

    <joint name="link_fixed_15_wall_(-0.3375, -1.4625)" type="fixed">
      <origin xyz="-1.35 -5.85 0.4" rpy="0 0 0"/>
      <parent link="base_link"/>
      <child link="link_fixed_15_wall_(-0.3375, -1.4625)"/>
    </joint>

    <joint name="link_fixed_16_wall_(0.3375, -1.4625)" type="fixed">
      <origin xyz="1.35 -5.85 0.4" rpy="0 0 0"/>
      <parent link="base_link"/>
      <child link="link_fixed_16_wall_(0.3375, -1.4625)"/>
    </joint>

    <joint name="link_fixed_18_hinge" type="fixed">
      <origin xyz="0 0 0" rpy="0 0 0"/>
      <parent link="link_1_joint_0"/>
      <child link="link_fixed_18_hinge"/>
    </joint>

    <joint name="link_fixed_19_door_panel" type="fixed">
      <origin xyz="0.8 0 0" rpy="0 0 0"/>
      <parent link="link_1_joint_0"/>
      <child link="link_fixed_19_door_panel"/>
    </joint>

    <joint name="link_fixed_20_door_handle1" type="fixed">
      <origin xyz="1.2 0.37 0" rpy="0 0 0"/>
      <parent link="link_1_joint_0"/>
      <child link="link_fixed_20_door_handle1"/>
    </joint>

    <joint name="link_fixed_21_door_handle1_connector" type="fixed">
      <origin xyz="1.2 0.25 -0.08" rpy="0 0 0"/>
      <parent link="link_1_joint_0"/>
      <child link="link_fixed_21_door_handle1_connector"/>
    </joint>

    <joint name="link_fixed_22_door_handle2" type="fixed">
      <origin xyz="1.2 -0.37 0" rpy="0 0 0"/>
      <parent link="link_1_joint_0"/>
      <child link="link_fixed_22_door_handle2"/>
    </joint>

    <joint name="link_fixed_23_door_handle2_connector" type="fixed">
      <origin xyz="1.2 -0.25 -0.08" rpy="0 0 0"/>
      <parent link="link_1_joint_0"/>
      <child link="link_fixed_23_door_handle2_connector"/>
    </joint>

    <joint name="link_fixed_24_pillar_(0.4625, -0.5375)" type="fixed">
      <origin xyz="1.85 -2.15 0.4" rpy="0 0 0"/>
      <parent link="base_link"/>
      <child link="link_fixed_24_pillar_(0.4625, -0.5375)"/>
    </joint>

    <joint name="link_fixed_25_wall_(0.4625, -1.0)" type="fixed">
      <origin xyz="1.85 -4.0 0.4" rpy="0 0 0"/>
      <parent link="base_link"/>
      <child link="link_fixed_25_wall_(0.4625, -1.0)"/>
    </joint>

    <joint name="link_fixed_26_pillar_(-0.4625, -0.5375)" type="fixed">
      <origin xyz="-1.85 -2.15 0.4" rpy="0 0 0"/>
      <parent link="base_link"/>
      <child link="link_fixed_26_pillar_(-0.4625, -0.5375)"/>
    </joint>

    <joint name="link_fixed_27_pillar_(-0.4625, -2.4625)" type="fixed">
      <origin xyz="-1.85 -9.85 0.4" rpy="0 0 0"/>
      <parent link="base_link"/>
      <child link="link_fixed_27_pillar_(-0.4625, -2.4625)"/>
    </joint>

    <joint name="link_fixed_28_wall_(-0.4625, -2.0)" type="fixed">
      <origin xyz="-1.85 -8.0 0.4" rpy="0 0 0"/>
      <parent link="base_link"/>
      <child link="link_fixed_28_wall_(-0.4625, -2.0)"/>
    </joint>

    <joint name="link_fixed_29_pillar_(0.4625, -2.4625)" type="fixed">
      <origin xyz="1.85 -9.85 0.4" rpy="0 0 0"/>
      <parent link="base_link"/>
      <child link="link_fixed_29_pillar_(0.4625, -2.4625)"/>
    </joint>

    <joint name="link_fixed_30_wall_(-0.3375, -2.4625)" type="fixed">
      <origin xyz="-1.35 -9.85 0.4" rpy="0 0 0"/>
      <parent link="base_link"/>
      <child link="link_fixed_30_wall_(-0.3375, -2.4625)"/>
    </joint>

    <joint name="link_fixed_31_wall_(0.3375, -2.4625)" type="fixed">
      <origin xyz="1.35 -9.85 0.4" rpy="0 0 0"/>
      <parent link="base_link"/>
      <child link="link_fixed_31_wall_(0.3375, -2.4625)"/>
    </joint>

    <joint name="link_fixed_32_pillar_(0.4625, -1.5375)" type="fixed">
      <origin xyz="1.85 -6.15 0.4" rpy="0 0 0"/>
      <parent link="base_link"/>
      <child link="link_fixed_32_pillar_(0.4625, -1.5375)"/>
    </joint>

    <joint name="link_fixed_33_wall_(0.4625, -2.0)" type="fixed">
      <origin xyz="1.85 -8.0 0.4" rpy="0 0 0"/>
      <parent link="base_link"/>
      <child link="link_fixed_33_wall_(0.4625, -2.0)"/>
    </joint>

    <joint name="link_fixed_34_pillar_(-0.4625, -1.5375)" type="fixed">
      <origin xyz="-1.85 -6.15 0.4" rpy="0 0 0"/>
      <parent link="base_link"/>
      <child link="link_fixed_34_pillar_(-0.4625, -1.5375)"/>
    </joint>

    <joint name="link_fixed_35_pillar_(-0.4625, -3.4625)" type="fixed">
      <origin xyz="-1.85 -13.85 0.4" rpy="0 0 0"/>
      <parent link="base_link"/>
      <child link="link_fixed_35_pillar_(-0.4625, -3.4625)"/>
    </joint>

    <joint name="link_fixed_36_wall_(-0.4625, -3.3375)" type="fixed">
      <origin xyz="-1.85 -13.35 0.4" rpy="0 0 0"/>
      <parent link="base_link"/>
      <child link="link_fixed_36_wall_(-0.4625, -3.3375)"/>
    </joint>

    <joint name="link_fixed_37_wall_(-0.4625, -2.6625)" type="fixed">
      <origin xyz="-1.85 -10.65 0.4" rpy="0 0 0"/>
      <parent link="base_link"/>
      <child link="link_fixed_37_wall_(-0.4625, -2.6625)"/>
    </joint>

    <joint name="link_fixed_39_hinge" type="fixed">
      <origin xyz="0 0 0" rpy="0 0 0"/>
      <parent link="link_2_joint_0"/>
      <child link="link_fixed_39_hinge"/>
    </joint>

    <joint name="link_fixed_3_pillar_(-0.4625, -0.4625)" type="fixed">
      <origin xyz="-1.85 -1.85 0.4" rpy="0 0 0"/>
      <parent link="base_link"/>
      <child link="link_fixed_3_pillar_(-0.4625, -0.4625)"/>
    </joint>

    <joint name="link_fixed_40_door_panel" type="fixed">
      <origin xyz="0.8 0 0" rpy="0 0 0"/>
      <parent link="link_2_joint_0"/>
      <child link="link_fixed_40_door_panel"/>
    </joint>

    <joint name="link_fixed_41_door_handle1" type="fixed">
      <origin xyz="1.2 0.37 0" rpy="0 0 0"/>
      <parent link="link_2_joint_0"/>
      <child link="link_fixed_41_door_handle1"/>
    </joint>

    <joint name="link_fixed_42_door_handle1_connector" type="fixed">
      <origin xyz="1.2 0.25 -0.08" rpy="0 0 0"/>
      <parent link="link_2_joint_0"/>
      <child link="link_fixed_42_door_handle1_connector"/>
    </joint>

    <joint name="link_fixed_43_door_handle2" type="fixed">
      <origin xyz="1.2 -0.37 0" rpy="0 0 0"/>
      <parent link="link_2_joint_0"/>
      <child link="link_fixed_43_door_handle2"/>
    </joint>

    <joint name="link_fixed_44_door_handle2_connector" type="fixed">
      <origin xyz="1.2 -0.25 -0.08" rpy="0 0 0"/>
      <parent link="link_2_joint_0"/>
      <child link="link_fixed_44_door_handle2_connector"/>
    </joint>

    <joint name="link_fixed_45_pillar_(0.4625, -3.4625)" type="fixed">
      <origin xyz="1.85 -13.85 0.4" rpy="0 0 0"/>
      <parent link="base_link"/>
      <child link="link_fixed_45_pillar_(0.4625, -3.4625)"/>
    </joint>

    <joint name="link_fixed_46_wall_(0.0, -3.4625)" type="fixed">
      <origin xyz="0 -13.85 0.4" rpy="0 0 0"/>
      <parent link="base_link"/>
      <child link="link_fixed_46_wall_(0.0, -3.4625)"/>
    </joint>

    <joint name="link_fixed_47_pillar_(0.4625, -2.5375)" type="fixed">
      <origin xyz="1.85 -10.15 0.4" rpy="0 0 0"/>
      <parent link="base_link"/>
      <child link="link_fixed_47_pillar_(0.4625, -2.5375)"/>
    </joint>

    <joint name="link_fixed_48_wall_(0.4625, -3.0)" type="fixed">
      <origin xyz="1.85 -12.0 0.4" rpy="0 0 0"/>
      <parent link="base_link"/>
      <child link="link_fixed_48_wall_(0.4625, -3.0)"/>
    </joint>

    <joint name="link_fixed_49_pillar_(-0.4625, -2.5375)" type="fixed">
      <origin xyz="-1.85 -10.15 0.4" rpy="0 0 0"/>
      <parent link="base_link"/>
      <child link="link_fixed_49_pillar_(-0.4625, -2.5375)"/>
    </joint>

    <joint name="link_fixed_4_wall_(-0.4625, 0.0)" type="fixed">
      <origin xyz="-1.85 0 0.4" rpy="0 0 0"/>
      <parent link="base_link"/>
      <child link="link_fixed_4_wall_(-0.4625, 0.0)"/>
    </joint>

    <joint name="link_fixed_5_pillar_(0.4625, -0.4625)" type="fixed">
      <origin xyz="1.85 -1.85 0.4" rpy="0 0 0"/>
      <parent link="base_link"/>
      <child link="link_fixed_5_pillar_(0.4625, -0.4625)"/>
    </joint>

    <joint name="link_fixed_6_wall_(-0.3375, -0.4625)" type="fixed">
      <origin xyz="-1.35 -1.85 0.4" rpy="0 0 0"/>
      <parent link="base_link"/>
      <child link="link_fixed_6_wall_(-0.3375, -0.4625)"/>
    </joint>

    <joint name="link_fixed_7_wall_(0.3375, -0.4625)" type="fixed">
      <origin xyz="1.35 -1.85 0.4" rpy="0 0 0"/>
      <parent link="base_link"/>
      <child link="link_fixed_7_wall_(0.3375, -0.4625)"/>
    </joint>

    <joint name="link_fixed_8_pillar_(0.4625, 0.4625)" type="fixed">
      <origin xyz="1.85 1.85 0.4" rpy="0 0 0"/>
      <parent link="base_link"/>
      <child link="link_fixed_8_pillar_(0.4625, 0.4625)"/>
    </joint>

    <joint name="link_fixed_9_wall_(0.4625, 0.0)" type="fixed">
      <origin xyz="1.85 0 0.4" rpy="0 0 0"/>
      <parent link="base_link"/>
      <child link="link_fixed_9_wall_(0.4625, 0.0)"/>
    </joint>

    <material name="black">
      <color rgba="0 0 0 1.0"/>
    </material>

    <material name="gray">
      <color rgba="0.5 0.5 0.5 1.0"/>
    </material>

    <material name="green">
      <color rgba="0 1.0 0 1.0"/>
    </material>

    <material name="green_translucent">
      <color rgba="0 1.0 0 0.25"/>
    </material>

    <material name="red">
      <color rgba="1.0 0 0 1.0"/>
    </material>

    <material name="yellow">
      <color rgba="1.0 1.0 0 1.0"/>
    </material>

  </robot>
