<?xml version="1.0"?>
<!-- created with Phobos 1.0.1 "Capricious Choutengan" -->
  <robot name="my_custom">

    <link name="base_link">
      <inertial>
        <origin xyz="0 0 0" rpy="0 0 0"/>
        <mass value="0.001"/>
        <inertia ixx="0.001" ixy="0" ixz="0" iyy="0.001" iyz="0" izz="0.001"/>
      </inertial>
      <visual name="visual_cube_base">
        <origin xyz="0 0 0" rpy="0 0 0"/>
        <geometry>
          <box size="32.0 32.0 0.2"/>
        </geometry>
        <material name="lavender"/>
      </visual>
      <collision name="collision_cube_base">
        <origin xyz="0 0 0" rpy="0 0 0"/>
        <geometry>
          <box size="32.0 32.0 0.2"/>
        </geometry>
      </collision>
    </link>

    <link name="link_0">
      <inertial>
        <origin xyz="0 0 0" rpy="0 0 0"/>
        <mass value="0.001"/>
        <inertia ixx="0.001" ixy="0" ixz="0" iyy="0.001" iyz="0" izz="0.001"/>
      </inertial>
      <visual name="visual_cube_0.0">
        <origin xyz="1.0 0 0" rpy="0 0 0"/>
        <geometry>
          <box size="2.0 1.0 2.0"/>
        </geometry>
        <material name="green"/>
      </visual>
      <visual name="visual_cylinder_0">
        <origin xyz="0 0 0" rpy="0 0 0"/>
        <geometry>
          <cylinder radius="0.5" length="2.0"/>
        </geometry>
        <material name="green"/>
      </visual>
      <collision name="collision_cube_0.0">
        <origin xyz="1.0 0 0" rpy="0 0 0"/>
        <geometry>
          <box size="2.0 1.0 2.0"/>
        </geometry>
      </collision>
      <collision name="collision_cylinder_0">
        <origin xyz="0 0 0" rpy="0 0 0"/>
        <geometry>
          <cylinder radius="0.5" length="2.0"/>
        </geometry>
      </collision>
    </link>

    <link name="link_1">
      <inertial>
        <origin xyz="0 0 0" rpy="0 0 0"/>
        <mass value="0.001"/>
        <inertia ixx="0.001" ixy="0" ixz="0" iyy="0.001" iyz="0" izz="0.001"/>
      </inertial>
      <visual name="visual_cube_1">
        <origin xyz="0 0 0" rpy="0 0 0"/>
        <geometry>
          <box size="1.0 1.0 4.0"/>
        </geometry>
        <material name="red"/>
      </visual>
      <collision name="collision_cube_1">
        <origin xyz="0 0 0" rpy="0 0 0"/>
        <geometry>
          <box size="1.0 1.0 4.0"/>
        </geometry>
      </collision>
    </link>

    <link name="link_2">
      <inertial>
        <origin xyz="0 0 0" rpy="0 0 0"/>
        <mass value="0.001"/>
        <inertia ixx="0.001" ixy="0" ixz="0" iyy="0.001" iyz="0" izz="0.001"/>
      </inertial>
      <visual name="visual_mesh_2">
        <origin xyz="0 0 0" rpy="0 0 0"/>
        <geometry>
          <mesh filename="file:///home/userone/ba/puzzle-generator/puzzles/my_custom/meshes/stl/slot_disc.stl" scale="1.0 1.0 1.0"/>
        </geometry>
        <material name="red"/>
      </visual>
      <collision concave="yes" name="collision_mesh_2">
        <origin xyz="-0.03587 0 0" rpy="0 0 0"/>
        <geometry>
          <mesh filename="file:///home/userone/ba/puzzle-generator/puzzles/my_custom/meshes/stl/slot_disc.001.stl" scale="1.0 1.0 1.0"/>
        </geometry>
      </collision>
    </link>

    <link name="link_door_3">
      <inertial>
        <origin xyz="0 0 0" rpy="0 0 0"/>
        <mass value="0.001"/>
        <inertia ixx="0.001" ixy="0" ixz="0" iyy="0.001" iyz="0" izz="0.001"/>
      </inertial>
      <visual name="visual_cube_door_3.0">
        <origin xyz="1.0 0 0" rpy="0 0 0"/>
        <geometry>
          <box size="2.0 0.2 4.0"/>
        </geometry>
        <material name="red"/>
      </visual>
      <visual name="visual_cylinder_door_3">
        <origin xyz="0 0 0" rpy="0 0 0"/>
        <geometry>
          <cylinder radius="0.2" length="4.0"/>
        </geometry>
        <material name="gray"/>
      </visual>
      <collision name="collision_cube_door_3.0">
        <origin xyz="1.0 0 0" rpy="0 0 0"/>
        <geometry>
          <box size="2.0 0.2 4.0"/>
        </geometry>
      </collision>
      <collision name="collision_cylinder_door_3">
        <origin xyz="0 0 0" rpy="0 0 0"/>
        <geometry>
          <cylinder radius="0.2" length="4.0"/>
        </geometry>
      </collision>
    </link>

    <joint name="link_0" type="revolute">
      <origin xyz="0 5.0 1.1" rpy="0 0 0"/>
      <parent link="base_link"/>
      <child link="link_0"/>
      <axis xyz="0 0 1.0"/>
      <limit lower="-0.7854" upper="0.7854" effort="0" velocity="0"/>
    </joint>

    <joint name="link_1" type="prismatic">
      <origin xyz="0 0 0.6" rpy="-1.5708 0 0.7854"/>
      <parent link="base_link"/>
      <child link="link_1"/>
      <axis xyz="0 0 1.0"/>
      <limit lower="0" upper="2.0" effort="0" velocity="0"/>
    </joint>

    <joint name="link_2" type="revolute">
      <origin xyz="0 -5.0 0.6" rpy="0 0 0"/>
      <parent link="base_link"/>
      <child link="link_2"/>
      <axis xyz="0 0 1.0"/>
      <limit lower="-0.7854" upper="0.7854" effort="0" velocity="0"/>
    </joint>

    <joint name="link_door_3" type="revolute">
      <origin xyz="4.0 4.0 2.1" rpy="0 0 0"/>
      <parent link="base_link"/>
      <child link="link_door_3"/>
      <axis xyz="0 0 1.0"/>
      <limit lower="0" upper="1.5708" effort="0" velocity="0"/>
    </joint>

    <material name="gray">
      <color rgba="0.5 0.5 0.5 1.0"/>
    </material>

    <material name="green">
      <color rgba="0 1.0 0 1.0"/>
    </material>

    <material name="lavender">
      <color rgba="0.8 0.8 1.0 1.0"/>
    </material>

    <material name="red">
      <color rgba="1.0 0 0 1.0"/>
    </material>

  </robot>
