<?xml version="1.0"?>
<!-- created with Phobos 1.0.1 "Capricious Choutengan" -->
  <robot name="continuous_space">

    <link name="base_link">
      <inertial>
        <origin xyz="0 0 0" rpy="0 0 0"/>
        <mass value="0.001"/>
        <inertia ixx="0.001" ixy="0" ixz="0" iyy="0.001" iyz="0" izz="0.001"/>
      </inertial>
      <visual name="visual_box_base">
        <origin xyz="0 0 0" rpy="0 0 0"/>
        <geometry>
          <box size="32.0 32.0 0.2"/>
        </geometry>
        <material name="lavender"/>
      </visual>
      <collision name="collision_box_base">
        <origin xyz="0 0 0" rpy="0 0 0"/>
        <geometry>
          <box size="32.0 32.0 0.2"/>
        </geometry>
      </collision>
    </link>

    <link name="goal">
      <inertial>
        <origin xyz="0 0 0" rpy="0 0 0"/>
        <mass value="0.001"/>
        <inertia ixx="0.001" ixy="0" ixz="0" iyy="0.001" iyz="0" izz="0.001"/>
      </inertial>
      <visual name="visual_box_0_joint_0.001">
        <origin xyz="0 0 0" rpy="0 0 0"/>
        <geometry>
          <box size="3.0 1.0 1.0"/>
        </geometry>
        <material name="green_semitransparent"/>
      </visual>
    </link>

    <link name="link_0_fixed_joint_1_handle_shaft">
      <inertial>
        <origin xyz="0 0 0" rpy="0 0 0"/>
        <mass value="0.001"/>
        <inertia ixx="0.001" ixy="0" ixz="0" iyy="0.001" iyz="0" izz="0.001"/>
      </inertial>
      <visual name="visual_cylinder_0_fixed_joint_1_handle_shaft">
        <origin xyz="0 0 0" rpy="0 0 0"/>
        <geometry>
          <cylinder radius="0.1" length="1.0"/>
        </geometry>
        <material name="green"/>
      </visual>
      <collision name="collision_cylinder_0_fixed_joint_1_handle_shaft">
        <origin xyz="0 0 0" rpy="0 0 0"/>
        <geometry>
          <cylinder radius="0.1" length="1.0"/>
        </geometry>
      </collision>
    </link>

    <link name="link_0_fixed_joint_1_handle_shaft.001">
      <inertial>
        <origin xyz="0 0 0" rpy="0 0 0"/>
        <mass value="0.001"/>
        <inertia ixx="0.001" ixy="0" ixz="0" iyy="0.001" iyz="0" izz="0.001"/>
      </inertial>
      <visual name="visual_cylinder_0_fixed_joint_1_handle_shaft.001">
        <origin xyz="0 0 0" rpy="0 0 0"/>
        <geometry>
          <cylinder radius="0.1" length="1.0"/>
        </geometry>
        <material name="green_semitransparent"/>
      </visual>
    </link>

    <link name="link_0_fixed_joint_2_handle_knob">
      <inertial>
        <origin xyz="0 0 0" rpy="0 0 0"/>
        <mass value="0.001"/>
        <inertia ixx="0.001" ixy="0" ixz="0" iyy="0.001" iyz="0" izz="0.001"/>
      </inertial>
      <visual name="visual_box_0_fixed_joint_2_handle_knob">
        <origin xyz="0 0 0" rpy="0 0 0"/>
        <geometry>
          <box size="0.05 0.05 0.2"/>
        </geometry>
        <material name="yellow"/>
      </visual>
      <collision name="collision_box_0_fixed_joint_2_handle_knob">
        <origin xyz="0 0 0" rpy="0 0 0"/>
        <geometry>
          <box size="0.05 0.05 0.2"/>
        </geometry>
      </collision>
    </link>

    <link name="link_0_fixed_joint_2_handle_knob.001">
      <inertial>
        <origin xyz="0 0 0" rpy="0 0 0"/>
        <mass value="0.001"/>
        <inertia ixx="0.001" ixy="0" ixz="0" iyy="0.001" iyz="0" izz="0.001"/>
      </inertial>
      <visual name="visual_box_0_fixed_joint_2_handle_knob.001">
        <origin xyz="0 0 0" rpy="0 0 0"/>
        <geometry>
          <box size="0.05 0.05 0.2"/>
        </geometry>
        <material name="green_semitransparent"/>
      </visual>
    </link>

    <link name="link_0_fixed_joint_3_hinge">
      <inertial>
        <origin xyz="0 0 0" rpy="0 0 0"/>
        <mass value="0.001"/>
        <inertia ixx="0.001" ixy="0" ixz="0" iyy="0.001" iyz="0" izz="0.001"/>
      </inertial>
      <visual name="visual_cylinder_0_fixed_joint_3_hinge">
        <origin xyz="0 0 0" rpy="0 0 0"/>
        <geometry>
          <cylinder radius="0.05" length="1.1"/>
        </geometry>
        <material name="gray"/>
      </visual>
    </link>

    <link name="link_0_fixed_joint_3_hinge.001">
      <inertial>
        <origin xyz="0 0 0" rpy="0 0 0"/>
        <mass value="0.001"/>
        <inertia ixx="0.001" ixy="0" ixz="0" iyy="0.001" iyz="0" izz="0.001"/>
      </inertial>
      <visual name="visual_cylinder_0_fixed_joint_3_hinge.001">
        <origin xyz="0 0 0" rpy="0 0 0"/>
        <geometry>
          <cylinder radius="0.05" length="1.1"/>
        </geometry>
        <material name="green_semitransparent"/>
      </visual>
    </link>

    <link name="link_0_joint_0">
      <inertial>
        <origin xyz="0 0 0" rpy="0 0 0"/>
        <mass value="0.001"/>
        <inertia ixx="0.001" ixy="0" ixz="0" iyy="0.001" iyz="0" izz="0.001"/>
      </inertial>
      <visual name="visual_box_0_joint_0">
        <origin xyz="0 0 0" rpy="0 0 0"/>
        <geometry>
          <box size="3.0 1.0 1.0"/>
        </geometry>
        <material name="green"/>
      </visual>
      <collision name="collision_box_0_joint_0">
        <origin xyz="0 0 0" rpy="0 0 0"/>
        <geometry>
          <box size="3.0 1.0 1.0"/>
        </geometry>
      </collision>
    </link>

    <link name="link_1_fixed_joint_1_handle_shaft">
      <inertial>
        <origin xyz="0 0 0" rpy="0 0 0"/>
        <mass value="0.001"/>
        <inertia ixx="0.001" ixy="0" ixz="0" iyy="0.001" iyz="0" izz="0.001"/>
      </inertial>
      <visual name="visual_cylinder_1_fixed_joint_1_handle_shaft">
        <origin xyz="0 0 0" rpy="0 0 0"/>
        <geometry>
          <cylinder radius="0.1" length="1.0"/>
        </geometry>
        <material name="red"/>
      </visual>
      <collision name="collision_cylinder_1_fixed_joint_1_handle_shaft">
        <origin xyz="0 0 0" rpy="0 0 0"/>
        <geometry>
          <cylinder radius="0.1" length="1.0"/>
        </geometry>
      </collision>
    </link>

    <link name="link_1_fixed_joint_2_handle_knob">
      <inertial>
        <origin xyz="0 0 0" rpy="0 0 0"/>
        <mass value="0.001"/>
        <inertia ixx="0.001" ixy="0" ixz="0" iyy="0.001" iyz="0" izz="0.001"/>
      </inertial>
      <visual name="visual_box_1_fixed_joint_2_handle_knob">
        <origin xyz="0 0 0" rpy="0 0 0"/>
        <geometry>
          <box size="0.05 0.05 0.2"/>
        </geometry>
        <material name="yellow"/>
      </visual>
      <collision name="collision_box_1_fixed_joint_2_handle_knob">
        <origin xyz="0 0 0" rpy="0 0 0"/>
        <geometry>
          <box size="0.05 0.05 0.2"/>
        </geometry>
      </collision>
    </link>

    <link name="link_1_fixed_joint_3_hinge">
      <inertial>
        <origin xyz="0 0 0" rpy="0 0 0"/>
        <mass value="0.001"/>
        <inertia ixx="0.001" ixy="0" ixz="0" iyy="0.001" iyz="0" izz="0.001"/>
      </inertial>
      <visual name="visual_cylinder_1_fixed_joint_3_hinge">
        <origin xyz="0 0 0" rpy="0 0 0"/>
        <geometry>
          <cylinder radius="0.05" length="1.1"/>
        </geometry>
        <material name="gray"/>
      </visual>
    </link>

    <link name="link_1_joint_0">
      <inertial>
        <origin xyz="0 0 0" rpy="0 0 0"/>
        <mass value="0.001"/>
        <inertia ixx="0.001" ixy="0" ixz="0" iyy="0.001" iyz="0" izz="0.001"/>
      </inertial>
      <visual name="visual_box_1_joint_0">
        <origin xyz="0 0 0" rpy="0 0 0"/>
        <geometry>
          <box size="3.0 1.0 1.0"/>
        </geometry>
        <material name="red"/>
      </visual>
      <collision name="collision_box_1_joint_0">
        <origin xyz="0 0 0" rpy="0 0 0"/>
        <geometry>
          <box size="3.0 1.0 1.0"/>
        </geometry>
      </collision>
    </link>

    <link name="link_2_fixed_joint_1_handle_shaft">
      <inertial>
        <origin xyz="0 0 0" rpy="0 0 0"/>
        <mass value="0.001"/>
        <inertia ixx="0.001" ixy="0" ixz="0" iyy="0.001" iyz="0" izz="0.001"/>
      </inertial>
      <visual name="visual_box_2_fixed_joint_1_handle_shaft">
        <origin xyz="0 0 0" rpy="0 0 0"/>
        <geometry>
          <box size="0.2 0.2 1.0"/>
        </geometry>
        <material name="red"/>
      </visual>
      <collision name="collision_box_2_fixed_joint_1_handle_shaft">
        <origin xyz="0 0 0" rpy="0 0 0"/>
        <geometry>
          <box size="0.2 0.2 1.0"/>
        </geometry>
      </collision>
    </link>

    <link name="link_2_fixed_joint_2_handle_knob">
      <inertial>
        <origin xyz="0 0 0" rpy="0 0 0"/>
        <mass value="0.001"/>
        <inertia ixx="0.001" ixy="0" ixz="0" iyy="0.001" iyz="0" izz="0.001"/>
      </inertial>
      <visual name="visual_box_2_fixed_joint_2_handle_knob">
        <origin xyz="0 0 0" rpy="0 0 0"/>
        <geometry>
          <box size="0.05 0.05 0.2"/>
        </geometry>
        <material name="yellow"/>
      </visual>
      <collision name="collision_box_2_fixed_joint_2_handle_knob">
        <origin xyz="0 0 0" rpy="0 0 0"/>
        <geometry>
          <box size="0.05 0.05 0.2"/>
        </geometry>
      </collision>
    </link>

    <link name="link_2_joint_0">
      <inertial>
        <origin xyz="0 0 0" rpy="0 0 0"/>
        <mass value="0.001"/>
        <inertia ixx="0.001" ixy="0" ixz="0" iyy="0.001" iyz="0" izz="0.001"/>
      </inertial>
      <visual name="visual_box_2_joint_0">
        <origin xyz="0 0 0" rpy="0 0 0"/>
        <geometry>
          <box size="1.0 1.0 2.0"/>
        </geometry>
        <material name="red"/>
      </visual>
      <collision name="collision_box_2_joint_0">
        <origin xyz="0 0 0" rpy="0 0 0"/>
        <geometry>
          <box size="1.0 1.0 2.0"/>
        </geometry>
      </collision>
    </link>

    <link name="link_3_fixed_joint_1_handle_shaft">
      <inertial>
        <origin xyz="0 0 0" rpy="0 0 0"/>
        <mass value="0.001"/>
        <inertia ixx="0.001" ixy="0" ixz="0" iyy="0.001" iyz="0" izz="0.001"/>
      </inertial>
      <visual name="visual_box_3_fixed_joint_1_handle_shaft">
        <origin xyz="0 0 0" rpy="0 0 0"/>
        <geometry>
          <box size="0.2 0.2 1.0"/>
        </geometry>
        <material name="red"/>
      </visual>
      <collision name="collision_box_3_fixed_joint_1_handle_shaft">
        <origin xyz="0 0 0" rpy="0 0 0"/>
        <geometry>
          <box size="0.2 0.2 1.0"/>
        </geometry>
      </collision>
    </link>

    <link name="link_3_fixed_joint_2_handle_knob">
      <inertial>
        <origin xyz="0 0 0" rpy="0 0 0"/>
        <mass value="0.001"/>
        <inertia ixx="0.001" ixy="0" ixz="0" iyy="0.001" iyz="0" izz="0.001"/>
      </inertial>
      <visual name="visual_box_3_fixed_joint_2_handle_knob">
        <origin xyz="0 0 0" rpy="0 0 0"/>
        <geometry>
          <box size="0.05 0.05 0.2"/>
        </geometry>
        <material name="yellow"/>
      </visual>
      <collision name="collision_box_3_fixed_joint_2_handle_knob">
        <origin xyz="0 0 0" rpy="0 0 0"/>
        <geometry>
          <box size="0.05 0.05 0.2"/>
        </geometry>
      </collision>
    </link>

    <link name="link_3_joint_0">
      <inertial>
        <origin xyz="0 0 0" rpy="0 0 0"/>
        <mass value="0.001"/>
        <inertia ixx="0.001" ixy="0" ixz="0" iyy="0.001" iyz="0" izz="0.001"/>
      </inertial>
      <visual name="visual_box_3_joint_0">
        <origin xyz="0 0 0" rpy="0 0 0"/>
        <geometry>
          <box size="1.0 1.0 2.0"/>
        </geometry>
        <material name="red"/>
      </visual>
      <collision name="collision_box_3_joint_0">
        <origin xyz="0 0 0" rpy="0 0 0"/>
        <geometry>
          <box size="1.0 1.0 2.0"/>
        </geometry>
      </collision>
    </link>

    <joint name="goal" type="fixed">
      <origin xyz="0 0 0.6" rpy="0 0 -2.79785"/>
      <parent link="base_link"/>
      <child link="goal"/>
      <limit effort="0" velocity="0"/>
    </joint>

    <joint name="link_0_fixed_joint_1_handle_shaft" type="fixed">
      <origin xyz="1.125 0 1.0" rpy="0 0 0"/>
      <parent link="link_0_joint_0"/>
      <child link="link_0_fixed_joint_1_handle_shaft"/>
    </joint>

    <joint name="link_0_fixed_joint_1_handle_shaft.001" type="fixed">
      <origin xyz="1.125 0 1.0" rpy="0 0 0"/>
      <parent link="goal"/>
      <child link="link_0_fixed_joint_1_handle_shaft.001"/>
    </joint>

    <joint name="link_0_fixed_joint_2_handle_knob" type="fixed">
      <origin xyz="0 0 0.6" rpy="0 0 0"/>
      <parent link="link_0_fixed_joint_1_handle_shaft"/>
      <child link="link_0_fixed_joint_2_handle_knob"/>
    </joint>

    <joint name="link_0_fixed_joint_2_handle_knob.001" type="fixed">
      <origin xyz="0 0 0.6" rpy="0 0 0"/>
      <parent link="link_0_fixed_joint_1_handle_shaft.001"/>
      <child link="link_0_fixed_joint_2_handle_knob.001"/>
    </joint>

    <joint name="link_0_fixed_joint_3_hinge" type="fixed">
      <origin xyz="0 0 0" rpy="0 0 0"/>
      <parent link="link_0_joint_0"/>
      <child link="link_0_fixed_joint_3_hinge"/>
    </joint>

    <joint name="link_0_fixed_joint_3_hinge.001" type="fixed">
      <origin xyz="0 0 0" rpy="0 0 0"/>
      <parent link="goal"/>
      <child link="link_0_fixed_joint_3_hinge.001"/>
    </joint>

    <joint name="link_0_joint_0" type="revolute">
      <origin xyz="0 0 0.6" rpy="0 0 -0.97753"/>
      <parent link="base_link"/>
      <child link="link_0_joint_0"/>
      <axis xyz="0 0 1.0"/>
      <limit lower="-1.82033" upper="0" effort="0" velocity="0"/>
    </joint>

    <joint name="link_1_fixed_joint_1_handle_shaft" type="fixed">
      <origin xyz="1.125 0 1.0" rpy="0 0 0"/>
      <parent link="link_1_joint_0"/>
      <child link="link_1_fixed_joint_1_handle_shaft"/>
    </joint>

    <joint name="link_1_fixed_joint_2_handle_knob" type="fixed">
      <origin xyz="0 0 0.6" rpy="0 0 0"/>
      <parent link="link_1_fixed_joint_1_handle_shaft"/>
      <child link="link_1_fixed_joint_2_handle_knob"/>
    </joint>

    <joint name="link_1_fixed_joint_3_hinge" type="fixed">
      <origin xyz="0 0 0" rpy="0 0 0"/>
      <parent link="link_1_joint_0"/>
      <child link="link_1_fixed_joint_3_hinge"/>
    </joint>

    <joint name="link_1_joint_0" type="revolute">
      <origin xyz="1.89729 1.60702 0.6" rpy="0 0 -2.61769"/>
      <parent link="base_link"/>
      <child link="link_1_joint_0"/>
      <axis xyz="0 0 1.0"/>
      <limit lower="0" upper="1.58552" effort="0" velocity="0"/>
    </joint>

    <joint name="link_2_fixed_joint_1_handle_shaft" type="fixed">
      <origin xyz="0 -1.0 0" rpy="1.5708 0 0"/>
      <parent link="link_2_joint_0"/>
      <child link="link_2_fixed_joint_1_handle_shaft"/>
    </joint>

    <joint name="link_2_fixed_joint_2_handle_knob" type="fixed">
      <origin xyz="0 0 0.6" rpy="0 0 0"/>
      <parent link="link_2_fixed_joint_1_handle_shaft"/>
      <child link="link_2_fixed_joint_2_handle_knob"/>
    </joint>

    <joint name="link_2_joint_0" type="prismatic">
      <origin xyz="2.7436 -0.22319 0.6" rpy="-1.5708 0 -2.39786"/>
      <parent link="base_link"/>
      <child link="link_2_joint_0"/>
      <axis xyz="0 0 1.0"/>
      <limit lower="0" upper="3.81949" effort="0" velocity="0"/>
    </joint>

    <joint name="link_3_fixed_joint_1_handle_shaft" type="fixed">
      <origin xyz="0 -1.0 0" rpy="1.5708 0 0"/>
      <parent link="link_3_joint_0"/>
      <child link="link_3_fixed_joint_1_handle_shaft"/>
    </joint>

    <joint name="link_3_fixed_joint_2_handle_knob" type="fixed">
      <origin xyz="0 0 0.6" rpy="0 0 0"/>
      <parent link="link_3_fixed_joint_1_handle_shaft"/>
      <child link="link_3_fixed_joint_2_handle_knob"/>
    </joint>

    <joint name="link_3_joint_0" type="prismatic">
      <origin xyz="3.51572 -2.56209 0.6" rpy="-1.5708 0 -2.44487"/>
      <parent link="base_link"/>
      <child link="link_3_joint_0"/>
      <axis xyz="0 0 1.0"/>
      <limit lower="0" upper="3.93321" effort="0" velocity="0"/>
    </joint>

    <material name="gray">
      <color rgba="0.5 0.5 0.5 1.0"/>
    </material>

    <material name="green">
      <color rgba="0 1.0 0 1.0"/>
    </material>

    <material name="green_semitransparent">
      <color rgba="0 1.0 0 0.25"/>
    </material>

    <material name="lavender">
      <color rgba="0.8 0.8 1.0 1.0"/>
    </material>

    <material name="red">
      <color rgba="1.0 0 0 1.0"/>
    </material>

    <material name="yellow">
      <color rgba="1.0 1.0 0 1.0"/>
    </material>

  </robot>
