<?xml version="1.0"?>
<!-- created with Phobos 1.0.1 "Capricious Choutengan" -->
  <robot name="continuous_space">

    <link name="base_link">
      <inertial>
        <origin xyz="0 0 0" rpy="0 0 0"/>
        <mass value="0.001"/>
        <inertia ixx="0.001" ixy="0" ixz="0" iyy="0.001" iyz="0" izz="0.001"/>
      </inertial>
      <visual name="visual_cube_base">
        <origin xyz="0 0 0" rpy="0 0 0"/>
        <geometry>
          <box size="32.0 32.0 0.2"/>
        </geometry>
        <material name="lavender"/>
      </visual>
      <collision name="collision_cube_base">
        <origin xyz="0 0 0" rpy="0 0 0"/>
        <geometry>
          <box size="32.0 32.0 0.2"/>
        </geometry>
      </collision>
    </link>

    <link name="link_0">
      <inertial>
        <origin xyz="0 0 0" rpy="0 0 0"/>
        <mass value="0.001"/>
        <inertia ixx="0.001" ixy="0" ixz="0" iyy="0.001" iyz="0" izz="0.001"/>
      </inertial>
      <visual name="visual_cube_0">
        <origin xyz="0 0 0" rpy="0 0 0"/>
        <geometry>
          <box size="3.0 1.0 1.0"/>
        </geometry>
        <material name="green"/>
      </visual>
      <collision name="collision_cube_0">
        <origin xyz="0 0 0" rpy="0 0 0"/>
        <geometry>
          <box size="3.0 1.0 1.0"/>
        </geometry>
      </collision>
    </link>

    <link name="link_1">
      <inertial>
        <origin xyz="0 0 0" rpy="0 0 0"/>
        <mass value="0.001"/>
        <inertia ixx="0.001" ixy="0" ixz="0" iyy="0.001" iyz="0" izz="0.001"/>
      </inertial>
      <visual name="visual_cube_1">
        <origin xyz="0 0 0" rpy="0 0 0"/>
        <geometry>
          <box size="3.0 1.0 1.0"/>
        </geometry>
        <material name="red"/>
      </visual>
      <collision name="collision_cube_1">
        <origin xyz="0 0 0" rpy="0 0 0"/>
        <geometry>
          <box size="3.0 1.0 1.0"/>
        </geometry>
      </collision>
    </link>

    <link name="link_2">
      <inertial>
        <origin xyz="0 0 0" rpy="0 0 0"/>
        <mass value="0.001"/>
        <inertia ixx="0.001" ixy="0" ixz="0" iyy="0.001" iyz="0" izz="0.001"/>
      </inertial>
      <visual name="visual_cube_2">
        <origin xyz="0 0 0" rpy="0 0 0"/>
        <geometry>
          <box size="1.0 1.0 2.0"/>
        </geometry>
        <material name="red"/>
      </visual>
      <collision name="collision_cube_2">
        <origin xyz="0 0 0" rpy="0 0 0"/>
        <geometry>
          <box size="1.0 1.0 2.0"/>
        </geometry>
      </collision>
    </link>

    <link name="link_3">
      <inertial>
        <origin xyz="0 0 0" rpy="0 0 0"/>
        <mass value="0.001"/>
        <inertia ixx="0.001" ixy="0" ixz="0" iyy="0.001" iyz="0" izz="0.001"/>
      </inertial>
      <visual name="visual_cube_3">
        <origin xyz="0 0 0" rpy="0 0 0"/>
        <geometry>
          <box size="1.0 1.0 2.0"/>
        </geometry>
        <material name="red"/>
      </visual>
      <collision name="collision_cube_3">
        <origin xyz="0 0 0" rpy="0 0 0"/>
        <geometry>
          <box size="1.0 1.0 2.0"/>
        </geometry>
      </collision>
    </link>

    <link name="link_handle_knob_0">
      <inertial>
        <origin xyz="0 0 0" rpy="0 0 0"/>
        <mass value="0.001"/>
        <inertia ixx="0.001" ixy="0" ixz="0" iyy="0.001" iyz="0" izz="0.001"/>
      </inertial>
      <visual name="visual_cube_handle_knob_0">
        <origin xyz="0 0 0" rpy="0 0 0"/>
        <geometry>
          <box size="0.05 0.05 0.2"/>
        </geometry>
        <material name="yellow"/>
      </visual>
      <collision name="collision_cube_handle_knob_0">
        <origin xyz="0 0 0" rpy="0 0 0"/>
        <geometry>
          <box size="0.05 0.05 0.2"/>
        </geometry>
      </collision>
    </link>

    <link name="link_handle_knob_1">
      <inertial>
        <origin xyz="0 0 0" rpy="0 0 0"/>
        <mass value="0.001"/>
        <inertia ixx="0.001" ixy="0" ixz="0" iyy="0.001" iyz="0" izz="0.001"/>
      </inertial>
      <visual name="visual_cube_handle_knob_1">
        <origin xyz="0 0 0" rpy="0 0 0"/>
        <geometry>
          <box size="0.05 0.05 0.2"/>
        </geometry>
        <material name="yellow"/>
      </visual>
      <collision name="collision_cube_handle_knob_1">
        <origin xyz="0 0 0" rpy="0 0 0"/>
        <geometry>
          <box size="0.05 0.05 0.2"/>
        </geometry>
      </collision>
    </link>

    <link name="link_handle_knob_2">
      <inertial>
        <origin xyz="0 0 0" rpy="0 0 0"/>
        <mass value="0.001"/>
        <inertia ixx="0.001" ixy="0" ixz="0" iyy="0.001" iyz="0" izz="0.001"/>
      </inertial>
      <visual name="visual_cube_handle_knob_2">
        <origin xyz="0 0 0" rpy="0 0 0"/>
        <geometry>
          <box size="0.05 0.05 0.2"/>
        </geometry>
        <material name="yellow"/>
      </visual>
      <collision name="collision_cube_handle_knob_2">
        <origin xyz="0 0 0" rpy="0 0 0"/>
        <geometry>
          <box size="0.05 0.05 0.2"/>
        </geometry>
      </collision>
    </link>

    <link name="link_handle_knob_3">
      <inertial>
        <origin xyz="0 0 0" rpy="0 0 0"/>
        <mass value="0.001"/>
        <inertia ixx="0.001" ixy="0" ixz="0" iyy="0.001" iyz="0" izz="0.001"/>
      </inertial>
      <visual name="visual_cube_handle_knob_3">
        <origin xyz="0 0 0" rpy="0 0 0"/>
        <geometry>
          <box size="0.05 0.05 0.2"/>
        </geometry>
        <material name="yellow"/>
      </visual>
      <collision name="collision_cube_handle_knob_3">
        <origin xyz="0 0 0" rpy="0 0 0"/>
        <geometry>
          <box size="0.05 0.05 0.2"/>
        </geometry>
      </collision>
    </link>

    <link name="link_handle_shaft_0">
      <inertial>
        <origin xyz="0 0 0" rpy="0 0 0"/>
        <mass value="0.001"/>
        <inertia ixx="0.001" ixy="0" ixz="0" iyy="0.001" iyz="0" izz="0.001"/>
      </inertial>
      <visual name="visual_cylinder_handle_shaft_0">
        <origin xyz="0 0 0" rpy="0 0 0"/>
        <geometry>
          <cylinder radius="0.1" length="1.0"/>
        </geometry>
        <material name="green"/>
      </visual>
      <collision name="collision_cylinder_handle_shaft_0">
        <origin xyz="0 0 0" rpy="0 0 0"/>
        <geometry>
          <cylinder radius="0.1" length="1.0"/>
        </geometry>
      </collision>
    </link>

    <link name="link_handle_shaft_1">
      <inertial>
        <origin xyz="0 0 0" rpy="0 0 0"/>
        <mass value="0.001"/>
        <inertia ixx="0.001" ixy="0" ixz="0" iyy="0.001" iyz="0" izz="0.001"/>
      </inertial>
      <visual name="visual_cylinder_handle_shaft_1">
        <origin xyz="0 0 0" rpy="0 0 0"/>
        <geometry>
          <cylinder radius="0.1" length="1.0"/>
        </geometry>
        <material name="red"/>
      </visual>
      <collision name="collision_cylinder_handle_shaft_1">
        <origin xyz="0 0 0" rpy="0 0 0"/>
        <geometry>
          <cylinder radius="0.1" length="1.0"/>
        </geometry>
      </collision>
    </link>

    <link name="link_handle_shaft_2">
      <inertial>
        <origin xyz="0 0 0" rpy="0 0 0"/>
        <mass value="0.001"/>
        <inertia ixx="0.001" ixy="0" ixz="0" iyy="0.001" iyz="0" izz="0.001"/>
      </inertial>
      <visual name="visual_cube_handle_shaft_2">
        <origin xyz="0 0 0" rpy="0 0 0"/>
        <geometry>
          <box size="0.2 0.2 1.0"/>
        </geometry>
        <material name="red"/>
      </visual>
      <collision name="collision_cube_handle_shaft_2">
        <origin xyz="0 0 0" rpy="0 0 0"/>
        <geometry>
          <box size="0.2 0.2 1.0"/>
        </geometry>
      </collision>
    </link>

    <link name="link_handle_shaft_3">
      <inertial>
        <origin xyz="0 0 0" rpy="0 0 0"/>
        <mass value="0.001"/>
        <inertia ixx="0.001" ixy="0" ixz="0" iyy="0.001" iyz="0" izz="0.001"/>
      </inertial>
      <visual name="visual_cube_handle_shaft_3">
        <origin xyz="0 0 0" rpy="0 0 0"/>
        <geometry>
          <box size="0.2 0.2 1.0"/>
        </geometry>
        <material name="red"/>
      </visual>
      <collision name="collision_cube_handle_shaft_3">
        <origin xyz="0 0 0" rpy="0 0 0"/>
        <geometry>
          <box size="0.2 0.2 1.0"/>
        </geometry>
      </collision>
    </link>

    <link name="link_hinge_0">
      <inertial>
        <origin xyz="0 0 0" rpy="0 0 0"/>
        <mass value="0.001"/>
        <inertia ixx="0.001" ixy="0" ixz="0" iyy="0.001" iyz="0" izz="0.001"/>
      </inertial>
      <visual name="visual_cylinder_hinge_0">
        <origin xyz="0 0 0" rpy="0 0 0"/>
        <geometry>
          <cylinder radius="0.05" length="1.1"/>
        </geometry>
        <material name="gray"/>
      </visual>
      <collision name="collision_cylinder_hinge_0">
        <origin xyz="0 0 0" rpy="0 0 0"/>
        <geometry>
          <cylinder radius="0.05" length="1.1"/>
        </geometry>
      </collision>
    </link>

    <link name="link_hinge_1">
      <inertial>
        <origin xyz="0 0 0" rpy="0 0 0"/>
        <mass value="0.001"/>
        <inertia ixx="0.001" ixy="0" ixz="0" iyy="0.001" iyz="0" izz="0.001"/>
      </inertial>
      <visual name="visual_cylinder_hinge_1">
        <origin xyz="0 0 0" rpy="0 0 0"/>
        <geometry>
          <cylinder radius="0.05" length="1.1"/>
        </geometry>
        <material name="gray"/>
      </visual>
      <collision name="collision_cylinder_hinge_1">
        <origin xyz="0 0 0" rpy="0 0 0"/>
        <geometry>
          <cylinder radius="0.05" length="1.1"/>
        </geometry>
      </collision>
    </link>

    <joint name="link_0" type="revolute">
      <origin xyz="0 0 0.6" rpy="0 0 -0.97753"/>
      <parent link="base_link"/>
      <child link="link_0"/>
      <axis xyz="0 0 1.0"/>
      <limit lower="-1.82033" upper="0" effort="0" velocity="0"/>
    </joint>

    <joint name="link_1" type="revolute">
      <origin xyz="1.89729 1.60702 0.6" rpy="0 0 -2.61769"/>
      <parent link="base_link"/>
      <child link="link_1"/>
      <axis xyz="0 0 1.0"/>
      <limit lower="0" upper="1.58552" effort="0" velocity="0"/>
    </joint>

    <joint name="link_2" type="prismatic">
      <origin xyz="2.7436 -0.22319 0.6" rpy="-1.5708 0 -2.39786"/>
      <parent link="base_link"/>
      <child link="link_2"/>
      <axis xyz="0 0 1.0"/>
      <limit lower="0" upper="3.81949" effort="0" velocity="0"/>
    </joint>

    <joint name="link_3" type="prismatic">
      <origin xyz="5.40311 -1.16809 0.6" rpy="-1.5708 0 -1.98559"/>
      <parent link="base_link"/>
      <child link="link_3"/>
      <axis xyz="0 0 1.0"/>
      <limit lower="0" upper="2.2014" effort="0" velocity="0"/>
    </joint>

    <joint name="link_handle_knob_0" type="fixed">
      <origin xyz="0 0 0.6" rpy="0 0 0"/>
      <parent link="link_handle_shaft_0"/>
      <child link="link_handle_knob_0"/>
    </joint>

    <joint name="link_handle_knob_1" type="fixed">
      <origin xyz="0 0 0.6" rpy="0 0 0"/>
      <parent link="link_handle_shaft_1"/>
      <child link="link_handle_knob_1"/>
    </joint>

    <joint name="link_handle_knob_2" type="fixed">
      <origin xyz="0 0 0.6" rpy="0 0 0"/>
      <parent link="link_handle_shaft_2"/>
      <child link="link_handle_knob_2"/>
    </joint>

    <joint name="link_handle_knob_3" type="fixed">
      <origin xyz="0 0 0.6" rpy="0 0 0"/>
      <parent link="link_handle_shaft_3"/>
      <child link="link_handle_knob_3"/>
    </joint>

    <joint name="link_handle_shaft_0" type="fixed">
      <origin xyz="1.125 0 1.0" rpy="0 0 0"/>
      <parent link="link_0"/>
      <child link="link_handle_shaft_0"/>
    </joint>

    <joint name="link_handle_shaft_1" type="fixed">
      <origin xyz="1.125 0 1.0" rpy="0 0 0"/>
      <parent link="link_1"/>
      <child link="link_handle_shaft_1"/>
    </joint>

    <joint name="link_handle_shaft_2" type="fixed">
      <origin xyz="0 -1.0 0" rpy="1.5708 0 0"/>
      <parent link="link_2"/>
      <child link="link_handle_shaft_2"/>
    </joint>

    <joint name="link_handle_shaft_3" type="fixed">
      <origin xyz="0 -1.0 0" rpy="1.5708 0 0"/>
      <parent link="link_3"/>
      <child link="link_handle_shaft_3"/>
    </joint>

    <joint name="link_hinge_0" type="fixed">
      <origin xyz="0 0 0" rpy="0 0 0"/>
      <parent link="link_0"/>
      <child link="link_hinge_0"/>
    </joint>

    <joint name="link_hinge_1" type="fixed">
      <origin xyz="0 0 0" rpy="0 0 0"/>
      <parent link="link_1"/>
      <child link="link_hinge_1"/>
    </joint>

    <material name="gray">
      <color rgba="0.5 0.5 0.5 1.0"/>
    </material>

    <material name="green">
      <color rgba="0 1.0 0 1.0"/>
    </material>

    <material name="lavender">
      <color rgba="0.8 0.8 1.0 1.0"/>
    </material>

    <material name="red">
      <color rgba="1.0 0 0 1.0"/>
    </material>

    <material name="yellow">
      <color rgba="1.0 1.0 0 1.0"/>
    </material>

  </robot>
