<?xml version="1.0"?>
<!-- created with Phobos 1.0.1 "Capricious Choutengan" -->
  <robot name="continuous_space">

    <link name="base_link">
      <inertial>
        <origin xyz="0 0 0" rpy="0 0 0"/>
        <mass value="0.001"/>
        <inertia ixx="0.001" ixy="0" ixz="0" iyy="0.001" iyz="0" izz="0.001"/>
      </inertial>
    </link>

    <link name="goal">
      <inertial>
        <origin xyz="0 0 0" rpy="0 0 0"/>
        <mass value="0.001"/>
        <inertia ixx="0.001" ixy="0" ixz="0" iyy="0.001" iyz="0" izz="0.001"/>
      </inertial>
      <visual name="visual_box_1_link_0.001">
        <origin xyz="0 0 0" rpy="0 0 0"/>
        <geometry>
          <box size="1.98503 0.99002 0.99002"/>
        </geometry>
        <material name="green_translucent"/>
      </visual>
    </link>

    <link name="link_0_joint_0">
      <inertial>
        <origin xyz="0 0 0" rpy="0 0 0"/>
        <mass value="0.001"/>
        <inertia ixx="0.001" ixy="0" ixz="0" iyy="0.001" iyz="0" izz="0.001"/>
      </inertial>
      <visual name="visual_box_1_link_0">
        <origin xyz="0 0 0" rpy="0 0 0"/>
        <geometry>
          <box size="1.995 0.995 0.995"/>
        </geometry>
        <material name="green"/>
      </visual>
      <collision name="collision_box_1_link_0">
        <origin xyz="0 0 0" rpy="0 0 0"/>
        <geometry>
          <box size="1.995 0.995 0.995"/>
        </geometry>
      </collision>
    </link>

    <link name="link_1_joint_0">
      <inertial>
        <origin xyz="0 0 0" rpy="0 0 0"/>
        <mass value="0.001"/>
        <inertia ixx="0.001" ixy="0" ixz="0" iyy="0.001" iyz="0" izz="0.001"/>
      </inertial>
      <visual name="visual_box_13_link_1">
        <origin xyz="0 0 0" rpy="0 0 0"/>
        <geometry>
          <box size="1.995 0.995 0.995"/>
        </geometry>
        <material name="red"/>
      </visual>
      <collision name="collision_box_13_link_1">
        <origin xyz="0 0 0" rpy="0 0 0"/>
        <geometry>
          <box size="1.995 0.995 0.995"/>
        </geometry>
      </collision>
    </link>

    <link name="link_2_joint_0">
      <inertial>
        <origin xyz="0 0 0" rpy="0 0 0"/>
        <mass value="0.001"/>
        <inertia ixx="0.001" ixy="0" ixz="0" iyy="0.001" iyz="0" izz="0.001"/>
      </inertial>
      <visual name="visual_box_61_link_2">
        <origin xyz="0 0 0" rpy="0 0 0"/>
        <geometry>
          <box size="2.995 0.995 0.995"/>
        </geometry>
        <material name="red"/>
      </visual>
      <collision name="collision_box_61_link_2">
        <origin xyz="0 0 0" rpy="0 0 0"/>
        <geometry>
          <box size="2.995 0.995 0.995"/>
        </geometry>
      </collision>
    </link>

    <link name="link_3_joint_0">
      <inertial>
        <origin xyz="0 0 0" rpy="0 0 0"/>
        <mass value="0.001"/>
        <inertia ixx="0.001" ixy="0" ixz="0" iyy="0.001" iyz="0" izz="0.001"/>
      </inertial>
      <visual name="visual_box_123_link_3">
        <origin xyz="0 0 0" rpy="0 0 0"/>
        <geometry>
          <box size="2.995 0.995 0.995"/>
        </geometry>
        <material name="red"/>
      </visual>
      <collision name="collision_box_123_link_3">
        <origin xyz="0 0 0" rpy="0 0 0"/>
        <geometry>
          <box size="2.995 0.995 0.995"/>
        </geometry>
      </collision>
    </link>

    <link name="link_4_joint_0">
      <inertial>
        <origin xyz="0 0 0" rpy="0 0 0"/>
        <mass value="0.001"/>
        <inertia ixx="0.001" ixy="0" ixz="0" iyy="0.001" iyz="0" izz="0.001"/>
      </inertial>
      <visual name="visual_box_151_link_4">
        <origin xyz="0 0 0" rpy="0 0 0"/>
        <geometry>
          <box size="1.995 0.995 0.995"/>
        </geometry>
        <material name="red"/>
      </visual>
      <collision name="collision_box_151_link_4">
        <origin xyz="0 0 0" rpy="0 0 0"/>
        <geometry>
          <box size="1.995 0.995 0.995"/>
        </geometry>
      </collision>
    </link>

    <link name="link_fixed_0_floor">
      <inertial>
        <origin xyz="0 0 0" rpy="0 0 0"/>
        <mass value="0.001"/>
        <inertia ixx="0.001" ixy="0" ixz="0" iyy="0.001" iyz="0" izz="0.001"/>
      </inertial>
      <visual name="visual_box_fixed_0_floor">
        <origin xyz="0 0 0" rpy="0 0 0"/>
        <geometry>
          <box size="31.995 31.995 0.195"/>
        </geometry>
        <material name="lavender"/>
      </visual>
      <collision name="collision_box_fixed_0_floor">
        <origin xyz="0 0 0" rpy="0 0 0"/>
        <geometry>
          <box size="31.995 31.995 0.195"/>
        </geometry>
      </collision>
    </link>

    <link name="link_fixed_124_hinge">
      <inertial>
        <origin xyz="0 0 0" rpy="0 0 0"/>
        <mass value="0.001"/>
        <inertia ixx="0.001" ixy="0" ixz="0" iyy="0.001" iyz="0" izz="0.001"/>
      </inertial>
      <visual name="visual_cylinder_fixed_124_hinge">
        <origin xyz="0 0 0" rpy="0 0 0"/>
        <geometry>
          <cylinder radius="0.1225" length="1.095"/>
        </geometry>
        <material name="gray"/>
      </visual>
    </link>

    <link name="link_fixed_125_handle_shaft">
      <inertial>
        <origin xyz="0 0 0" rpy="0 0 0"/>
        <mass value="0.001"/>
        <inertia ixx="0.001" ixy="0" ixz="0" iyy="0.001" iyz="0" izz="0.001"/>
      </inertial>
      <visual name="visual_cylinder_fixed_125_handle_shaft">
        <origin xyz="0 0 0" rpy="0 0 0"/>
        <geometry>
          <cylinder radius="0.0975" length="0.995"/>
        </geometry>
        <material name="red"/>
      </visual>
      <collision name="collision_cylinder_fixed_125_handle_shaft">
        <origin xyz="0 0 0" rpy="0 0 0"/>
        <geometry>
          <cylinder radius="0.0975" length="0.995"/>
        </geometry>
      </collision>
    </link>

    <link name="link_fixed_126_handle_knob">
      <inertial>
        <origin xyz="0 0 0" rpy="0 0 0"/>
        <mass value="0.001"/>
        <inertia ixx="0.001" ixy="0" ixz="0" iyy="0.001" iyz="0" izz="0.001"/>
      </inertial>
      <visual name="visual_box_fixed_126_handle_knob">
        <origin xyz="0 0 0" rpy="0 0 0"/>
        <geometry>
          <box size="0.045 0.045 0.195"/>
        </geometry>
        <material name="yellow"/>
      </visual>
      <collision name="collision_box_fixed_126_handle_knob">
        <origin xyz="0 0 0" rpy="0 0 0"/>
        <geometry>
          <box size="0.045 0.045 0.195"/>
        </geometry>
      </collision>
    </link>

    <link name="link_fixed_14_handle_shaft">
      <inertial>
        <origin xyz="0 0 0" rpy="0 0 0"/>
        <mass value="0.001"/>
        <inertia ixx="0.001" ixy="0" ixz="0" iyy="0.001" iyz="0" izz="0.001"/>
      </inertial>
      <visual name="visual_box_fixed_14_handle_shaft">
        <origin xyz="0 0 0" rpy="0 0 0"/>
        <geometry>
          <box size="0.195 0.195 0.995"/>
        </geometry>
        <material name="red"/>
      </visual>
      <collision name="collision_box_fixed_14_handle_shaft">
        <origin xyz="0 0 0" rpy="0 0 0"/>
        <geometry>
          <box size="0.195 0.195 0.995"/>
        </geometry>
      </collision>
    </link>

    <link name="link_fixed_152_handle_shaft">
      <inertial>
        <origin xyz="0 0 0" rpy="0 0 0"/>
        <mass value="0.001"/>
        <inertia ixx="0.001" ixy="0" ixz="0" iyy="0.001" iyz="0" izz="0.001"/>
      </inertial>
      <visual name="visual_box_fixed_152_handle_shaft">
        <origin xyz="0 0 0" rpy="0 0 0"/>
        <geometry>
          <box size="0.195 0.195 0.995"/>
        </geometry>
        <material name="red"/>
      </visual>
      <collision name="collision_box_fixed_152_handle_shaft">
        <origin xyz="0 0 0" rpy="0 0 0"/>
        <geometry>
          <box size="0.195 0.195 0.995"/>
        </geometry>
      </collision>
    </link>

    <link name="link_fixed_153_handle_knob">
      <inertial>
        <origin xyz="0 0 0" rpy="0 0 0"/>
        <mass value="0.001"/>
        <inertia ixx="0.001" ixy="0" ixz="0" iyy="0.001" iyz="0" izz="0.001"/>
      </inertial>
      <visual name="visual_box_fixed_153_handle_knob">
        <origin xyz="0 0 0" rpy="0 0 0"/>
        <geometry>
          <box size="0.045 0.045 0.195"/>
        </geometry>
        <material name="yellow"/>
      </visual>
      <collision name="collision_box_fixed_153_handle_knob">
        <origin xyz="0 0 0" rpy="0 0 0"/>
        <geometry>
          <box size="0.045 0.045 0.195"/>
        </geometry>
      </collision>
    </link>

    <link name="link_fixed_15_handle_knob">
      <inertial>
        <origin xyz="0 0 0" rpy="0 0 0"/>
        <mass value="0.001"/>
        <inertia ixx="0.001" ixy="0" ixz="0" iyy="0.001" iyz="0" izz="0.001"/>
      </inertial>
      <visual name="visual_box_fixed_15_handle_knob">
        <origin xyz="0 0 0" rpy="0 0 0"/>
        <geometry>
          <box size="0.045 0.045 0.195"/>
        </geometry>
        <material name="yellow"/>
      </visual>
      <collision name="collision_box_fixed_15_handle_knob">
        <origin xyz="0 0 0" rpy="0 0 0"/>
        <geometry>
          <box size="0.045 0.045 0.195"/>
        </geometry>
      </collision>
    </link>

    <link name="link_fixed_2_handle_shaft">
      <inertial>
        <origin xyz="0 0 0" rpy="0 0 0"/>
        <mass value="0.001"/>
        <inertia ixx="0.001" ixy="0" ixz="0" iyy="0.001" iyz="0" izz="0.001"/>
      </inertial>
      <visual name="visual_box_fixed_2_handle_shaft">
        <origin xyz="0 0 0" rpy="0 0 0"/>
        <geometry>
          <box size="0.195 0.195 0.995"/>
        </geometry>
        <material name="green"/>
      </visual>
      <collision name="collision_box_fixed_2_handle_shaft">
        <origin xyz="0 0 0" rpy="0 0 0"/>
        <geometry>
          <box size="0.195 0.195 0.995"/>
        </geometry>
      </collision>
    </link>

    <link name="link_fixed_2_handle_shaft.001">
      <inertial>
        <origin xyz="0 0 0" rpy="0 0 0"/>
        <mass value="0.001"/>
        <inertia ixx="0.001" ixy="0" ixz="0" iyy="0.001" iyz="0" izz="0.001"/>
      </inertial>
      <visual name="visual_box_fixed_2_handle_shaft.001">
        <origin xyz="0 0 0" rpy="0 0 0"/>
        <geometry>
          <box size="0.19402 0.19402 0.99002"/>
        </geometry>
        <material name="green_translucent"/>
      </visual>
    </link>

    <link name="link_fixed_3_handle_knob">
      <inertial>
        <origin xyz="0 0 0" rpy="0 0 0"/>
        <mass value="0.001"/>
        <inertia ixx="0.001" ixy="0" ixz="0" iyy="0.001" iyz="0" izz="0.001"/>
      </inertial>
      <visual name="visual_box_fixed_3_handle_knob">
        <origin xyz="0 0 0" rpy="0 0 0"/>
        <geometry>
          <box size="0.045 0.045 0.195"/>
        </geometry>
        <material name="yellow"/>
      </visual>
      <collision name="collision_box_fixed_3_handle_knob">
        <origin xyz="0 0 0" rpy="0 0 0"/>
        <geometry>
          <box size="0.045 0.045 0.195"/>
        </geometry>
      </collision>
    </link>

    <link name="link_fixed_3_handle_knob.001">
      <inertial>
        <origin xyz="0 0 0" rpy="0 0 0"/>
        <mass value="0.001"/>
        <inertia ixx="0.001" ixy="0" ixz="0" iyy="0.001" iyz="0" izz="0.001"/>
      </inertial>
      <visual name="visual_box_fixed_3_handle_knob.001">
        <origin xyz="0 0 0" rpy="0 0 0"/>
        <geometry>
          <box size="0.04477 0.04477 0.19402"/>
        </geometry>
        <material name="green_translucent"/>
      </visual>
    </link>

    <link name="link_fixed_62_hinge">
      <inertial>
        <origin xyz="0 0 0" rpy="0 0 0"/>
        <mass value="0.001"/>
        <inertia ixx="0.001" ixy="0" ixz="0" iyy="0.001" iyz="0" izz="0.001"/>
      </inertial>
      <visual name="visual_cylinder_fixed_62_hinge">
        <origin xyz="0 0 0" rpy="0 0 0"/>
        <geometry>
          <cylinder radius="0.1225" length="1.095"/>
        </geometry>
        <material name="gray"/>
      </visual>
    </link>

    <link name="link_fixed_63_handle_shaft">
      <inertial>
        <origin xyz="0 0 0" rpy="0 0 0"/>
        <mass value="0.001"/>
        <inertia ixx="0.001" ixy="0" ixz="0" iyy="0.001" iyz="0" izz="0.001"/>
      </inertial>
      <visual name="visual_cylinder_fixed_63_handle_shaft">
        <origin xyz="0 0 0" rpy="0 0 0"/>
        <geometry>
          <cylinder radius="0.0975" length="0.995"/>
        </geometry>
        <material name="red"/>
      </visual>
      <collision name="collision_cylinder_fixed_63_handle_shaft">
        <origin xyz="0 0 0" rpy="0 0 0"/>
        <geometry>
          <cylinder radius="0.0975" length="0.995"/>
        </geometry>
      </collision>
    </link>

    <link name="link_fixed_64_handle_knob">
      <inertial>
        <origin xyz="0 0 0" rpy="0 0 0"/>
        <mass value="0.001"/>
        <inertia ixx="0.001" ixy="0" ixz="0" iyy="0.001" iyz="0" izz="0.001"/>
      </inertial>
      <visual name="visual_box_fixed_64_handle_knob">
        <origin xyz="0 0 0" rpy="0 0 0"/>
        <geometry>
          <box size="0.045 0.045 0.195"/>
        </geometry>
        <material name="yellow"/>
      </visual>
      <collision name="collision_box_fixed_64_handle_knob">
        <origin xyz="0 0 0" rpy="0 0 0"/>
        <geometry>
          <box size="0.045 0.045 0.195"/>
        </geometry>
      </collision>
    </link>

    <joint name="goal" type="fixed">
      <origin xyz="0.99739 -2.4812 0.5" rpy="0 0 -1.18859"/>
      <parent link="base_link"/>
      <child link="goal"/>
      <limit effort="0" velocity="0"/>
    </joint>

    <joint name="link_0_joint_0" type="prismatic">
      <origin xyz="0 0 0.5" rpy="0 0 -1.18859"/>
      <parent link="base_link"/>
      <child link="link_0_joint_0"/>
      <axis xyz="1.0 0 0"/>
      <limit lower="0" upper="2.67416" effort="0" velocity="0"/>
    </joint>

    <joint name="link_1_joint_0" type="prismatic">
      <origin xyz="-0.03422 -3.00526 0.5" rpy="0 0 -2.29454"/>
      <parent link="base_link"/>
      <child link="link_1_joint_0"/>
      <axis xyz="1.0 0 0"/>
      <limit lower="0" upper="3.11295" effort="0" velocity="0"/>
    </joint>

    <joint name="link_2_joint_0" type="revolute">
      <origin xyz="-1.10798 -5.00962 0.5" rpy="0 0 -1.25698"/>
      <parent link="base_link"/>
      <child link="link_2_joint_0"/>
      <axis xyz="0 0 1.0"/>
      <limit lower="0" upper="2.87617" effort="0" velocity="0"/>
    </joint>

    <joint name="link_3_joint_0" type="revolute">
      <origin xyz="2.8631 -3.5405 0.5" rpy="0 0 -3.02217"/>
      <parent link="base_link"/>
      <child link="link_3_joint_0"/>
      <axis xyz="0 0 1.0"/>
      <limit lower="-2.54743" upper="0" effort="0" velocity="0"/>
    </joint>

    <joint name="link_4_joint_0" type="prismatic">
      <origin xyz="3.4627 -1.85032 0.5" rpy="0 0 1.59111"/>
      <parent link="base_link"/>
      <child link="link_4_joint_0"/>
      <axis xyz="1.0 0 0"/>
      <limit lower="0" upper="3.4642" effort="0" velocity="0"/>
    </joint>

    <joint name="link_fixed_0_floor" type="fixed">
      <origin xyz="0 0 -0.1" rpy="0 0 0"/>
      <parent link="base_link"/>
      <child link="link_fixed_0_floor"/>
    </joint>

    <joint name="link_fixed_124_hinge" type="fixed">
      <origin xyz="0 0 0" rpy="0 0 0"/>
      <parent link="link_3_joint_0"/>
      <child link="link_fixed_124_hinge"/>
    </joint>

    <joint name="link_fixed_125_handle_shaft" type="fixed">
      <origin xyz="1.125 0 1.0" rpy="0 0 0"/>
      <parent link="link_3_joint_0"/>
      <child link="link_fixed_125_handle_shaft"/>
    </joint>

    <joint name="link_fixed_126_handle_knob" type="fixed">
      <origin xyz="0 0 0.6" rpy="0 0 0"/>
      <parent link="link_fixed_125_handle_shaft"/>
      <child link="link_fixed_126_handle_knob"/>
    </joint>

    <joint name="link_fixed_14_handle_shaft" type="fixed">
      <origin xyz="0 0 1.0" rpy="0 0 0"/>
      <parent link="link_1_joint_0"/>
      <child link="link_fixed_14_handle_shaft"/>
    </joint>

    <joint name="link_fixed_152_handle_shaft" type="fixed">
      <origin xyz="0 0 1.0" rpy="0 0 0"/>
      <parent link="link_4_joint_0"/>
      <child link="link_fixed_152_handle_shaft"/>
    </joint>

    <joint name="link_fixed_153_handle_knob" type="fixed">
      <origin xyz="0 0 0.6" rpy="0 0 0"/>
      <parent link="link_fixed_152_handle_shaft"/>
      <child link="link_fixed_153_handle_knob"/>
    </joint>

    <joint name="link_fixed_15_handle_knob" type="fixed">
      <origin xyz="0 0 0.6" rpy="0 0 0"/>
      <parent link="link_fixed_14_handle_shaft"/>
      <child link="link_fixed_15_handle_knob"/>
    </joint>

    <joint name="link_fixed_2_handle_shaft" type="fixed">
      <origin xyz="0 0 1.0" rpy="0 0 0"/>
      <parent link="link_0_joint_0"/>
      <child link="link_fixed_2_handle_shaft"/>
    </joint>

    <joint name="link_fixed_2_handle_shaft.001" type="fixed">
      <origin xyz="0 0 0.995" rpy="0 0 0"/>
      <parent link="goal"/>
      <child link="link_fixed_2_handle_shaft.001"/>
    </joint>

    <joint name="link_fixed_3_handle_knob" type="fixed">
      <origin xyz="0 0 0.6" rpy="0 0 0"/>
      <parent link="link_fixed_2_handle_shaft"/>
      <child link="link_fixed_3_handle_knob"/>
    </joint>

    <joint name="link_fixed_3_handle_knob.001" type="fixed">
      <origin xyz="0 0 0.597" rpy="0 0 0"/>
      <parent link="link_fixed_2_handle_shaft.001"/>
      <child link="link_fixed_3_handle_knob.001"/>
    </joint>

    <joint name="link_fixed_62_hinge" type="fixed">
      <origin xyz="0 0 0" rpy="0 0 0"/>
      <parent link="link_2_joint_0"/>
      <child link="link_fixed_62_hinge"/>
    </joint>

    <joint name="link_fixed_63_handle_shaft" type="fixed">
      <origin xyz="1.125 0 1.0" rpy="0 0 0"/>
      <parent link="link_2_joint_0"/>
      <child link="link_fixed_63_handle_shaft"/>
    </joint>

    <joint name="link_fixed_64_handle_knob" type="fixed">
      <origin xyz="0 0 0.6" rpy="0 0 0"/>
      <parent link="link_fixed_63_handle_shaft"/>
      <child link="link_fixed_64_handle_knob"/>
    </joint>

    <material name="gray">
      <color rgba="0.5 0.5 0.5 1.0"/>
    </material>

    <material name="green">
      <color rgba="0 1.0 0 1.0"/>
    </material>

    <material name="green_translucent">
      <color rgba="0 1.0 0 0.25"/>
    </material>

    <material name="lavender">
      <color rgba="0.8 0.8 1.0 1.0"/>
    </material>

    <material name="red">
      <color rgba="1.0 0 0 1.0"/>
    </material>

    <material name="yellow">
      <color rgba="1.0 1.0 0 1.0"/>
    </material>

  </robot>
