<?xml version="1.0"?>
<!-- created with Phobos 1.0.1 "Capricious Choutengan" -->
  <robot name="unnamed">

    <link name="base_link">
      <inertial>
        <origin xyz="0 0 0" rpy="0 0 0"/>
        <mass value="0.001"/>
        <inertia ixx="0.001" ixy="0" ixz="0" iyy="0.001" iyz="0" izz="0.001"/>
      </inertial>
      <visual name="visual_Cube">
        <origin xyz="0 0 0" rpy="0 0 0"/>
        <geometry>
          <box size="16.0 16.0 1.0"/>
        </geometry>
      </visual>
      <collision name="collision_Cube">
        <origin xyz="0 0 0" rpy="0 0 0"/>
        <geometry>
          <box size="16.0 16.0 1.0"/>
        </geometry>
      </collision>
    </link>

    <link name="link_cog">
      <inertial>
        <origin xyz="0 0 0" rpy="0 0 0"/>
        <mass value="0.001"/>
        <inertia ixx="0.001" ixy="0" ixz="0" iyy="0.001" iyz="0" izz="0.001"/>
      </inertial>
      <visual name="visual_Torus">
        <origin xyz="0 0 0" rpy="0 0 0"/>
        <geometry>
          <mesh filename="file:///home/userone/ba/puzzle-generator/puzzles/continuous_space/meshes/stl/Torus.002.stl" scale="1.0 1.0 1.0"/>
        </geometry>
        <material name="Material.002"/>
      </visual>
      <collision name="collision_Torus">
        <origin xyz="0 0 0" rpy="0 0 0"/>
        <geometry>
          <mesh filename="file:///home/userone/ba/puzzle-generator/puzzles/continuous_space/meshes/stl/Torus.003.stl" scale="1.0 1.0 1.0"/>
        </geometry>
      </collision>
    </link>

    <joint name="link_cog" type="continuous">
      <origin xyz="0 0 0.53454" rpy="0 0 0"/>
      <parent link="base_link"/>
      <child link="link_cog"/>
      <axis xyz="0 0 1.0"/>
      <limit effort="0" velocity="0"/>
    </joint>

    <material name="Material.002">
      <color rgba="0.8 0.8 0.8 1.0"/>
    </material>

  </robot>
