<?xml version="1.0"?>
<!-- created with Phobos 1.0.1 "Capricious Choutengan" -->
  <robot name="escape_room">

    <link name="base_link">
      <inertial>
        <origin xyz="0 0 0" rpy="0 0 0"/>
        <mass value="0.001"/>
        <inertia ixx="0.001" ixy="0" ixz="0" iyy="0.001" iyz="0" izz="0.001"/>
      </inertial>
    </link>

    <link name="goal">
      <inertial>
        <origin xyz="0 0 0" rpy="0 0 0"/>
        <mass value="0.001"/>
        <inertia ixx="0.001" ixy="0" ixz="0" iyy="0.001" iyz="0" izz="0.001"/>
      </inertial>
    </link>

    <link name="link_0_joint_0">
      <inertial>
        <origin xyz="0 0 0" rpy="0 0 0"/>
        <mass value="0.001"/>
        <inertia ixx="0.001" ixy="0" ixz="0" iyy="0.001" iyz="0" izz="0.001"/>
      </inertial>
      <visual name="visual_mesh_3_link_0">
        <origin xyz="0 0 0" rpy="0 0 0"/>
        <geometry>
          <mesh filename="file:///home/userone/ba/puzzle-generator/puzzles/escape_room/meshes/stl/robot.stl" scale="1.0 1.0 1.0"/>
        </geometry>
        <material name="green"/>
      </visual>
      <collision name="collision_mesh_3_link_0">
        <origin xyz="0 0 0" rpy="0 0 0"/>
        <geometry>
          <mesh filename="file:///home/userone/ba/puzzle-generator/puzzles/escape_room/meshes/stl/robot.001.stl" scale="1.0 1.0 1.0"/>
        </geometry>
      </collision>
    </link>

    <link name="link_0_joint_0.001">
      <inertial>
        <origin xyz="0 0 0" rpy="0 0 0"/>
        <mass value="0.001"/>
        <inertia ixx="0.001" ixy="0" ixz="0" iyy="0.001" iyz="0" izz="0.001"/>
      </inertial>
      <visual name="visual_mesh_3_link_0.001">
        <origin xyz="0 0 0" rpy="0 0 0"/>
        <geometry>
          <mesh filename="file:///home/userone/ba/puzzle-generator/puzzles/escape_room/meshes/stl/robot.002.stl" scale="0.995 0.995 0.995"/>
        </geometry>
        <material name="green_translucent"/>
      </visual>
    </link>

    <link name="link_0_joint_1">
      <inertial>
        <origin xyz="0 0 0" rpy="0 0 0"/>
        <mass value="0.001"/>
        <inertia ixx="0.001" ixy="0" ixz="0" iyy="0.001" iyz="0" izz="0.001"/>
      </inertial>
    </link>

    <link name="link_0_joint_1.001">
      <inertial>
        <origin xyz="0 0 0" rpy="0 0 0"/>
        <mass value="0.001"/>
        <inertia ixx="0.001" ixy="0" ixz="0" iyy="0.001" iyz="0" izz="0.001"/>
      </inertial>
    </link>

    <link name="link_0_joint_2">
      <inertial>
        <origin xyz="0 0 0" rpy="0 0 0"/>
        <mass value="0.001"/>
        <inertia ixx="0.001" ixy="0" ixz="0" iyy="0.001" iyz="0" izz="0.001"/>
      </inertial>
    </link>

    <link name="link_1_joint_0">
      <inertial>
        <origin xyz="0 0 0" rpy="0 0 0"/>
        <mass value="0.001"/>
        <inertia ixx="0.001" ixy="0" ixz="0" iyy="0.001" iyz="0" izz="0.001"/>
      </inertial>
      <visual name="visual_mesh_6_link_1">
        <origin xyz="0 0 0" rpy="0 0 0"/>
        <geometry>
          <mesh filename="file:///home/userone/ba/puzzle-generator/puzzles/escape_room/meshes/stl/stick.stl" scale="1.0 1.0 1.0"/>
        </geometry>
        <material name="brown"/>
      </visual>
      <collision name="collision_mesh_6_link_1">
        <origin xyz="0 0 0" rpy="0 0 0"/>
        <geometry>
          <mesh filename="file:///home/userone/ba/puzzle-generator/puzzles/escape_room/meshes/stl/stick.001.stl" scale="1.0 1.0 1.0"/>
        </geometry>
      </collision>
    </link>

    <link name="link_1_joint_1">
      <inertial>
        <origin xyz="0 0 0" rpy="0 0 0"/>
        <mass value="0.001"/>
        <inertia ixx="0.001" ixy="0" ixz="0" iyy="0.001" iyz="0" izz="0.001"/>
      </inertial>
    </link>

    <link name="link_1_joint_2">
      <inertial>
        <origin xyz="0 0 0" rpy="0 0 0"/>
        <mass value="0.001"/>
        <inertia ixx="0.001" ixy="0" ixz="0" iyy="0.001" iyz="0" izz="0.001"/>
      </inertial>
    </link>

    <link name="link_2_joint_0">
      <inertial>
        <origin xyz="0 0 0" rpy="0 0 0"/>
        <mass value="0.001"/>
        <inertia ixx="0.001" ixy="0" ixz="0" iyy="0.001" iyz="0" izz="0.001"/>
      </inertial>
      <visual name="visual_cylinder_7_link_2">
        <origin xyz="0 0 0" rpy="0 0 0"/>
        <geometry>
          <cylinder radius="0.1975" length="0.995"/>
        </geometry>
        <material name="gray"/>
      </visual>
      <collision name="collision_cylinder_7_link_2">
        <origin xyz="0 0 0" rpy="0 0 0"/>
        <geometry>
          <cylinder radius="0.1975" length="0.995"/>
        </geometry>
      </collision>
    </link>

    <link name="link_fixed_0_floor">
      <inertial>
        <origin xyz="0 0 0" rpy="0 0 0"/>
        <mass value="0.001"/>
        <inertia ixx="0.001" ixy="0" ixz="0" iyy="0.001" iyz="0" izz="0.001"/>
      </inertial>
      <visual name="visual_box_fixed_0_floor">
        <origin xyz="0 0 0" rpy="0 0 0"/>
        <geometry>
          <box size="31.995 31.995 0.195"/>
        </geometry>
        <material name="lavender"/>
      </visual>
      <collision name="collision_box_fixed_0_floor">
        <origin xyz="0 0 0" rpy="0 0 0"/>
        <geometry>
          <box size="31.995 31.995 0.195"/>
        </geometry>
      </collision>
    </link>

    <link name="link_fixed_10_door_handle1">
      <inertial>
        <origin xyz="0 0 0" rpy="0 0 0"/>
        <mass value="0.001"/>
        <inertia ixx="0.001" ixy="0" ixz="0" iyy="0.001" iyz="0" izz="0.001"/>
      </inertial>
      <visual name="visual_box_fixed_10_door_handle1">
        <origin xyz="0 0 0" rpy="0 0 0"/>
        <geometry>
          <box size="0.045 0.195 0.195"/>
        </geometry>
        <material name="yellow"/>
      </visual>
      <collision name="collision_box_fixed_10_door_handle1">
        <origin xyz="0 0 0" rpy="0 0 0"/>
        <geometry>
          <box size="0.045 0.195 0.195"/>
        </geometry>
      </collision>
    </link>

    <link name="link_fixed_11_door_handle2">
      <inertial>
        <origin xyz="0 0 0" rpy="0 0 0"/>
        <mass value="0.001"/>
        <inertia ixx="0.001" ixy="0" ixz="0" iyy="0.001" iyz="0" izz="0.001"/>
      </inertial>
      <visual name="visual_box_fixed_11_door_handle2">
        <origin xyz="0 0 0" rpy="0 0 0"/>
        <geometry>
          <box size="0.045 0.195 0.195"/>
        </geometry>
        <material name="yellow"/>
      </visual>
      <collision name="collision_box_fixed_11_door_handle2">
        <origin xyz="0 0 0" rpy="0 0 0"/>
        <geometry>
          <box size="0.045 0.195 0.195"/>
        </geometry>
      </collision>
    </link>

    <link name="link_fixed_12_wall_left">
      <inertial>
        <origin xyz="0 0 0" rpy="0 0 0"/>
        <mass value="0.001"/>
        <inertia ixx="0.001" ixy="0" ixz="0" iyy="0.001" iyz="0" izz="0.001"/>
      </inertial>
      <visual name="visual_box_fixed_12_wall_left">
        <origin xyz="0 0 0" rpy="0 0 0"/>
        <geometry>
          <box size="3.795 0.195 0.495"/>
        </geometry>
        <material name="gray"/>
      </visual>
      <collision name="collision_box_fixed_12_wall_left">
        <origin xyz="0 0 0" rpy="0 0 0"/>
        <geometry>
          <box size="3.795 0.195 0.495"/>
        </geometry>
      </collision>
    </link>

    <link name="link_fixed_13_wall_front">
      <inertial>
        <origin xyz="0 0 0" rpy="0 0 0"/>
        <mass value="0.001"/>
        <inertia ixx="0.001" ixy="0" ixz="0" iyy="0.001" iyz="0" izz="0.001"/>
      </inertial>
      <visual name="visual_box_fixed_13_wall_front">
        <origin xyz="0 0 0" rpy="0 0 0"/>
        <geometry>
          <box size="0.195 7.995 0.495"/>
        </geometry>
        <material name="gray"/>
      </visual>
      <collision name="collision_box_fixed_13_wall_front">
        <origin xyz="0 0 0" rpy="0 0 0"/>
        <geometry>
          <box size="0.195 7.995 0.495"/>
        </geometry>
      </collision>
    </link>

    <link name="link_fixed_14_wall_back">
      <inertial>
        <origin xyz="0 0 0" rpy="0 0 0"/>
        <mass value="0.001"/>
        <inertia ixx="0.001" ixy="0" ixz="0" iyy="0.001" iyz="0" izz="0.001"/>
      </inertial>
      <visual name="visual_box_fixed_14_wall_back">
        <origin xyz="0 0 0" rpy="0 0 0"/>
        <geometry>
          <box size="0.195 7.995 0.495"/>
        </geometry>
        <material name="gray"/>
      </visual>
      <collision name="collision_box_fixed_14_wall_back">
        <origin xyz="0 0 0" rpy="0 0 0"/>
        <geometry>
          <box size="0.195 7.995 0.495"/>
        </geometry>
      </collision>
    </link>

    <link name="link_fixed_8_hinge">
      <inertial>
        <origin xyz="0 0 0" rpy="0 0 0"/>
        <mass value="0.001"/>
        <inertia ixx="0.001" ixy="0" ixz="0" iyy="0.001" iyz="0" izz="0.001"/>
      </inertial>
      <visual name="visual_cylinder_fixed_8_hinge">
        <origin xyz="0 0 0" rpy="0 0 0"/>
        <geometry>
          <cylinder radius="0.0475" length="1.095"/>
        </geometry>
        <material name="gray"/>
      </visual>
    </link>

    <link name="link_fixed_9_door_panel">
      <inertial>
        <origin xyz="0 0 0" rpy="0 0 0"/>
        <mass value="0.001"/>
        <inertia ixx="0.001" ixy="0" ixz="0" iyy="0.001" iyz="0" izz="0.001"/>
      </inertial>
      <visual name="visual_box_fixed_9_door_panel">
        <origin xyz="0 0 0" rpy="0 0 0"/>
        <geometry>
          <box size="3.195 0.195 0.995"/>
        </geometry>
        <material name="red"/>
      </visual>
      <collision name="collision_box_fixed_9_door_panel">
        <origin xyz="0 0 0" rpy="0 0 0"/>
        <geometry>
          <box size="3.195 0.195 0.995"/>
        </geometry>
      </collision>
    </link>

    <joint name="goal" type="fixed">
      <origin xyz="0 5.0 0.5" rpy="0 0 1.5708"/>
      <parent link="base_link"/>
      <child link="goal"/>
      <limit effort="0" velocity="0"/>
    </joint>

    <joint name="link_0_joint_0" type="revolute">
      <origin xyz="0 0 0" rpy="0 0 0"/>
      <parent link="link_0_joint_1"/>
      <child link="link_0_joint_0"/>
      <axis xyz="0 0 1.0"/>
      <limit lower="-3.14159" upper="3.14159" effort="0" velocity="0"/>
    </joint>

    <joint name="link_0_joint_0.001" type="fixed">
      <origin xyz="0 0 0" rpy="0 0 0"/>
      <parent link="link_0_joint_1.001"/>
      <child link="link_0_joint_0.001"/>
      <limit effort="0" velocity="0"/>
    </joint>

    <joint name="link_0_joint_1" type="prismatic">
      <origin xyz="0 0 0" rpy="0 0 0"/>
      <parent link="link_0_joint_2"/>
      <child link="link_0_joint_1"/>
      <axis xyz="0 1.0 0"/>
      <limit lower="-6.0" upper="6.0" effort="0" velocity="0"/>
    </joint>

    <joint name="link_0_joint_1.001" type="fixed">
      <origin xyz="0 0 0" rpy="0 0 0"/>
      <parent link="goal"/>
      <child link="link_0_joint_1.001"/>
      <limit effort="0" velocity="0"/>
    </joint>

    <joint name="link_0_joint_2" type="prismatic">
      <origin xyz="0 0 0.5" rpy="0 0 0"/>
      <parent link="base_link"/>
      <child link="link_0_joint_2"/>
      <axis xyz="1.0 0 0"/>
      <limit lower="-6.0" upper="6.0" effort="0" velocity="0"/>
    </joint>

    <joint name="link_1_joint_0" type="revolute">
      <origin xyz="0 0 0" rpy="0 0 0"/>
      <parent link="link_1_joint_1"/>
      <child link="link_1_joint_0"/>
      <axis xyz="0 0 1.0"/>
      <limit lower="-3.14159" upper="3.14159" effort="0" velocity="0"/>
    </joint>

    <joint name="link_1_joint_1" type="prismatic">
      <origin xyz="0 0 0" rpy="0 0 0"/>
      <parent link="link_1_joint_2"/>
      <child link="link_1_joint_1"/>
      <axis xyz="0 1.0 0"/>
      <limit lower="-6.0" upper="6.0" effort="0" velocity="0"/>
    </joint>

    <joint name="link_1_joint_2" type="prismatic">
      <origin xyz="-0.75 2.68884 0.25" rpy="0 0 0"/>
      <parent link="base_link"/>
      <child link="link_1_joint_2"/>
      <axis xyz="1.0 0 0"/>
      <limit lower="-6.0" upper="6.0" effort="0" velocity="0"/>
    </joint>

    <joint name="link_2_joint_0" type="revolute">
      <origin xyz="1.5 4.0 0.5" rpy="0 0 3.14159"/>
      <parent link="base_link"/>
      <child link="link_2_joint_0"/>
      <axis xyz="0 0 1.0"/>
      <limit lower="0" upper="1.5708" effort="0" velocity="0"/>
    </joint>

    <joint name="link_fixed_0_floor" type="fixed">
      <origin xyz="0 0 -0.1" rpy="0 0 0"/>
      <parent link="base_link"/>
      <child link="link_fixed_0_floor"/>
    </joint>

    <joint name="link_fixed_10_door_handle1" type="fixed">
      <origin xyz="2.4 0.2 0" rpy="0 0 0"/>
      <parent link="link_2_joint_0"/>
      <child link="link_fixed_10_door_handle1"/>
    </joint>

    <joint name="link_fixed_11_door_handle2" type="fixed">
      <origin xyz="2.4 -0.2 0" rpy="0 0 0"/>
      <parent link="link_2_joint_0"/>
      <child link="link_fixed_11_door_handle2"/>
    </joint>

    <joint name="link_fixed_12_wall_left" type="fixed">
      <origin xyz="0 -4.0 0.25" rpy="0 0 0"/>
      <parent link="base_link"/>
      <child link="link_fixed_12_wall_left"/>
    </joint>

    <joint name="link_fixed_13_wall_front" type="fixed">
      <origin xyz="2.0 0 0.25" rpy="0 0 0"/>
      <parent link="base_link"/>
      <child link="link_fixed_13_wall_front"/>
    </joint>

    <joint name="link_fixed_14_wall_back" type="fixed">
      <origin xyz="-2.0 0 0.25" rpy="0 0 0"/>
      <parent link="base_link"/>
      <child link="link_fixed_14_wall_back"/>
    </joint>

    <joint name="link_fixed_8_hinge" type="fixed">
      <origin xyz="0 0 0" rpy="0 0 0"/>
      <parent link="link_2_joint_0"/>
      <child link="link_fixed_8_hinge"/>
    </joint>

    <joint name="link_fixed_9_door_panel" type="fixed">
      <origin xyz="1.6 0 0" rpy="0 0 0"/>
      <parent link="link_2_joint_0"/>
      <child link="link_fixed_9_door_panel"/>
    </joint>

    <material name="brown">
      <color rgba="0.38 0.2 0.07 1.0"/>
    </material>

    <material name="gray">
      <color rgba="0.5 0.5 0.5 1.0"/>
    </material>

    <material name="green">
      <color rgba="0 1.0 0 1.0"/>
    </material>

    <material name="green_translucent">
      <color rgba="0 1.0 0 0.25"/>
    </material>

    <material name="lavender">
      <color rgba="0.8 0.8 1.0 1.0"/>
    </material>

    <material name="red">
      <color rgba="1.0 0 0 1.0"/>
    </material>

    <material name="yellow">
      <color rgba="1.0 1.0 0 1.0"/>
    </material>

  </robot>
