<?xml version="1.0"?>
<!-- created with Phobos 1.0.1 "Capricious Choutengan" -->
  <robot name="lockbox2017">

    <link name="base_link">
      <inertial>
        <origin xyz="0 0 0" rpy="0 0 0"/>
        <mass value="0.001"/>
        <inertia ixx="0.001" ixy="0" ixz="0" iyy="0.001" iyz="0" izz="0.001"/>
      </inertial>
      <visual name="visual_cube_base">
        <origin xyz="0 0 0" rpy="0 0 0"/>
        <geometry>
          <box size="32.0 32.0 0.2"/>
        </geometry>
        <material name="lavender"/>
      </visual>
      <collision name="collision_cube_base">
        <origin xyz="0 0 0" rpy="0 0 0"/>
        <geometry>
          <box size="32.0 32.0 0.2"/>
        </geometry>
      </collision>
    </link>

    <link name="link_1">
      <inertial>
        <origin xyz="0 0 0" rpy="0 0 0"/>
        <mass value="0.001"/>
        <inertia ixx="0.001" ixy="0" ixz="0" iyy="0.001" iyz="0" izz="0.001"/>
      </inertial>
      <visual name="visual_cube_1">
        <origin xyz="0 0 0" rpy="0 0 0"/>
        <geometry>
          <box size="0.8 1.0 3.6"/>
        </geometry>
        <material name="red"/>
      </visual>
      <collision name="collision_cube_1">
        <origin xyz="0 0 0" rpy="0 0 0"/>
        <geometry>
          <box size="0.8 1.0 3.6"/>
        </geometry>
      </collision>
    </link>

    <link name="link_2">
      <inertial>
        <origin xyz="0 0 0" rpy="0 0 0"/>
        <mass value="0.001"/>
        <inertia ixx="0.001" ixy="0" ixz="0" iyy="0.001" iyz="0" izz="0.001"/>
      </inertial>
      <visual name="visual_mesh_2">
        <origin xyz="0 0 0" rpy="0 0 0"/>
        <geometry>
          <mesh filename="file:///home/userone/ba/puzzle-generator/puzzles/lockbox2017/meshes/stl/slot_disc.stl" scale="1.0 1.0 1.0"/>
        </geometry>
        <material name="red"/>
      </visual>
      <collision concave="yes" name="collision_mesh_2">
        <origin xyz="-0.03587 0 0" rpy="0 0 0"/>
        <geometry>
          <mesh filename="file:///home/userone/ba/puzzle-generator/puzzles/lockbox2017/meshes/stl/slot_disc.001.stl" scale="1.0 1.0 1.0"/>
        </geometry>
      </collision>
    </link>

    <link name="link_3">
      <inertial>
        <origin xyz="0 0 0" rpy="0 0 0"/>
        <mass value="0.001"/>
        <inertia ixx="0.001" ixy="0" ixz="0" iyy="0.001" iyz="0" izz="0.001"/>
      </inertial>
      <visual name="visual_cube_3">
        <origin xyz="0 0 0" rpy="0 0 0"/>
        <geometry>
          <box size="0.8 1.0 3.6"/>
        </geometry>
        <material name="red"/>
      </visual>
      <collision name="collision_cube_3">
        <origin xyz="0 0 0" rpy="0 0 0"/>
        <geometry>
          <box size="0.8 1.0 3.6"/>
        </geometry>
      </collision>
    </link>

    <link name="link_door_0">
      <inertial>
        <origin xyz="0 0 0" rpy="0 0 0"/>
        <mass value="0.001"/>
        <inertia ixx="0.001" ixy="0" ixz="0" iyy="0.001" iyz="0" izz="0.001"/>
      </inertial>
      <visual name="visual_cylinder_door_0">
        <origin xyz="0 0 0" rpy="0 0 0"/>
        <geometry>
          <cylinder radius="0.2" length="2.0"/>
        </geometry>
        <material name="gray"/>
      </visual>
      <collision name="collision_cylinder_door_0">
        <origin xyz="0 0 0" rpy="0 0 0"/>
        <geometry>
          <cylinder radius="0.2" length="2.0"/>
        </geometry>
      </collision>
    </link>

    <link name="link_door_4">
      <inertial>
        <origin xyz="0 0 0" rpy="0 0 0"/>
        <mass value="0.001"/>
        <inertia ixx="0.001" ixy="0" ixz="0" iyy="0.001" iyz="0" izz="0.001"/>
      </inertial>
      <visual name="visual_cylinder_door_4">
        <origin xyz="0 0 0" rpy="0 0 0"/>
        <geometry>
          <cylinder radius="0.2" length="2.0"/>
        </geometry>
        <material name="gray"/>
      </visual>
      <collision name="collision_cylinder_door_4">
        <origin xyz="0 0 0" rpy="0 0 0"/>
        <geometry>
          <cylinder radius="0.2" length="2.0"/>
        </geometry>
      </collision>
    </link>

    <link name="link_door_handle_0">
      <inertial>
        <origin xyz="0 0 0" rpy="0 0 0"/>
        <mass value="0.001"/>
        <inertia ixx="0.001" ixy="0" ixz="0" iyy="0.001" iyz="0" izz="0.001"/>
      </inertial>
      <visual name="visual_cube_door_handle_0">
        <origin xyz="0 0 0" rpy="0 0 0"/>
        <geometry>
          <box size="0.2 0.05 0.2"/>
        </geometry>
        <material name="yellow"/>
      </visual>
      <collision name="collision_cube_door_handle_0">
        <origin xyz="0 0 0" rpy="0 0 0"/>
        <geometry>
          <box size="0.2 0.05 0.2"/>
        </geometry>
      </collision>
    </link>

    <link name="link_door_handle_4">
      <inertial>
        <origin xyz="0 0 0" rpy="0 0 0"/>
        <mass value="0.001"/>
        <inertia ixx="0.001" ixy="0" ixz="0" iyy="0.001" iyz="0" izz="0.001"/>
      </inertial>
      <visual name="visual_cube_door_handle_4">
        <origin xyz="0 0 0" rpy="0 0 0"/>
        <geometry>
          <box size="0.2 0.05 0.2"/>
        </geometry>
        <material name="yellow"/>
      </visual>
      <collision name="collision_cube_door_handle_4">
        <origin xyz="0 0 0" rpy="0 0 0"/>
        <geometry>
          <box size="0.2 0.05 0.2"/>
        </geometry>
      </collision>
    </link>

    <link name="link_door_panel_0">
      <inertial>
        <origin xyz="0 0 0" rpy="0 0 0"/>
        <mass value="0.001"/>
        <inertia ixx="0.001" ixy="0" ixz="0" iyy="0.001" iyz="0" izz="0.001"/>
      </inertial>
      <visual name="visual_cube_door_panel_0">
        <origin xyz="0 0 0" rpy="0 0 0"/>
        <geometry>
          <box size="2.0 0.2 2.0"/>
        </geometry>
        <material name="green"/>
      </visual>
      <collision name="collision_cube_door_panel_0">
        <origin xyz="0 0 0" rpy="0 0 0"/>
        <geometry>
          <box size="2.0 0.2 2.0"/>
        </geometry>
      </collision>
    </link>

    <link name="link_door_panel_4">
      <inertial>
        <origin xyz="0 0 0" rpy="0 0 0"/>
        <mass value="0.001"/>
        <inertia ixx="0.001" ixy="0" ixz="0" iyy="0.001" iyz="0" izz="0.001"/>
      </inertial>
      <visual name="visual_cube_door_panel_4">
        <origin xyz="0 0 0" rpy="0 0 0"/>
        <geometry>
          <box size="4.0 0.2 2.0"/>
        </geometry>
        <material name="red"/>
      </visual>
      <collision name="collision_cube_door_panel_4">
        <origin xyz="0 0 0" rpy="0 0 0"/>
        <geometry>
          <box size="4.0 0.2 2.0"/>
        </geometry>
      </collision>
    </link>

    <link name="link_handle_knob_1">
      <inertial>
        <origin xyz="0 0 0" rpy="0 0 0"/>
        <mass value="0.001"/>
        <inertia ixx="0.001" ixy="0" ixz="0" iyy="0.001" iyz="0" izz="0.001"/>
      </inertial>
      <visual name="visual_cube_handle_knob_1">
        <origin xyz="0 0 0" rpy="0 0 0"/>
        <geometry>
          <box size="0.05 0.05 0.2"/>
        </geometry>
        <material name="yellow"/>
      </visual>
      <collision name="collision_cube_handle_knob_1">
        <origin xyz="0 0 0" rpy="0 0 0"/>
        <geometry>
          <box size="0.05 0.05 0.2"/>
        </geometry>
      </collision>
    </link>

    <link name="link_handle_knob_2">
      <inertial>
        <origin xyz="0 0 0" rpy="0 0 0"/>
        <mass value="0.001"/>
        <inertia ixx="0.001" ixy="0" ixz="0" iyy="0.001" iyz="0" izz="0.001"/>
      </inertial>
      <visual name="visual_cube_handle_knob_2">
        <origin xyz="0 0 0" rpy="0 0 0"/>
        <geometry>
          <box size="0.05 0.05 0.2"/>
        </geometry>
        <material name="yellow"/>
      </visual>
      <collision name="collision_cube_handle_knob_2">
        <origin xyz="0 0 0" rpy="0 0 0"/>
        <geometry>
          <box size="0.05 0.05 0.2"/>
        </geometry>
      </collision>
    </link>

    <link name="link_handle_knob_3">
      <inertial>
        <origin xyz="0 0 0" rpy="0 0 0"/>
        <mass value="0.001"/>
        <inertia ixx="0.001" ixy="0" ixz="0" iyy="0.001" iyz="0" izz="0.001"/>
      </inertial>
      <visual name="visual_cube_handle_knob_3">
        <origin xyz="0 0 0" rpy="0 0 0"/>
        <geometry>
          <box size="0.05 0.05 0.2"/>
        </geometry>
        <material name="yellow"/>
      </visual>
      <collision name="collision_cube_handle_knob_3">
        <origin xyz="0 0 0" rpy="0 0 0"/>
        <geometry>
          <box size="0.05 0.05 0.2"/>
        </geometry>
      </collision>
    </link>

    <link name="link_handle_shaft_1">
      <inertial>
        <origin xyz="0 0 0" rpy="0 0 0"/>
        <mass value="0.001"/>
        <inertia ixx="0.001" ixy="0" ixz="0" iyy="0.001" iyz="0" izz="0.001"/>
      </inertial>
      <visual name="visual_cube_handle_shaft_1">
        <origin xyz="0 0 0" rpy="0 0 0"/>
        <geometry>
          <box size="0.2 0.2 1.0"/>
        </geometry>
        <material name="red"/>
      </visual>
      <collision name="collision_cube_handle_shaft_1">
        <origin xyz="0 0 0" rpy="0 0 0"/>
        <geometry>
          <box size="0.2 0.2 1.0"/>
        </geometry>
      </collision>
    </link>

    <link name="link_handle_shaft_2">
      <inertial>
        <origin xyz="0 0 0" rpy="0 0 0"/>
        <mass value="0.001"/>
        <inertia ixx="0.001" ixy="0" ixz="0" iyy="0.001" iyz="0" izz="0.001"/>
      </inertial>
      <visual name="visual_cylinder_handle_shaft_2">
        <origin xyz="0 0 0" rpy="0 0 0"/>
        <geometry>
          <cylinder radius="0.1" length="1.0"/>
        </geometry>
        <material name="red"/>
      </visual>
      <collision name="collision_cylinder_handle_shaft_2">
        <origin xyz="0 0 0" rpy="0 0 0"/>
        <geometry>
          <cylinder radius="0.1" length="1.0"/>
        </geometry>
      </collision>
    </link>

    <link name="link_handle_shaft_3">
      <inertial>
        <origin xyz="0 0 0" rpy="0 0 0"/>
        <mass value="0.001"/>
        <inertia ixx="0.001" ixy="0" ixz="0" iyy="0.001" iyz="0" izz="0.001"/>
      </inertial>
      <visual name="visual_cube_handle_shaft_3">
        <origin xyz="0 0 0" rpy="0 0 0"/>
        <geometry>
          <box size="0.2 0.2 1.0"/>
        </geometry>
        <material name="red"/>
      </visual>
      <collision name="collision_cube_handle_shaft_3">
        <origin xyz="0 0 0" rpy="0 0 0"/>
        <geometry>
          <box size="0.2 0.2 1.0"/>
        </geometry>
      </collision>
    </link>

    <link name="link_hinge_0">
      <inertial>
        <origin xyz="0 0 0" rpy="0 0 0"/>
        <mass value="0.001"/>
        <inertia ixx="0.001" ixy="0" ixz="0" iyy="0.001" iyz="0" izz="0.001"/>
      </inertial>
      <visual name="visual_cylinder_hinge_0">
        <origin xyz="0 0 0" rpy="0 0 0"/>
        <geometry>
          <cylinder radius="0.05" length="2.1"/>
        </geometry>
        <material name="gray"/>
      </visual>
      <collision name="collision_cylinder_hinge_0">
        <origin xyz="0 0 0" rpy="0 0 0"/>
        <geometry>
          <cylinder radius="0.05" length="2.1"/>
        </geometry>
      </collision>
    </link>

    <link name="link_hinge_2">
      <inertial>
        <origin xyz="0 0 0" rpy="0 0 0"/>
        <mass value="0.001"/>
        <inertia ixx="0.001" ixy="0" ixz="0" iyy="0.001" iyz="0" izz="0.001"/>
      </inertial>
      <visual name="visual_cylinder_hinge_2">
        <origin xyz="0 0 0" rpy="0 0 0"/>
        <geometry>
          <cylinder radius="0.05" length="1.1"/>
        </geometry>
        <material name="gray"/>
      </visual>
      <collision name="collision_cylinder_hinge_2">
        <origin xyz="0 0 0" rpy="0 0 0"/>
        <geometry>
          <cylinder radius="0.05" length="1.1"/>
        </geometry>
      </collision>
    </link>

    <link name="link_hinge_4">
      <inertial>
        <origin xyz="0 0 0" rpy="0 0 0"/>
        <mass value="0.001"/>
        <inertia ixx="0.001" ixy="0" ixz="0" iyy="0.001" iyz="0" izz="0.001"/>
      </inertial>
      <visual name="visual_cylinder_hinge_4">
        <origin xyz="0 0 0" rpy="0 0 0"/>
        <geometry>
          <cylinder radius="0.05" length="2.1"/>
        </geometry>
        <material name="gray"/>
      </visual>
      <collision name="collision_cylinder_hinge_4">
        <origin xyz="0 0 0" rpy="0 0 0"/>
        <geometry>
          <cylinder radius="0.05" length="2.1"/>
        </geometry>
      </collision>
    </link>

    <joint name="link_1" type="prismatic">
      <origin xyz="-4.0 0 0.6" rpy="-1.5708 0 -1.5708"/>
      <parent link="base_link"/>
      <child link="link_1"/>
      <axis xyz="0 0 1.0"/>
      <limit lower="0" upper="2.0" effort="0" velocity="0"/>
    </joint>

    <joint name="link_2" type="revolute">
      <origin xyz="0 0 0.6" rpy="0 0 1.5708"/>
      <parent link="base_link"/>
      <child link="link_2"/>
      <axis xyz="0 0 1.0"/>
      <limit lower="0" upper="1.5708" effort="0" velocity="0"/>
    </joint>

    <joint name="link_3" type="prismatic">
      <origin xyz="0 2.0 0.6" rpy="-1.5708 0 0"/>
      <parent link="base_link"/>
      <child link="link_3"/>
      <axis xyz="0 0 1.0"/>
      <limit lower="0" upper="2.0" effort="0" velocity="0"/>
    </joint>

    <joint name="link_door_0" type="revolute">
      <origin xyz="-6.0 -1.0 0.6" rpy="0 0 0"/>
      <parent link="base_link"/>
      <child link="link_door_0"/>
      <axis xyz="0 0 1.0"/>
      <limit lower="0" upper="1.5708" effort="0" velocity="0"/>
    </joint>

    <joint name="link_door_4" type="revolute">
      <origin xyz="-2.0 4.0 1.1" rpy="0 0 0"/>
      <parent link="base_link"/>
      <child link="link_door_4"/>
      <axis xyz="0 0 1.0"/>
      <limit lower="0" upper="1.5708" effort="0" velocity="0"/>
    </joint>

    <joint name="link_door_handle_0" type="fixed">
      <origin xyz="1.5 0 1.1" rpy="0 0 0"/>
      <parent link="link_door_0"/>
      <child link="link_door_handle_0"/>
    </joint>

    <joint name="link_door_handle_4" type="fixed">
      <origin xyz="3.0 0 1.1" rpy="0 0 0"/>
      <parent link="link_door_4"/>
      <child link="link_door_handle_4"/>
    </joint>

    <joint name="link_door_panel_0" type="fixed">
      <origin xyz="1.0 0 0" rpy="0 0 0"/>
      <parent link="link_door_0"/>
      <child link="link_door_panel_0"/>
    </joint>

    <joint name="link_door_panel_4" type="fixed">
      <origin xyz="2.0 0 0" rpy="0 0 0"/>
      <parent link="link_door_4"/>
      <child link="link_door_panel_4"/>
    </joint>

    <joint name="link_handle_knob_1" type="fixed">
      <origin xyz="0 0 0.6" rpy="0 0 0"/>
      <parent link="link_handle_shaft_1"/>
      <child link="link_handle_knob_1"/>
    </joint>

    <joint name="link_handle_knob_2" type="fixed">
      <origin xyz="0 0 0.6" rpy="0 0 0"/>
      <parent link="link_handle_shaft_2"/>
      <child link="link_handle_knob_2"/>
    </joint>

    <joint name="link_handle_knob_3" type="fixed">
      <origin xyz="0 0 0.6" rpy="0 0 0"/>
      <parent link="link_handle_shaft_3"/>
      <child link="link_handle_knob_3"/>
    </joint>

    <joint name="link_handle_shaft_1" type="fixed">
      <origin xyz="0 -1.0 0" rpy="1.5708 0 0"/>
      <parent link="link_1"/>
      <child link="link_handle_shaft_1"/>
    </joint>

    <joint name="link_handle_shaft_2" type="fixed">
      <origin xyz="0 1.5 1.0" rpy="0 0 0"/>
      <parent link="link_2"/>
      <child link="link_handle_shaft_2"/>
    </joint>

    <joint name="link_handle_shaft_3" type="fixed">
      <origin xyz="0 -1.0 0" rpy="1.5708 0 0"/>
      <parent link="link_3"/>
      <child link="link_handle_shaft_3"/>
    </joint>

    <joint name="link_hinge_0" type="fixed">
      <origin xyz="0 0 0" rpy="0 0 0"/>
      <parent link="link_door_0"/>
      <child link="link_hinge_0"/>
    </joint>

    <joint name="link_hinge_2" type="fixed">
      <origin xyz="0 0 0" rpy="0 0 0"/>
      <parent link="link_2"/>
      <child link="link_hinge_2"/>
    </joint>

    <joint name="link_hinge_4" type="fixed">
      <origin xyz="0 0 0" rpy="0 0 0"/>
      <parent link="link_door_4"/>
      <child link="link_hinge_4"/>
    </joint>

    <material name="gray">
      <color rgba="0.5 0.5 0.5 1.0"/>
    </material>

    <material name="green">
      <color rgba="0 1.0 0 1.0"/>
    </material>

    <material name="lavender">
      <color rgba="0.8 0.8 1.0 1.0"/>
    </material>

    <material name="red">
      <color rgba="1.0 0 0 1.0"/>
    </material>

    <material name="yellow">
      <color rgba="1.0 1.0 0 1.0"/>
    </material>

  </robot>
