<?xml version="1.0"?>
<!-- created with Phobos 1.0.1 "Capricious Choutengan" -->
  <robot name="lockbox2017">

    <link name="base_link">
      <inertial>
        <origin xyz="0 0 0" rpy="0 0 0"/>
        <mass value="0.001"/>
        <inertia ixx="0.001" ixy="0" ixz="0" iyy="0.001" iyz="0" izz="0.001"/>
      </inertial>
      <visual name="visual_cube_base">
        <origin xyz="0 0 0" rpy="0 0 0"/>
        <geometry>
          <box size="32.0 32.0 0.2"/>
        </geometry>
        <material name="lavender"/>
      </visual>
      <collision name="collision_cube_base">
        <origin xyz="0 0 0" rpy="0 0 0"/>
        <geometry>
          <box size="32.0 32.0 0.2"/>
        </geometry>
      </collision>
    </link>

    <link name="link0">
      <inertial>
        <origin xyz="0 0 0" rpy="0 0 0"/>
        <mass value="0.001"/>
        <inertia ixx="0.001" ixy="0" ixz="0" iyy="0.001" iyz="0" izz="0.001"/>
      </inertial>
      <visual name="visual_cube0">
        <origin xyz="0 0 0" rpy="0 0 0"/>
        <geometry>
          <box size="0.1 1.0 3.4"/>
        </geometry>
        <material name="red"/>
      </visual>
      <collision name="collision_cube0">
        <origin xyz="0 0 0" rpy="0 0 0"/>
        <geometry>
          <box size="0.1 1.0 3.4"/>
        </geometry>
      </collision>
    </link>

    <link name="link1">
      <inertial>
        <origin xyz="0 0 0" rpy="0 0 0"/>
        <mass value="0.001"/>
        <inertia ixx="0.001" ixy="0" ixz="0" iyy="0.001" iyz="0" izz="0.001"/>
      </inertial>
      <visual name="visual_mesh1">
        <origin xyz="0 0 0" rpy="0 0 0"/>
        <geometry>
          <mesh filename="file:///home/userone/ba/puzzle-generator/puzzles/lockbox2017/meshes/stl/slot_disc.stl" scale="0.5 0.5 0.5"/>
        </geometry>
        <material name="green"/>
      </visual>
      <collision name="collision_mesh1">
        <origin xyz="-0.00897 0 0" rpy="0 0 0"/>
        <geometry>
          <mesh filename="file:///home/userone/ba/puzzle-generator/puzzles/lockbox2017/meshes/stl/slot_disc.001.stl" scale="1.0 1.0 1.0"/>
        </geometry>
      </collision>
    </link>

    <joint name="link0" type="prismatic">
      <origin xyz="3.0 0 0.6" rpy="-1.5708 0 1.5708"/>
      <parent link="base_link"/>
      <child link="link0"/>
      <axis xyz="0 0 1.0"/>
      <limit lower="0" upper="1.0" effort="0" velocity="0"/>
    </joint>

    <joint name="link1" type="revolute">
      <origin xyz="0 0 0.6" rpy="0 0 0"/>
      <parent link="base_link"/>
      <child link="link1"/>
      <axis xyz="0 0 1.0"/>
      <limit lower="-6.28319" upper="6.28319" effort="0" velocity="0"/>
    </joint>

    <material name="green">
      <color rgba="0 1.0 0 1.0"/>
    </material>

    <material name="lavender">
      <color rgba="0.8 0.8 1.0 1.0"/>
    </material>

    <material name="red">
      <color rgba="1.0 0 0 1.0"/>
    </material>

  </robot>
