<?xml version="1.0"?>
<!-- created with Phobos 1.0.1 "Capricious Choutengan" -->
  <robot name="lockbox2017">

    <link name="base_link">
      <inertial>
        <origin xyz="0 0 0" rpy="0 0 0"/>
        <mass value="0.001"/>
        <inertia ixx="0.001" ixy="0" ixz="0" iyy="0.001" iyz="0" izz="0.001"/>
      </inertial>
    </link>

    <link name="goal">
      <inertial>
        <origin xyz="0 0 0" rpy="0 0 0"/>
        <mass value="0.001"/>
        <inertia ixx="0.001" ixy="0" ixz="0" iyy="0.001" iyz="0" izz="0.001"/>
      </inertial>
      <visual name="visual_cylinder_1_link_0.001">
        <origin xyz="0 0 0" rpy="0 0 0"/>
        <geometry>
          <cylinder radius="0.19651" length="1.98503"/>
        </geometry>
        <material name="green_translucent"/>
      </visual>
    </link>

    <link name="link_0_joint_0">
      <inertial>
        <origin xyz="0 0 0" rpy="0 0 0"/>
        <mass value="0.001"/>
        <inertia ixx="0.001" ixy="0" ixz="0" iyy="0.001" iyz="0" izz="0.001"/>
      </inertial>
      <visual name="visual_cylinder_1_link_0">
        <origin xyz="0 0 0" rpy="0 0 0"/>
        <geometry>
          <cylinder radius="0.1975" length="1.995"/>
        </geometry>
        <material name="gray"/>
      </visual>
      <collision name="collision_cylinder_1_link_0">
        <origin xyz="0 0 0" rpy="0 0 0"/>
        <geometry>
          <cylinder radius="0.1975" length="1.995"/>
        </geometry>
      </collision>
    </link>

    <link name="link_1_joint_0">
      <inertial>
        <origin xyz="0 0 0" rpy="0 0 0"/>
        <mass value="0.001"/>
        <inertia ixx="0.001" ixy="0" ixz="0" iyy="0.001" iyz="0" izz="0.001"/>
      </inertial>
      <visual name="visual_box_5_link_1">
        <origin xyz="0 0 0" rpy="0 0 0"/>
        <geometry>
          <box size="2.995 0.495 0.995"/>
        </geometry>
        <material name="red"/>
      </visual>
      <collision name="collision_box_5_link_1">
        <origin xyz="0 0 0" rpy="0 0 0"/>
        <geometry>
          <box size="2.995 0.495 0.995"/>
        </geometry>
      </collision>
    </link>

    <link name="link_2_joint_0">
      <inertial>
        <origin xyz="0 0 0" rpy="0 0 0"/>
        <mass value="0.001"/>
        <inertia ixx="0.001" ixy="0" ixz="0" iyy="0.001" iyz="0" izz="0.001"/>
      </inertial>
      <visual name="visual_mesh_8_link_2">
        <origin xyz="0 0 0" rpy="0 0 0"/>
        <geometry>
          <mesh filename="file:///home/userone/ba/puzzle-generator/puzzles/lockbox2017/meshes/stl/slot_disc.stl" scale="1.0 1.0 1.0"/>
        </geometry>
        <material name="red"/>
      </visual>
      <collision concave="yes" name="collision_mesh_8_link_2">
        <origin xyz="0 0 0" rpy="0 0 0"/>
        <geometry>
          <mesh filename="file:///home/userone/ba/puzzle-generator/puzzles/lockbox2017/meshes/stl/slot_disc.001.stl" scale="1.0 1.0 1.0"/>
        </geometry>
      </collision>
    </link>

    <link name="link_3_joint_0">
      <inertial>
        <origin xyz="0 0 0" rpy="0 0 0"/>
        <mass value="0.001"/>
        <inertia ixx="0.001" ixy="0" ixz="0" iyy="0.001" iyz="0" izz="0.001"/>
      </inertial>
      <visual name="visual_box_12_link_3">
        <origin xyz="0 0 0" rpy="0 0 0"/>
        <geometry>
          <box size="2.995 0.495 0.995"/>
        </geometry>
        <material name="red"/>
      </visual>
      <collision name="collision_box_12_link_3">
        <origin xyz="0 0 0" rpy="0 0 0"/>
        <geometry>
          <box size="2.995 0.495 0.995"/>
        </geometry>
      </collision>
    </link>

    <link name="link_4_joint_0">
      <inertial>
        <origin xyz="0 0 0" rpy="0 0 0"/>
        <mass value="0.001"/>
        <inertia ixx="0.001" ixy="0" ixz="0" iyy="0.001" iyz="0" izz="0.001"/>
      </inertial>
      <visual name="visual_cylinder_15_link_4">
        <origin xyz="0 0 0" rpy="0 0 0"/>
        <geometry>
          <cylinder radius="0.1975" length="1.995"/>
        </geometry>
        <material name="gray"/>
      </visual>
      <collision name="collision_cylinder_15_link_4">
        <origin xyz="0 0 0" rpy="0 0 0"/>
        <geometry>
          <cylinder radius="0.1975" length="1.995"/>
        </geometry>
      </collision>
    </link>

    <link name="link_fixed_0_floor">
      <inertial>
        <origin xyz="0 0 0" rpy="0 0 0"/>
        <mass value="0.001"/>
        <inertia ixx="0.001" ixy="0" ixz="0" iyy="0.001" iyz="0" izz="0.001"/>
      </inertial>
      <visual name="visual_box_fixed_0_floor">
        <origin xyz="0 0 0" rpy="0 0 0"/>
        <geometry>
          <box size="31.995 31.995 0.195"/>
        </geometry>
        <material name="lavender"/>
      </visual>
      <collision name="collision_box_fixed_0_floor">
        <origin xyz="0 0 0" rpy="0 0 0"/>
        <geometry>
          <box size="31.995 31.995 0.195"/>
        </geometry>
      </collision>
    </link>

    <link name="link_fixed_10_handle_shaft">
      <inertial>
        <origin xyz="0 0 0" rpy="0 0 0"/>
        <mass value="0.001"/>
        <inertia ixx="0.001" ixy="0" ixz="0" iyy="0.001" iyz="0" izz="0.001"/>
      </inertial>
      <visual name="visual_cylinder_fixed_10_handle_shaft">
        <origin xyz="0 0 0" rpy="0 0 0"/>
        <geometry>
          <cylinder radius="0.0975" length="0.995"/>
        </geometry>
        <material name="red"/>
      </visual>
      <collision name="collision_cylinder_fixed_10_handle_shaft">
        <origin xyz="0 0 0" rpy="0 0 0"/>
        <geometry>
          <cylinder radius="0.0975" length="0.995"/>
        </geometry>
      </collision>
    </link>

    <link name="link_fixed_11_handle_knob">
      <inertial>
        <origin xyz="0 0 0" rpy="0 0 0"/>
        <mass value="0.001"/>
        <inertia ixx="0.001" ixy="0" ixz="0" iyy="0.001" iyz="0" izz="0.001"/>
      </inertial>
      <visual name="visual_box_fixed_11_handle_knob">
        <origin xyz="0 0 0" rpy="0 0 0"/>
        <geometry>
          <box size="0.045 0.045 0.195"/>
        </geometry>
        <material name="yellow"/>
      </visual>
      <collision name="collision_box_fixed_11_handle_knob">
        <origin xyz="0 0 0" rpy="0 0 0"/>
        <geometry>
          <box size="0.045 0.045 0.195"/>
        </geometry>
      </collision>
    </link>

    <link name="link_fixed_13_handle_shaft">
      <inertial>
        <origin xyz="0 0 0" rpy="0 0 0"/>
        <mass value="0.001"/>
        <inertia ixx="0.001" ixy="0" ixz="0" iyy="0.001" iyz="0" izz="0.001"/>
      </inertial>
      <visual name="visual_box_fixed_13_handle_shaft">
        <origin xyz="0 0 0" rpy="0 0 0"/>
        <geometry>
          <box size="0.195 0.195 0.995"/>
        </geometry>
        <material name="red"/>
      </visual>
      <collision name="collision_box_fixed_13_handle_shaft">
        <origin xyz="0 0 0" rpy="0 0 0"/>
        <geometry>
          <box size="0.195 0.195 0.995"/>
        </geometry>
      </collision>
    </link>

    <link name="link_fixed_14_handle_knob">
      <inertial>
        <origin xyz="0 0 0" rpy="0 0 0"/>
        <mass value="0.001"/>
        <inertia ixx="0.001" ixy="0" ixz="0" iyy="0.001" iyz="0" izz="0.001"/>
      </inertial>
      <visual name="visual_box_fixed_14_handle_knob">
        <origin xyz="0 0 0" rpy="0 0 0"/>
        <geometry>
          <box size="0.045 0.045 0.195"/>
        </geometry>
        <material name="yellow"/>
      </visual>
      <collision name="collision_box_fixed_14_handle_knob">
        <origin xyz="0 0 0" rpy="0 0 0"/>
        <geometry>
          <box size="0.045 0.045 0.195"/>
        </geometry>
      </collision>
    </link>

    <link name="link_fixed_16_hinge">
      <inertial>
        <origin xyz="0 0 0" rpy="0 0 0"/>
        <mass value="0.001"/>
        <inertia ixx="0.001" ixy="0" ixz="0" iyy="0.001" iyz="0" izz="0.001"/>
      </inertial>
      <visual name="visual_cylinder_fixed_16_hinge">
        <origin xyz="0 0 0" rpy="0 0 0"/>
        <geometry>
          <cylinder radius="0.0475" length="2.195"/>
        </geometry>
        <material name="gray"/>
      </visual>
    </link>

    <link name="link_fixed_17_door_panel">
      <inertial>
        <origin xyz="0 0 0" rpy="0 0 0"/>
        <mass value="0.001"/>
        <inertia ixx="0.001" ixy="0" ixz="0" iyy="0.001" iyz="0" izz="0.001"/>
      </inertial>
      <visual name="visual_box_fixed_17_door_panel">
        <origin xyz="0 0 0" rpy="0 0 0"/>
        <geometry>
          <box size="3.995 0.195 1.995"/>
        </geometry>
        <material name="red"/>
      </visual>
      <collision name="collision_box_fixed_17_door_panel">
        <origin xyz="0 0 0" rpy="0 0 0"/>
        <geometry>
          <box size="3.995 0.195 1.995"/>
        </geometry>
      </collision>
    </link>

    <link name="link_fixed_18_door_handle">
      <inertial>
        <origin xyz="0 0 0" rpy="0 0 0"/>
        <mass value="0.001"/>
        <inertia ixx="0.001" ixy="0" ixz="0" iyy="0.001" iyz="0" izz="0.001"/>
      </inertial>
      <visual name="visual_box_fixed_18_door_handle">
        <origin xyz="0 0 0" rpy="0 0 0"/>
        <geometry>
          <box size="0.195 0.045 0.195"/>
        </geometry>
        <material name="yellow"/>
      </visual>
      <collision name="collision_box_fixed_18_door_handle">
        <origin xyz="0 0 0" rpy="0 0 0"/>
        <geometry>
          <box size="0.195 0.045 0.195"/>
        </geometry>
      </collision>
    </link>

    <link name="link_fixed_2_hinge">
      <inertial>
        <origin xyz="0 0 0" rpy="0 0 0"/>
        <mass value="0.001"/>
        <inertia ixx="0.001" ixy="0" ixz="0" iyy="0.001" iyz="0" izz="0.001"/>
      </inertial>
      <visual name="visual_cylinder_fixed_2_hinge">
        <origin xyz="0 0 0" rpy="0 0 0"/>
        <geometry>
          <cylinder radius="0.0475" length="2.195"/>
        </geometry>
        <material name="gray"/>
      </visual>
    </link>

    <link name="link_fixed_2_hinge.001">
      <inertial>
        <origin xyz="0 0 0" rpy="0 0 0"/>
        <mass value="0.001"/>
        <inertia ixx="0.001" ixy="0" ixz="0" iyy="0.001" iyz="0" izz="0.001"/>
      </inertial>
      <visual name="visual_cylinder_fixed_2_hinge.001">
        <origin xyz="0 0 0" rpy="0 0 0"/>
        <geometry>
          <cylinder radius="0.04726" length="2.18403"/>
        </geometry>
        <material name="green_translucent"/>
      </visual>
    </link>

    <link name="link_fixed_3_door_panel">
      <inertial>
        <origin xyz="0 0 0" rpy="0 0 0"/>
        <mass value="0.001"/>
        <inertia ixx="0.001" ixy="0" ixz="0" iyy="0.001" iyz="0" izz="0.001"/>
      </inertial>
      <visual name="visual_box_fixed_3_door_panel">
        <origin xyz="0 0 0" rpy="0 0 0"/>
        <geometry>
          <box size="1.995 0.195 1.995"/>
        </geometry>
        <material name="green"/>
      </visual>
      <collision name="collision_box_fixed_3_door_panel">
        <origin xyz="0 0 0" rpy="0 0 0"/>
        <geometry>
          <box size="1.995 0.195 1.995"/>
        </geometry>
      </collision>
    </link>

    <link name="link_fixed_3_door_panel.001">
      <inertial>
        <origin xyz="0 0 0" rpy="0 0 0"/>
        <mass value="0.001"/>
        <inertia ixx="0.001" ixy="0" ixz="0" iyy="0.001" iyz="0" izz="0.001"/>
      </inertial>
      <visual name="visual_box_fixed_3_door_panel.001">
        <origin xyz="0 0 0" rpy="0 0 0"/>
        <geometry>
          <box size="1.98503 0.19402 1.98503"/>
        </geometry>
        <material name="green_translucent"/>
      </visual>
    </link>

    <link name="link_fixed_4_door_handle">
      <inertial>
        <origin xyz="0 0 0" rpy="0 0 0"/>
        <mass value="0.001"/>
        <inertia ixx="0.001" ixy="0" ixz="0" iyy="0.001" iyz="0" izz="0.001"/>
      </inertial>
      <visual name="visual_box_fixed_4_door_handle">
        <origin xyz="0 0 0" rpy="0 0 0"/>
        <geometry>
          <box size="0.195 0.045 0.195"/>
        </geometry>
        <material name="yellow"/>
      </visual>
      <collision name="collision_box_fixed_4_door_handle">
        <origin xyz="0 0 0" rpy="0 0 0"/>
        <geometry>
          <box size="0.195 0.045 0.195"/>
        </geometry>
      </collision>
    </link>

    <link name="link_fixed_4_door_handle.001">
      <inertial>
        <origin xyz="0 0 0" rpy="0 0 0"/>
        <mass value="0.001"/>
        <inertia ixx="0.001" ixy="0" ixz="0" iyy="0.001" iyz="0" izz="0.001"/>
      </inertial>
      <visual name="visual_box_fixed_4_door_handle.001">
        <origin xyz="0 0 0" rpy="0 0 0"/>
        <geometry>
          <box size="0.19402 0.04478 0.19402"/>
        </geometry>
        <material name="green_translucent"/>
      </visual>
    </link>

    <link name="link_fixed_6_handle_shaft">
      <inertial>
        <origin xyz="0 0 0" rpy="0 0 0"/>
        <mass value="0.001"/>
        <inertia ixx="0.001" ixy="0" ixz="0" iyy="0.001" iyz="0" izz="0.001"/>
      </inertial>
      <visual name="visual_box_fixed_6_handle_shaft">
        <origin xyz="0 0 0" rpy="0 0 0"/>
        <geometry>
          <box size="0.195 0.195 0.995"/>
        </geometry>
        <material name="red"/>
      </visual>
      <collision name="collision_box_fixed_6_handle_shaft">
        <origin xyz="0 0 0" rpy="0 0 0"/>
        <geometry>
          <box size="0.195 0.195 0.995"/>
        </geometry>
      </collision>
    </link>

    <link name="link_fixed_7_handle_knob">
      <inertial>
        <origin xyz="0 0 0" rpy="0 0 0"/>
        <mass value="0.001"/>
        <inertia ixx="0.001" ixy="0" ixz="0" iyy="0.001" iyz="0" izz="0.001"/>
      </inertial>
      <visual name="visual_box_fixed_7_handle_knob">
        <origin xyz="0 0 0" rpy="0 0 0"/>
        <geometry>
          <box size="0.045 0.045 0.195"/>
        </geometry>
        <material name="yellow"/>
      </visual>
      <collision name="collision_box_fixed_7_handle_knob">
        <origin xyz="0 0 0" rpy="0 0 0"/>
        <geometry>
          <box size="0.045 0.045 0.195"/>
        </geometry>
      </collision>
    </link>

    <link name="link_fixed_9_hinge">
      <inertial>
        <origin xyz="0 0 0" rpy="0 0 0"/>
        <mass value="0.001"/>
        <inertia ixx="0.001" ixy="0" ixz="0" iyy="0.001" iyz="0" izz="0.001"/>
      </inertial>
      <visual name="visual_cylinder_fixed_9_hinge">
        <origin xyz="0 0 0" rpy="0 0 0"/>
        <geometry>
          <cylinder radius="0.1225" length="1.095"/>
        </geometry>
        <material name="gray"/>
      </visual>
    </link>

    <joint name="goal" type="fixed">
      <origin xyz="-6.0 -1.0 1.0" rpy="0 0 1.5708"/>
      <parent link="base_link"/>
      <child link="goal"/>
      <limit effort="0" velocity="0"/>
    </joint>

    <joint name="link_0_joint_0" type="revolute">
      <origin xyz="-6.0 -1.0 1.0" rpy="0 0 0"/>
      <parent link="base_link"/>
      <child link="link_0_joint_0"/>
      <axis xyz="0 0 1.0"/>
      <limit lower="0" upper="1.5708" effort="0" velocity="0"/>
    </joint>

    <joint name="link_1_joint_0" type="prismatic">
      <origin xyz="-4.0 0 0.5" rpy="0 0 0"/>
      <parent link="base_link"/>
      <child link="link_1_joint_0"/>
      <axis xyz="1.0 0 0"/>
      <limit lower="0" upper="2.0" effort="0" velocity="0"/>
    </joint>

    <joint name="link_2_joint_0" type="revolute">
      <origin xyz="0 0 0.5" rpy="0 0 1.5708"/>
      <parent link="base_link"/>
      <child link="link_2_joint_0"/>
      <axis xyz="0 0 1.0"/>
      <limit lower="0" upper="1.5708" effort="0" velocity="0"/>
    </joint>

    <joint name="link_3_joint_0" type="prismatic">
      <origin xyz="0 2.0 0.5" rpy="0 0 1.5708"/>
      <parent link="base_link"/>
      <child link="link_3_joint_0"/>
      <axis xyz="1.0 0 0"/>
      <limit lower="0" upper="2.0" effort="0" velocity="0"/>
    </joint>

    <joint name="link_4_joint_0" type="revolute">
      <origin xyz="-2.0 4.0 1.0" rpy="0 0 0"/>
      <parent link="base_link"/>
      <child link="link_4_joint_0"/>
      <axis xyz="0 0 1.0"/>
      <limit lower="0" upper="1.5708" effort="0" velocity="0"/>
    </joint>

    <joint name="link_fixed_0_floor" type="fixed">
      <origin xyz="0 0 -0.1" rpy="0 0 0"/>
      <parent link="base_link"/>
      <child link="link_fixed_0_floor"/>
    </joint>

    <joint name="link_fixed_10_handle_shaft" type="fixed">
      <origin xyz="0 1.5 1.0" rpy="0 0 0"/>
      <parent link="link_2_joint_0"/>
      <child link="link_fixed_10_handle_shaft"/>
    </joint>

    <joint name="link_fixed_11_handle_knob" type="fixed">
      <origin xyz="0 0 0.6" rpy="0 0 0"/>
      <parent link="link_fixed_10_handle_shaft"/>
      <child link="link_fixed_11_handle_knob"/>
    </joint>

    <joint name="link_fixed_13_handle_shaft" type="fixed">
      <origin xyz="0 0 1.0" rpy="0 0 0"/>
      <parent link="link_3_joint_0"/>
      <child link="link_fixed_13_handle_shaft"/>
    </joint>

    <joint name="link_fixed_14_handle_knob" type="fixed">
      <origin xyz="0 0 0.6" rpy="0 0 0"/>
      <parent link="link_fixed_13_handle_shaft"/>
      <child link="link_fixed_14_handle_knob"/>
    </joint>

    <joint name="link_fixed_16_hinge" type="fixed">
      <origin xyz="0 0 0" rpy="0 0 0"/>
      <parent link="link_4_joint_0"/>
      <child link="link_fixed_16_hinge"/>
    </joint>

    <joint name="link_fixed_17_door_panel" type="fixed">
      <origin xyz="2.0 0 0" rpy="0 0 0"/>
      <parent link="link_4_joint_0"/>
      <child link="link_fixed_17_door_panel"/>
    </joint>

    <joint name="link_fixed_18_door_handle" type="fixed">
      <origin xyz="3.0 0 1.1" rpy="0 0 0"/>
      <parent link="link_4_joint_0"/>
      <child link="link_fixed_18_door_handle"/>
    </joint>

    <joint name="link_fixed_2_hinge" type="fixed">
      <origin xyz="0 0 0" rpy="0 0 0"/>
      <parent link="link_0_joint_0"/>
      <child link="link_fixed_2_hinge"/>
    </joint>

    <joint name="link_fixed_2_hinge.001" type="fixed">
      <origin xyz="0 0 0" rpy="0 0 0"/>
      <parent link="goal"/>
      <child link="link_fixed_2_hinge.001"/>
    </joint>

    <joint name="link_fixed_3_door_panel" type="fixed">
      <origin xyz="1.0 0 0" rpy="0 0 0"/>
      <parent link="link_0_joint_0"/>
      <child link="link_fixed_3_door_panel"/>
    </joint>

    <joint name="link_fixed_3_door_panel.001" type="fixed">
      <origin xyz="0.995 0 0" rpy="0 0 0"/>
      <parent link="goal"/>
      <child link="link_fixed_3_door_panel.001"/>
    </joint>

    <joint name="link_fixed_4_door_handle" type="fixed">
      <origin xyz="1.5 0 1.1" rpy="0 0 0"/>
      <parent link="link_0_joint_0"/>
      <child link="link_fixed_4_door_handle"/>
    </joint>

    <joint name="link_fixed_4_door_handle.001" type="fixed">
      <origin xyz="1.4925 0 1.0945" rpy="0 0 0"/>
      <parent link="goal"/>
      <child link="link_fixed_4_door_handle.001"/>
    </joint>

    <joint name="link_fixed_6_handle_shaft" type="fixed">
      <origin xyz="0 0 1.0" rpy="0 0 0"/>
      <parent link="link_1_joint_0"/>
      <child link="link_fixed_6_handle_shaft"/>
    </joint>

    <joint name="link_fixed_7_handle_knob" type="fixed">
      <origin xyz="0 0 0.6" rpy="0 0 0"/>
      <parent link="link_fixed_6_handle_shaft"/>
      <child link="link_fixed_7_handle_knob"/>
    </joint>

    <joint name="link_fixed_9_hinge" type="fixed">
      <origin xyz="0 0 0" rpy="0 0 0"/>
      <parent link="link_2_joint_0"/>
      <child link="link_fixed_9_hinge"/>
    </joint>

    <material name="gray">
      <color rgba="0.5 0.5 0.5 1.0"/>
    </material>

    <material name="green">
      <color rgba="0 1.0 0 1.0"/>
    </material>

    <material name="green_translucent">
      <color rgba="0 1.0 0 0.25"/>
    </material>

    <material name="lavender">
      <color rgba="0.8 0.8 1.0 1.0"/>
    </material>

    <material name="red">
      <color rgba="1.0 0 0 1.0"/>
    </material>

    <material name="yellow">
      <color rgba="1.0 1.0 0 1.0"/>
    </material>

  </robot>
