<?xml version="1.0"?>
<!-- created with Phobos 1.0.1 "Capricious Choutengan" -->
  <robot name="lockbox2017">

    <link name="base_link">
      <inertial>
        <origin xyz="0 0 0" rpy="0 0 0"/>
        <mass value="0.001"/>
        <inertia ixx="0.001" ixy="0" ixz="0" iyy="0.001" iyz="0" izz="0.001"/>
      </inertial>
      <visual name="visual_box_base">
        <origin xyz="0 0 0" rpy="0 0 0"/>
        <geometry>
          <box size="31.999 31.999 0.199"/>
        </geometry>
        <material name="lavender"/>
      </visual>
      <collision name="collision_box_base">
        <origin xyz="0 0 0" rpy="0 0 0"/>
        <geometry>
          <box size="31.999 31.999 0.199"/>
        </geometry>
      </collision>
    </link>

    <link name="goal">
      <inertial>
        <origin xyz="0 0 0" rpy="0 0 0"/>
        <mass value="0.001"/>
        <inertia ixx="0.001" ixy="0" ixz="0" iyy="0.001" iyz="0" izz="0.001"/>
      </inertial>
      <visual name="visual_cylinder_39_link_0.001">
        <origin xyz="0 0 0" rpy="0 0 0"/>
        <geometry>
          <cylinder radius="0.1995" length="1.999"/>
        </geometry>
        <material name="green_translucent"/>
      </visual>
    </link>

    <link name="link_0_joint_0">
      <inertial>
        <origin xyz="0 0 0" rpy="0 0 0"/>
        <mass value="0.001"/>
        <inertia ixx="0.001" ixy="0" ixz="0" iyy="0.001" iyz="0" izz="0.001"/>
      </inertial>
      <visual name="visual_cylinder_39_link_0">
        <origin xyz="0 0 0" rpy="0 0 0"/>
        <geometry>
          <cylinder radius="0.1995" length="1.999"/>
        </geometry>
        <material name="gray"/>
      </visual>
      <collision name="collision_cylinder_39_link_0">
        <origin xyz="0 0 0" rpy="0 0 0"/>
        <geometry>
          <cylinder radius="0.1995" length="1.999"/>
        </geometry>
      </collision>
    </link>

    <link name="link_1_joint_0">
      <inertial>
        <origin xyz="0 0 0" rpy="0 0 0"/>
        <mass value="0.001"/>
        <inertia ixx="0.001" ixy="0" ixz="0" iyy="0.001" iyz="0" izz="0.001"/>
      </inertial>
      <visual name="visual_box_43_link_1">
        <origin xyz="0 0 0" rpy="0 0 0"/>
        <geometry>
          <box size="0.799 0.999 3.599"/>
        </geometry>
        <material name="red"/>
      </visual>
      <collision name="collision_box_43_link_1">
        <origin xyz="0 0 0" rpy="0 0 0"/>
        <geometry>
          <box size="0.799 0.999 3.599"/>
        </geometry>
      </collision>
    </link>

    <link name="link_2_joint_0">
      <inertial>
        <origin xyz="0 0 0" rpy="0 0 0"/>
        <mass value="0.001"/>
        <inertia ixx="0.001" ixy="0" ixz="0" iyy="0.001" iyz="0" izz="0.001"/>
      </inertial>
      <visual name="visual_mesh_46_link_2">
        <origin xyz="0 0 0" rpy="0 0 0"/>
        <geometry>
          <mesh filename="file:///home/userone/ba/puzzle-generator/puzzles/lockbox2017/meshes/stl/slot_disc.stl" scale="1.0 1.0 1.0"/>
        </geometry>
        <material name="red"/>
      </visual>
      <collision concave="yes" name="collision_mesh_46_link_2">
        <origin xyz="0 0 0" rpy="0 0 0"/>
        <geometry>
          <mesh filename="file:///home/userone/ba/puzzle-generator/puzzles/lockbox2017/meshes/stl/slot_disc.001.stl" scale="1.0 1.0 1.0"/>
        </geometry>
      </collision>
    </link>

    <link name="link_3_joint_0">
      <inertial>
        <origin xyz="0 0 0" rpy="0 0 0"/>
        <mass value="0.001"/>
        <inertia ixx="0.001" ixy="0" ixz="0" iyy="0.001" iyz="0" izz="0.001"/>
      </inertial>
      <visual name="visual_box_50_link_3">
        <origin xyz="0 0 0" rpy="0 0 0"/>
        <geometry>
          <box size="0.799 0.999 3.599"/>
        </geometry>
        <material name="red"/>
      </visual>
      <collision name="collision_box_50_link_3">
        <origin xyz="0 0 0" rpy="0 0 0"/>
        <geometry>
          <box size="0.799 0.999 3.599"/>
        </geometry>
      </collision>
    </link>

    <link name="link_40_fixed_hinge">
      <inertial>
        <origin xyz="0 0 0" rpy="0 0 0"/>
        <mass value="0.001"/>
        <inertia ixx="0.001" ixy="0" ixz="0" iyy="0.001" iyz="0" izz="0.001"/>
      </inertial>
      <visual name="visual_cylinder_40_fixed_hinge">
        <origin xyz="0 0 0" rpy="0 0 0"/>
        <geometry>
          <cylinder radius="0.0495" length="2.099"/>
        </geometry>
        <material name="gray"/>
      </visual>
    </link>

    <link name="link_40_fixed_hinge.001">
      <inertial>
        <origin xyz="0 0 0" rpy="0 0 0"/>
        <mass value="0.001"/>
        <inertia ixx="0.001" ixy="0" ixz="0" iyy="0.001" iyz="0" izz="0.001"/>
      </inertial>
      <visual name="visual_cylinder_40_fixed_hinge.001">
        <origin xyz="0 0 0" rpy="0 0 0"/>
        <geometry>
          <cylinder radius="0.0495" length="2.099"/>
        </geometry>
        <material name="green_translucent"/>
      </visual>
    </link>

    <link name="link_41_fixed_door_panel">
      <inertial>
        <origin xyz="0 0 0" rpy="0 0 0"/>
        <mass value="0.001"/>
        <inertia ixx="0.001" ixy="0" ixz="0" iyy="0.001" iyz="0" izz="0.001"/>
      </inertial>
      <visual name="visual_box_41_fixed_door_panel">
        <origin xyz="0 0 0" rpy="0 0 0"/>
        <geometry>
          <box size="1.999 0.199 1.999"/>
        </geometry>
        <material name="green"/>
      </visual>
      <collision name="collision_box_41_fixed_door_panel">
        <origin xyz="0 0 0" rpy="0 0 0"/>
        <geometry>
          <box size="1.999 0.199 1.999"/>
        </geometry>
      </collision>
    </link>

    <link name="link_41_fixed_door_panel.001">
      <inertial>
        <origin xyz="0 0 0" rpy="0 0 0"/>
        <mass value="0.001"/>
        <inertia ixx="0.001" ixy="0" ixz="0" iyy="0.001" iyz="0" izz="0.001"/>
      </inertial>
      <visual name="visual_box_41_fixed_door_panel.001">
        <origin xyz="0 0 0" rpy="0 0 0"/>
        <geometry>
          <box size="1.999 0.199 1.999"/>
        </geometry>
        <material name="green_translucent"/>
      </visual>
    </link>

    <link name="link_42_fixed_door_handle">
      <inertial>
        <origin xyz="0 0 0" rpy="0 0 0"/>
        <mass value="0.001"/>
        <inertia ixx="0.001" ixy="0" ixz="0" iyy="0.001" iyz="0" izz="0.001"/>
      </inertial>
      <visual name="visual_box_42_fixed_door_handle">
        <origin xyz="0 0 0" rpy="0 0 0"/>
        <geometry>
          <box size="0.199 0.049 0.199"/>
        </geometry>
        <material name="yellow"/>
      </visual>
      <collision name="collision_box_42_fixed_door_handle">
        <origin xyz="0 0 0" rpy="0 0 0"/>
        <geometry>
          <box size="0.199 0.049 0.199"/>
        </geometry>
      </collision>
    </link>

    <link name="link_42_fixed_door_handle.001">
      <inertial>
        <origin xyz="0 0 0" rpy="0 0 0"/>
        <mass value="0.001"/>
        <inertia ixx="0.001" ixy="0" ixz="0" iyy="0.001" iyz="0" izz="0.001"/>
      </inertial>
      <visual name="visual_box_42_fixed_door_handle.001">
        <origin xyz="0 0 0" rpy="0 0 0"/>
        <geometry>
          <box size="0.199 0.049 0.199"/>
        </geometry>
        <material name="green_translucent"/>
      </visual>
    </link>

    <link name="link_44_fixed_handle_shaft">
      <inertial>
        <origin xyz="0 0 0" rpy="0 0 0"/>
        <mass value="0.001"/>
        <inertia ixx="0.001" ixy="0" ixz="0" iyy="0.001" iyz="0" izz="0.001"/>
      </inertial>
      <visual name="visual_box_44_fixed_handle_shaft">
        <origin xyz="0 0 0" rpy="0 0 0"/>
        <geometry>
          <box size="0.199 0.199 0.999"/>
        </geometry>
        <material name="red"/>
      </visual>
      <collision name="collision_box_44_fixed_handle_shaft">
        <origin xyz="0 0 0" rpy="0 0 0"/>
        <geometry>
          <box size="0.199 0.199 0.999"/>
        </geometry>
      </collision>
    </link>

    <link name="link_45_fixed_handle_knob">
      <inertial>
        <origin xyz="0 0 0" rpy="0 0 0"/>
        <mass value="0.001"/>
        <inertia ixx="0.001" ixy="0" ixz="0" iyy="0.001" iyz="0" izz="0.001"/>
      </inertial>
      <visual name="visual_box_45_fixed_handle_knob">
        <origin xyz="0 0 0" rpy="0 0 0"/>
        <geometry>
          <box size="0.049 0.049 0.199"/>
        </geometry>
        <material name="yellow"/>
      </visual>
      <collision name="collision_box_45_fixed_handle_knob">
        <origin xyz="0 0 0" rpy="0 0 0"/>
        <geometry>
          <box size="0.049 0.049 0.199"/>
        </geometry>
      </collision>
    </link>

    <link name="link_47_fixed_handle_shaft">
      <inertial>
        <origin xyz="0 0 0" rpy="0 0 0"/>
        <mass value="0.001"/>
        <inertia ixx="0.001" ixy="0" ixz="0" iyy="0.001" iyz="0" izz="0.001"/>
      </inertial>
      <visual name="visual_cylinder_47_fixed_handle_shaft">
        <origin xyz="0 0 0" rpy="0 0 0"/>
        <geometry>
          <cylinder radius="0.0995" length="0.999"/>
        </geometry>
        <material name="red"/>
      </visual>
      <collision name="collision_cylinder_47_fixed_handle_shaft">
        <origin xyz="0 0 0" rpy="0 0 0"/>
        <geometry>
          <cylinder radius="0.0995" length="0.999"/>
        </geometry>
      </collision>
    </link>

    <link name="link_48_fixed_handle_knob">
      <inertial>
        <origin xyz="0 0 0" rpy="0 0 0"/>
        <mass value="0.001"/>
        <inertia ixx="0.001" ixy="0" ixz="0" iyy="0.001" iyz="0" izz="0.001"/>
      </inertial>
      <visual name="visual_box_48_fixed_handle_knob">
        <origin xyz="0 0 0" rpy="0 0 0"/>
        <geometry>
          <box size="0.049 0.049 0.199"/>
        </geometry>
        <material name="yellow"/>
      </visual>
      <collision name="collision_box_48_fixed_handle_knob">
        <origin xyz="0 0 0" rpy="0 0 0"/>
        <geometry>
          <box size="0.049 0.049 0.199"/>
        </geometry>
      </collision>
    </link>

    <link name="link_49_fixed_hinge">
      <inertial>
        <origin xyz="0 0 0" rpy="0 0 0"/>
        <mass value="0.001"/>
        <inertia ixx="0.001" ixy="0" ixz="0" iyy="0.001" iyz="0" izz="0.001"/>
      </inertial>
      <visual name="visual_cylinder_49_fixed_hinge">
        <origin xyz="0 0 0" rpy="0 0 0"/>
        <geometry>
          <cylinder radius="0.0495" length="1.099"/>
        </geometry>
        <material name="gray"/>
      </visual>
    </link>

    <link name="link_4_joint_0">
      <inertial>
        <origin xyz="0 0 0" rpy="0 0 0"/>
        <mass value="0.001"/>
        <inertia ixx="0.001" ixy="0" ixz="0" iyy="0.001" iyz="0" izz="0.001"/>
      </inertial>
      <visual name="visual_cylinder_53_link_4">
        <origin xyz="0 0 0" rpy="0 0 0"/>
        <geometry>
          <cylinder radius="0.1995" length="1.999"/>
        </geometry>
        <material name="gray"/>
      </visual>
      <collision name="collision_cylinder_53_link_4">
        <origin xyz="0 0 0" rpy="0 0 0"/>
        <geometry>
          <cylinder radius="0.1995" length="1.999"/>
        </geometry>
      </collision>
    </link>

    <link name="link_51_fixed_handle_shaft">
      <inertial>
        <origin xyz="0 0 0" rpy="0 0 0"/>
        <mass value="0.001"/>
        <inertia ixx="0.001" ixy="0" ixz="0" iyy="0.001" iyz="0" izz="0.001"/>
      </inertial>
      <visual name="visual_box_51_fixed_handle_shaft">
        <origin xyz="0 0 0" rpy="0 0 0"/>
        <geometry>
          <box size="0.199 0.199 0.999"/>
        </geometry>
        <material name="red"/>
      </visual>
      <collision name="collision_box_51_fixed_handle_shaft">
        <origin xyz="0 0 0" rpy="0 0 0"/>
        <geometry>
          <box size="0.199 0.199 0.999"/>
        </geometry>
      </collision>
    </link>

    <link name="link_52_fixed_handle_knob">
      <inertial>
        <origin xyz="0 0 0" rpy="0 0 0"/>
        <mass value="0.001"/>
        <inertia ixx="0.001" ixy="0" ixz="0" iyy="0.001" iyz="0" izz="0.001"/>
      </inertial>
      <visual name="visual_box_52_fixed_handle_knob">
        <origin xyz="0 0 0" rpy="0 0 0"/>
        <geometry>
          <box size="0.049 0.049 0.199"/>
        </geometry>
        <material name="yellow"/>
      </visual>
      <collision name="collision_box_52_fixed_handle_knob">
        <origin xyz="0 0 0" rpy="0 0 0"/>
        <geometry>
          <box size="0.049 0.049 0.199"/>
        </geometry>
      </collision>
    </link>

    <link name="link_54_fixed_hinge">
      <inertial>
        <origin xyz="0 0 0" rpy="0 0 0"/>
        <mass value="0.001"/>
        <inertia ixx="0.001" ixy="0" ixz="0" iyy="0.001" iyz="0" izz="0.001"/>
      </inertial>
      <visual name="visual_cylinder_54_fixed_hinge">
        <origin xyz="0 0 0" rpy="0 0 0"/>
        <geometry>
          <cylinder radius="0.0495" length="2.099"/>
        </geometry>
        <material name="gray"/>
      </visual>
    </link>

    <link name="link_55_fixed_door_panel">
      <inertial>
        <origin xyz="0 0 0" rpy="0 0 0"/>
        <mass value="0.001"/>
        <inertia ixx="0.001" ixy="0" ixz="0" iyy="0.001" iyz="0" izz="0.001"/>
      </inertial>
      <visual name="visual_box_55_fixed_door_panel">
        <origin xyz="0 0 0" rpy="0 0 0"/>
        <geometry>
          <box size="3.999 0.199 1.999"/>
        </geometry>
        <material name="red"/>
      </visual>
      <collision name="collision_box_55_fixed_door_panel">
        <origin xyz="0 0 0" rpy="0 0 0"/>
        <geometry>
          <box size="3.999 0.199 1.999"/>
        </geometry>
      </collision>
    </link>

    <link name="link_56_fixed_door_handle">
      <inertial>
        <origin xyz="0 0 0" rpy="0 0 0"/>
        <mass value="0.001"/>
        <inertia ixx="0.001" ixy="0" ixz="0" iyy="0.001" iyz="0" izz="0.001"/>
      </inertial>
      <visual name="visual_box_56_fixed_door_handle">
        <origin xyz="0 0 0" rpy="0 0 0"/>
        <geometry>
          <box size="0.199 0.049 0.199"/>
        </geometry>
        <material name="yellow"/>
      </visual>
      <collision name="collision_box_56_fixed_door_handle">
        <origin xyz="0 0 0" rpy="0 0 0"/>
        <geometry>
          <box size="0.199 0.049 0.199"/>
        </geometry>
      </collision>
    </link>

    <joint name="goal" type="fixed">
      <origin xyz="-6.0 -1.0 1.1" rpy="0 0 1.5708"/>
      <parent link="base_link"/>
      <child link="goal"/>
      <limit effort="0" velocity="0"/>
    </joint>

    <joint name="link_0_joint_0" type="revolute">
      <origin xyz="-6.0 -1.0 1.1" rpy="0 0 0"/>
      <parent link="base_link"/>
      <child link="link_0_joint_0"/>
      <axis xyz="0 0 1.0"/>
      <limit lower="0" upper="1.5708" effort="0" velocity="0"/>
    </joint>

    <joint name="link_1_joint_0" type="prismatic">
      <origin xyz="-4.0 0 0.6" rpy="-1.5708 0 -1.5708"/>
      <parent link="base_link"/>
      <child link="link_1_joint_0"/>
      <axis xyz="0 0 1.0"/>
      <limit lower="0" upper="2.0" effort="0" velocity="0"/>
    </joint>

    <joint name="link_2_joint_0" type="revolute">
      <origin xyz="0 0 0.6" rpy="0 0 1.5708"/>
      <parent link="base_link"/>
      <child link="link_2_joint_0"/>
      <axis xyz="0 0 1.0"/>
      <limit lower="0" upper="1.5708" effort="0" velocity="0"/>
    </joint>

    <joint name="link_3_joint_0" type="prismatic">
      <origin xyz="0 2.0 0.6" rpy="-1.5708 0 0"/>
      <parent link="base_link"/>
      <child link="link_3_joint_0"/>
      <axis xyz="0 0 1.0"/>
      <limit lower="0" upper="2.0" effort="0" velocity="0"/>
    </joint>

    <joint name="link_40_fixed_hinge" type="fixed">
      <origin xyz="0 0 0" rpy="0 0 0"/>
      <parent link="link_0_joint_0"/>
      <child link="link_40_fixed_hinge"/>
    </joint>

    <joint name="link_40_fixed_hinge.001" type="fixed">
      <origin xyz="0 0 0" rpy="0 0 0"/>
      <parent link="goal"/>
      <child link="link_40_fixed_hinge.001"/>
    </joint>

    <joint name="link_41_fixed_door_panel" type="fixed">
      <origin xyz="1.0 0 0" rpy="0 0 0"/>
      <parent link="link_0_joint_0"/>
      <child link="link_41_fixed_door_panel"/>
    </joint>

    <joint name="link_41_fixed_door_panel.001" type="fixed">
      <origin xyz="1.0 0 0" rpy="0 0 0"/>
      <parent link="goal"/>
      <child link="link_41_fixed_door_panel.001"/>
    </joint>

    <joint name="link_42_fixed_door_handle" type="fixed">
      <origin xyz="1.5 0 1.1" rpy="0 0 0"/>
      <parent link="link_0_joint_0"/>
      <child link="link_42_fixed_door_handle"/>
    </joint>

    <joint name="link_42_fixed_door_handle.001" type="fixed">
      <origin xyz="1.5 0 1.1" rpy="0 0 0"/>
      <parent link="goal"/>
      <child link="link_42_fixed_door_handle.001"/>
    </joint>

    <joint name="link_44_fixed_handle_shaft" type="fixed">
      <origin xyz="0 -1.0 0" rpy="1.5708 0 0"/>
      <parent link="link_1_joint_0"/>
      <child link="link_44_fixed_handle_shaft"/>
    </joint>

    <joint name="link_45_fixed_handle_knob" type="fixed">
      <origin xyz="0 0 0.6" rpy="0 0 0"/>
      <parent link="link_44_fixed_handle_shaft"/>
      <child link="link_45_fixed_handle_knob"/>
    </joint>

    <joint name="link_47_fixed_handle_shaft" type="fixed">
      <origin xyz="0 1.5 1.0" rpy="0 0 0"/>
      <parent link="link_2_joint_0"/>
      <child link="link_47_fixed_handle_shaft"/>
    </joint>

    <joint name="link_48_fixed_handle_knob" type="fixed">
      <origin xyz="0 0 0.6" rpy="0 0 0"/>
      <parent link="link_47_fixed_handle_shaft"/>
      <child link="link_48_fixed_handle_knob"/>
    </joint>

    <joint name="link_49_fixed_hinge" type="fixed">
      <origin xyz="0 0 0" rpy="0 0 0"/>
      <parent link="link_2_joint_0"/>
      <child link="link_49_fixed_hinge"/>
    </joint>

    <joint name="link_4_joint_0" type="revolute">
      <origin xyz="-2.0 4.0 1.1" rpy="0 0 0"/>
      <parent link="base_link"/>
      <child link="link_4_joint_0"/>
      <axis xyz="0 0 1.0"/>
      <limit lower="0" upper="1.5708" effort="0" velocity="0"/>
    </joint>

    <joint name="link_51_fixed_handle_shaft" type="fixed">
      <origin xyz="0 -1.0 0" rpy="1.5708 0 0"/>
      <parent link="link_3_joint_0"/>
      <child link="link_51_fixed_handle_shaft"/>
    </joint>

    <joint name="link_52_fixed_handle_knob" type="fixed">
      <origin xyz="0 0 0.6" rpy="0 0 0"/>
      <parent link="link_51_fixed_handle_shaft"/>
      <child link="link_52_fixed_handle_knob"/>
    </joint>

    <joint name="link_54_fixed_hinge" type="fixed">
      <origin xyz="0 0 0" rpy="0 0 0"/>
      <parent link="link_4_joint_0"/>
      <child link="link_54_fixed_hinge"/>
    </joint>

    <joint name="link_55_fixed_door_panel" type="fixed">
      <origin xyz="2.0 0 0" rpy="0 0 0"/>
      <parent link="link_4_joint_0"/>
      <child link="link_55_fixed_door_panel"/>
    </joint>

    <joint name="link_56_fixed_door_handle" type="fixed">
      <origin xyz="3.0 0 1.1" rpy="0 0 0"/>
      <parent link="link_4_joint_0"/>
      <child link="link_56_fixed_door_handle"/>
    </joint>

    <material name="gray">
      <color rgba="0.5 0.5 0.5 1.0"/>
    </material>

    <material name="green">
      <color rgba="0 1.0 0 1.0"/>
    </material>

    <material name="green_translucent">
      <color rgba="0 1.0 0 0.25"/>
    </material>

    <material name="lavender">
      <color rgba="0.8 0.8 1.0 1.0"/>
    </material>

    <material name="red">
      <color rgba="1.0 0 0 1.0"/>
    </material>

    <material name="yellow">
      <color rgba="1.0 1.0 0 1.0"/>
    </material>

  </robot>
