<?xml version="1.0"?>
<!-- created with Phobos 1.0.1 "Capricious Choutengan" -->
  <robot name="lockbox2017">

    <link name="base_link">
      <inertial>
        <origin xyz="0 0 0" rpy="0 0 0"/>
        <mass value="0.001"/>
        <inertia ixx="0.001" ixy="0" ixz="0" iyy="0.001" iyz="0" izz="0.001"/>
      </inertial>
      <visual name="visual_cube_base">
        <origin xyz="0 0 0" rpy="0 0 0"/>
        <geometry>
          <box size="32.0 32.0 0.2"/>
        </geometry>
        <material name="lavender"/>
      </visual>
      <collision name="collision_cube_base">
        <origin xyz="0 0 0" rpy="0 0 0"/>
        <geometry>
          <box size="32.0 32.0 0.2"/>
        </geometry>
      </collision>
    </link>

    <link name="link_0">
      <inertial>
        <origin xyz="0 0 0" rpy="0 0 0"/>
        <mass value="0.001"/>
        <inertia ixx="0.001" ixy="0" ixz="0" iyy="0.001" iyz="0" izz="0.001"/>
      </inertial>
      <visual name="visual_cube_0">
        <origin xyz="0 0 0" rpy="0 0 0"/>
        <geometry>
          <box size="3.6 0.8 1.0"/>
        </geometry>
        <material name="green"/>
      </visual>
      <collision name="collision_cube_0">
        <origin xyz="0 0 0" rpy="0 0 0"/>
        <geometry>
          <box size="3.6 0.8 1.0"/>
        </geometry>
      </collision>
    </link>

    <link name="link_1">
      <inertial>
        <origin xyz="0 0 0" rpy="0 0 0"/>
        <mass value="0.001"/>
        <inertia ixx="0.001" ixy="0" ixz="0" iyy="0.001" iyz="0" izz="0.001"/>
      </inertial>
      <visual name="visual_cube_1">
        <origin xyz="0 0 0" rpy="0 0 0"/>
        <geometry>
          <box size="0.8 1.0 3.6"/>
        </geometry>
        <material name="red"/>
      </visual>
      <collision name="collision_cube_1">
        <origin xyz="0 0 0" rpy="0 0 0"/>
        <geometry>
          <box size="0.8 1.0 3.6"/>
        </geometry>
      </collision>
    </link>

    <link name="link_2">
      <inertial>
        <origin xyz="0 0 0" rpy="0 0 0"/>
        <mass value="0.001"/>
        <inertia ixx="0.001" ixy="0" ixz="0" iyy="0.001" iyz="0" izz="0.001"/>
      </inertial>
      <visual name="visual_mesh_2">
        <origin xyz="0 0 0" rpy="0 0 0"/>
        <geometry>
          <mesh filename="file:///home/userone/ba/puzzle-generator/puzzles/lockbox2017/meshes/stl/slot_disc.stl" scale="1.0 1.0 1.0"/>
        </geometry>
        <material name="red"/>
      </visual>
      <collision concave="yes" name="collision_mesh_2">
        <origin xyz="-0.03587 0 0" rpy="0 0 0"/>
        <geometry>
          <mesh filename="file:///home/userone/ba/puzzle-generator/puzzles/lockbox2017/meshes/stl/slot_disc.001.stl" scale="1.0 1.0 1.0"/>
        </geometry>
      </collision>
    </link>

    <link name="link_3">
      <inertial>
        <origin xyz="0 0 0" rpy="0 0 0"/>
        <mass value="0.001"/>
        <inertia ixx="0.001" ixy="0" ixz="0" iyy="0.001" iyz="0" izz="0.001"/>
      </inertial>
      <visual name="visual_cube_3">
        <origin xyz="0 0 0" rpy="0 0 0"/>
        <geometry>
          <box size="0.8 1.0 3.6"/>
        </geometry>
        <material name="red"/>
      </visual>
      <collision name="collision_cube_3">
        <origin xyz="0 0 0" rpy="0 0 0"/>
        <geometry>
          <box size="0.8 1.0 3.6"/>
        </geometry>
      </collision>
    </link>

    <link name="link_4">
      <inertial>
        <origin xyz="0 0 0" rpy="0 0 0"/>
        <mass value="0.001"/>
        <inertia ixx="0.001" ixy="0" ixz="0" iyy="0.001" iyz="0" izz="0.001"/>
      </inertial>
      <visual name="visual_cube_4">
        <origin xyz="0 0 0" rpy="0 0 0"/>
        <geometry>
          <box size="3.6 0.8 1.0"/>
        </geometry>
        <material name="red"/>
      </visual>
      <collision name="collision_cube_4">
        <origin xyz="0 0 0" rpy="0 0 0"/>
        <geometry>
          <box size="3.6 0.8 1.0"/>
        </geometry>
      </collision>
    </link>

    <joint name="link_0" type="revolute">
      <origin xyz="-6.0 -1.0 0.6" rpy="0 0 0"/>
      <parent link="base_link"/>
      <child link="link_0"/>
      <axis xyz="0 0 1.0"/>
      <limit lower="0" upper="1.5708" effort="0" velocity="0"/>
    </joint>

    <joint name="link_1" type="prismatic">
      <origin xyz="-4.0 0 0.6" rpy="-1.5708 0 -1.5708"/>
      <parent link="base_link"/>
      <child link="link_1"/>
      <axis xyz="0 0 1.0"/>
      <limit lower="0" upper="2.0" effort="0" velocity="0"/>
    </joint>

    <joint name="link_2" type="revolute">
      <origin xyz="0 0 0.6" rpy="0 0 1.5708"/>
      <parent link="base_link"/>
      <child link="link_2"/>
      <axis xyz="0 0 1.0"/>
      <limit lower="-3.14159" upper="3.14159" effort="0" velocity="0"/>
    </joint>

    <joint name="link_3" type="prismatic">
      <origin xyz="0 2.0 0.6" rpy="-1.5708 0 0"/>
      <parent link="base_link"/>
      <child link="link_3"/>
      <axis xyz="0 0 1.0"/>
      <limit lower="0" upper="2.0" effort="0" velocity="0"/>
    </joint>

    <joint name="link_4" type="revolute">
      <origin xyz="-1.0 5.0 0.6" rpy="0 0 0"/>
      <parent link="base_link"/>
      <child link="link_4"/>
      <axis xyz="0 0 1.0"/>
      <limit lower="0" upper="1.5708" effort="0" velocity="0"/>
    </joint>

    <material name="green">
      <color rgba="0 1.0 0 1.0"/>
    </material>

    <material name="lavender">
      <color rgba="0.8 0.8 1.0 1.0"/>
    </material>

    <material name="red">
      <color rgba="1.0 0 0 1.0"/>
    </material>

  </robot>
