<?xml version="1.0"?>
<!-- created with Phobos 1.0.1 "Capricious Choutengan" -->
  <robot name="gridworld">

    <link name="base_link">
      <inertial>
        <origin xyz="0 0 0" rpy="0 0 0"/>
        <mass value="0.001"/>
        <inertia ixx="0.001" ixy="0" ixz="0" iyy="0.001" iyz="0" izz="0.001"/>
      </inertial>
      <visual name="visual_cube_base">
        <origin xyz="0 0 0" rpy="0 0 0"/>
        <geometry>
          <box size="32.0 32.0 0.2"/>
        </geometry>
        <material name="lavender"/>
      </visual>
      <collision name="collision_cube_base">
        <origin xyz="0 0 0" rpy="0 0 0"/>
        <geometry>
          <box size="32.0 32.0 0.2"/>
        </geometry>
      </collision>
    </link>

    <link name="link0">
      <inertial>
        <origin xyz="0 0 0" rpy="0 0 0"/>
        <mass value="0.001"/>
        <inertia ixx="0.001" ixy="0" ixz="0" iyy="0.001" iyz="0" izz="0.001"/>
      </inertial>
      <visual name="visual_cube0">
        <origin xyz="0 0 0" rpy="0 0 0"/>
        <geometry>
          <box size="2.9 0.9 0.9"/>
        </geometry>
        <material name="green"/>
      </visual>
      <collision name="collision_cube0">
        <origin xyz="0 0 0" rpy="0 0 0"/>
        <geometry>
          <box size="2.9 0.9 0.9"/>
        </geometry>
      </collision>
    </link>

    <link name="link1">
      <inertial>
        <origin xyz="0 0 0" rpy="0 0 0"/>
        <mass value="0.001"/>
        <inertia ixx="0.001" ixy="0" ixz="0" iyy="0.001" iyz="0" izz="0.001"/>
      </inertial>
      <visual name="visual_cube1">
        <origin xyz="0 0 0" rpy="0 0 0"/>
        <geometry>
          <box size="2.9 0.9 0.9"/>
        </geometry>
        <material name="green"/>
      </visual>
      <collision name="collision_cube1">
        <origin xyz="0 0 0" rpy="0 0 0"/>
        <geometry>
          <box size="2.9 0.9 0.9"/>
        </geometry>
      </collision>
    </link>

    <link name="link2">
      <inertial>
        <origin xyz="0 0 0" rpy="0 0 0"/>
        <mass value="0.001"/>
        <inertia ixx="0.001" ixy="0" ixz="0" iyy="0.001" iyz="0" izz="0.001"/>
      </inertial>
      <visual name="visual_cube2">
        <origin xyz="0 0 0" rpy="0 0 0"/>
        <geometry>
          <box size="0.9 0.9 1.9"/>
        </geometry>
        <material name="red"/>
      </visual>
      <collision name="collision_cube2">
        <origin xyz="0 0 0" rpy="0 0 0"/>
        <geometry>
          <box size="0.9 0.9 1.9"/>
        </geometry>
      </collision>
    </link>

    <link name="link3">
      <inertial>
        <origin xyz="0 0 0" rpy="0 0 0"/>
        <mass value="0.001"/>
        <inertia ixx="0.001" ixy="0" ixz="0" iyy="0.001" iyz="0" izz="0.001"/>
      </inertial>
      <visual name="visual_cube3">
        <origin xyz="0 0 0" rpy="0 0 0"/>
        <geometry>
          <box size="0.9 0.9 1.9"/>
        </geometry>
        <material name="red"/>
      </visual>
      <collision name="collision_cube3">
        <origin xyz="0 0 0" rpy="0 0 0"/>
        <geometry>
          <box size="0.9 0.9 1.9"/>
        </geometry>
      </collision>
    </link>

    <joint name="link0" type="revolute">
      <origin xyz="-0.5 0.5 0.45" rpy="0 0 0"/>
      <parent link="base_link"/>
      <child link="link0"/>
      <axis xyz="0 0 1.0"/>
      <limit lower="0" upper="1.5708" effort="0" velocity="0"/>
    </joint>

    <joint name="link1" type="revolute">
      <origin xyz="-2.5 -0.5 0.45" rpy="0 0 0"/>
      <parent link="base_link"/>
      <child link="link1"/>
      <axis xyz="0 0 1.0"/>
      <limit lower="-1.5708" upper="0" effort="0" velocity="0"/>
    </joint>

    <joint name="link2" type="prismatic">
      <origin xyz="1.0 1.5 0.45" rpy="0 1.5708 0"/>
      <parent link="base_link"/>
      <child link="link2"/>
      <axis xyz="0 0 1.0"/>
      <limit lower="0" upper="1.0" effort="0" velocity="0"/>
    </joint>

    <joint name="link3" type="prismatic">
      <origin xyz="-1.5 -2.0 0.45" rpy="1.5708 0 0"/>
      <parent link="base_link"/>
      <child link="link3"/>
      <axis xyz="0 0 1.0"/>
      <limit lower="0" upper="1.0" effort="0" velocity="0"/>
    </joint>

    <material name="green">
      <color rgba="0 1.0 0 1.0"/>
    </material>

    <material name="lavender">
      <color rgba="0.8 0.8 1.0 1.0"/>
    </material>

    <material name="red">
      <color rgba="1.0 0 0 1.0"/>
    </material>

  </robot>
