<?xml version="1.0"?>
<!-- created with Phobos 1.0.1 "Capricious Choutengan" -->
  <robot name="simple_sliders">

    <link name="base_link">
      <inertial>
        <origin xyz="0 0 0" rpy="0 0 0"/>
        <mass value="0.001"/>
        <inertia ixx="0.001" ixy="0" ixz="0" iyy="0.001" iyz="0" izz="0.001"/>
      </inertial>
      <visual name="visual_box_base">
        <origin xyz="0 0 0" rpy="0 0 0"/>
        <geometry>
          <box size="31.999 31.999 0.199"/>
        </geometry>
        <material name="lavender"/>
      </visual>
      <collision name="collision_box_base">
        <origin xyz="0 0 0" rpy="0 0 0"/>
        <geometry>
          <box size="31.999 31.999 0.199"/>
        </geometry>
      </collision>
    </link>

    <link name="goal">
      <inertial>
        <origin xyz="0 0 0" rpy="0 0 0"/>
        <mass value="0.001"/>
        <inertia ixx="0.001" ixy="0" ixz="0" iyy="0.001" iyz="0" izz="0.001"/>
      </inertial>
      <visual name="visual_box_0_link_0.001">
        <origin xyz="0 0 0" rpy="0 0 0"/>
        <geometry>
          <box size="1.599 0.199 0.199"/>
        </geometry>
        <material name="green_translucent"/>
      </visual>
    </link>

    <link name="link_0_joint_0">
      <inertial>
        <origin xyz="0 0 0" rpy="0 0 0"/>
        <mass value="0.001"/>
        <inertia ixx="0.001" ixy="0" ixz="0" iyy="0.001" iyz="0" izz="0.001"/>
      </inertial>
      <visual name="visual_box_0_link_0">
        <origin xyz="0 0 0" rpy="0 0 0"/>
        <geometry>
          <box size="1.599 0.199 0.199"/>
        </geometry>
        <material name="green"/>
      </visual>
      <collision name="collision_box_0_link_0">
        <origin xyz="0 0 0" rpy="0 0 0"/>
        <geometry>
          <box size="1.599 0.199 0.199"/>
        </geometry>
      </collision>
    </link>

    <link name="link_1_joint_0">
      <inertial>
        <origin xyz="0 0 0" rpy="0 0 0"/>
        <mass value="0.001"/>
        <inertia ixx="0.001" ixy="0" ixz="0" iyy="0.001" iyz="0" izz="0.001"/>
      </inertial>
      <visual name="visual_box_1_link_1">
        <origin xyz="0 0 0" rpy="0 0 0"/>
        <geometry>
          <box size="1.599 0.199 0.199"/>
        </geometry>
        <material name="red"/>
      </visual>
      <collision name="collision_box_1_link_1">
        <origin xyz="0 0 0" rpy="0 0 0"/>
        <geometry>
          <box size="1.599 0.199 0.199"/>
        </geometry>
      </collision>
    </link>

    <link name="link_2_joint_0">
      <inertial>
        <origin xyz="0 0 0" rpy="0 0 0"/>
        <mass value="0.001"/>
        <inertia ixx="0.001" ixy="0" ixz="0" iyy="0.001" iyz="0" izz="0.001"/>
      </inertial>
      <visual name="visual_box_2_link_2">
        <origin xyz="0 0 0" rpy="0 0 0"/>
        <geometry>
          <box size="1.599 0.199 0.199"/>
        </geometry>
        <material name="red"/>
      </visual>
      <collision name="collision_box_2_link_2">
        <origin xyz="0 0 0" rpy="0 0 0"/>
        <geometry>
          <box size="1.599 0.199 0.199"/>
        </geometry>
      </collision>
    </link>

    <link name="link_3_joint_0">
      <inertial>
        <origin xyz="0 0 0" rpy="0 0 0"/>
        <mass value="0.001"/>
        <inertia ixx="0.001" ixy="0" ixz="0" iyy="0.001" iyz="0" izz="0.001"/>
      </inertial>
      <visual name="visual_box_3_link_3">
        <origin xyz="0 0 0" rpy="0 0 0"/>
        <geometry>
          <box size="1.599 0.199 0.199"/>
        </geometry>
        <material name="red"/>
      </visual>
      <collision name="collision_box_3_link_3">
        <origin xyz="0 0 0" rpy="0 0 0"/>
        <geometry>
          <box size="1.599 0.199 0.199"/>
        </geometry>
      </collision>
    </link>

    <joint name="goal" type="fixed">
      <origin xyz="0 -1.0 0.2" rpy="0 0 -1.5708"/>
      <parent link="base_link"/>
      <child link="goal"/>
      <limit effort="0" velocity="0"/>
    </joint>

    <joint name="link_0_joint_0" type="prismatic">
      <origin xyz="0 0 0.2" rpy="0 0 -1.5708"/>
      <parent link="base_link"/>
      <child link="link_0_joint_0"/>
      <axis xyz="1.0 0 0"/>
      <limit lower="0" upper="1.0" effort="0" velocity="0"/>
    </joint>

    <joint name="link_1_joint_0" type="prismatic">
      <origin xyz="0 -1.0 0.2" rpy="0 0 0"/>
      <parent link="base_link"/>
      <child link="link_1_joint_0"/>
      <axis xyz="1.0 0 0"/>
      <limit lower="0" upper="1.0" effort="0" velocity="0"/>
    </joint>

    <joint name="link_2_joint_0" type="prismatic">
      <origin xyz="1.0 -1.0 0.2" rpy="0 0 -1.5708"/>
      <parent link="base_link"/>
      <child link="link_2_joint_0"/>
      <axis xyz="1.0 0 0"/>
      <limit lower="0" upper="1.0" effort="0" velocity="0"/>
    </joint>

    <joint name="link_3_joint_0" type="prismatic">
      <origin xyz="1.0 -2.0 0.2" rpy="0 0 0"/>
      <parent link="base_link"/>
      <child link="link_3_joint_0"/>
      <axis xyz="1.0 0 0"/>
      <limit lower="0" upper="1.0" effort="0" velocity="0"/>
    </joint>

    <material name="green">
      <color rgba="0 1.0 0 1.0"/>
    </material>

    <material name="green_translucent">
      <color rgba="0 1.0 0 0.25"/>
    </material>

    <material name="lavender">
      <color rgba="0.8 0.8 1.0 1.0"/>
    </material>

    <material name="red">
      <color rgba="1.0 0 0 1.0"/>
    </material>

  </robot>
